Workbook

Sheet README
A1: DRCFJSP HPC results, rerun 2026-10 (doduo)
A3: CP reference (all comparisons): CP Optimizer 1 h on the HPC with the same resources as the other methods.
A4: LBBD variants (LBBD_CP, CP_LBBD_CP, LBBD_CP_TS, CP_LBBD_CP_TS): 3600 s, seed 1, 8 cores / 16 GB, tag Rerun_2026-10.
A5: TS_<it>_<min>_<bj> (6 configurations): seed 1, 8 cores / 16 GB (TS is single-threaded), tag Rerun_2026-10.
A6: FaF chain (FaF, FaFM, FaFMJ, FaFMx2, TS@FaF, TS@FaFM, TSN1@FaFM): seeds 1-5, 1 core / 4 GB, job 66273394.
A7: FaFMJ = FaFM with the TS neighbourhood package; FaFMx2 = FaFM_30_50_600 (doubled parameters); FaFMx3 = FaFM_45_75_900 (tripled parameters, run separately with the same resources); TS@FaF / TS@FaFM = TS with the same-seed FaF / FaFM wall time; TSN1@FaFM = TS framework with FaF's N1, same time.
A8: TSN1_2000_5_5, TSN1_10000_10_5: TS framework with FaF's neighbourhood N1, seed 1, 8 cores / 16 GB, job 66273395; compare with TS_2000_5_5 / TS_10000_10_5.
A10: Gap% = (UB - LB) / UB. RPD = (UB - best UB of CP and the four LBBD variants) / best. Q = Dev CP = (UB - CP UB) / CP UB. CPU Time = wall-clock seconds reported by the solver.
A11: Instance sets: WFJSP 1-24 (240), MK = Mk01-Mk10, DP = Dauzere_01a-12a. In the WFJSP / MK / DP tables, "Average (3 sets)" = mean of the three set averages and "Average (262 instances)" = mean over all 262 instances = (240*WFJSP + 10*MK + 12*DP) / 262.
A12: All schedules were validated against the instances (eligibility, durations, precedences, no overlaps on machines and workers, obj = makespan).
A13: Sheets: CPvsLBBD, TSvsF&F (summaries, formulas) | Exact Methods(_lit), TS(_lit), FaF (per instance) | FaF_runs (every chain / TSN1 run).

Sheet CPvsLBBD
A1: Optimality Gap (WFJSP)
A2: Instance set | B2: Scale | C2: CP | D2: LBBD_CP_TS | E2: LBBD_CP | F2: CP_LBBD_CP | G2: CP_LBBD_CP_TS
A3: wfjsp1 | B3: 5×3×3 | C3: =AVERAGE('Exact Methods'!$F3:$F12) | D3: =AVERAGE('Exact Methods'!$K3:$K12) | E3: =AVERAGE('Exact Methods'!$Q3:$Q12) | F3: =AVERAGE('Exact Methods'!$W3:$W12) | G3: =AVERAGE('Exact Methods'!$AC3:$AC12)
A4: wfjsp2 | B4: 7×3×3 | C4: =AVERAGE('Exact Methods'!$F13:$F22) | D4: =AVERAGE('Exact Methods'!$K13:$K22) | E4: =AVERAGE('Exact Methods'!$Q13:$Q22) | F4: =AVERAGE('Exact Methods'!$W13:$W22) | G4: =AVERAGE('Exact Methods'!$AC13:$AC22)
A5: wfjsp3 | B5: 7×4×4 | C5: =AVERAGE('Exact Methods'!$F23:$F32) | D5: =AVERAGE('Exact Methods'!$K23:$K32) | E5: =AVERAGE('Exact Methods'!$Q23:$Q32) | F5: =AVERAGE('Exact Methods'!$W23:$W32) | G5: =AVERAGE('Exact Methods'!$AC23:$AC32)
A6: wfjsp4 | B6: 10×5×5 | C6: =AVERAGE('Exact Methods'!$F33:$F42) | D6: =AVERAGE('Exact Methods'!$K33:$K42) | E6: =AVERAGE('Exact Methods'!$Q33:$Q42) | F6: =AVERAGE('Exact Methods'!$W33:$W42) | G6: =AVERAGE('Exact Methods'!$AC33:$AC42)
A7: wfjsp5 | B7: 10×5×5 | C7: =AVERAGE('Exact Methods'!$F43:$F52) | D7: =AVERAGE('Exact Methods'!$K43:$K52) | E7: =AVERAGE('Exact Methods'!$Q43:$Q52) | F7: =AVERAGE('Exact Methods'!$W43:$W52) | G7: =AVERAGE('Exact Methods'!$AC43:$AC52)
A8: wfjsp6 | B8: 12×5×5 | C8: =AVERAGE('Exact Methods'!$F53:$F62) | D8: =AVERAGE('Exact Methods'!$K53:$K62) | E8: =AVERAGE('Exact Methods'!$Q53:$Q62) | F8: =AVERAGE('Exact Methods'!$W53:$W62) | G8: =AVERAGE('Exact Methods'!$AC53:$AC62)
A9: wfjsp7 | B9: 12×5×5 | C9: =AVERAGE('Exact Methods'!$F63:$F72) | D9: =AVERAGE('Exact Methods'!$K63:$K72) | E9: =AVERAGE('Exact Methods'!$Q63:$Q72) | F9: =AVERAGE('Exact Methods'!$W63:$W72) | G9: =AVERAGE('Exact Methods'!$AC63:$AC72)
A10: wfjsp8 | B10: 15×5×5 | C10: =AVERAGE('Exact Methods'!$F73:$F82) | D10: =AVERAGE('Exact Methods'!$K73:$K82) | E10: =AVERAGE('Exact Methods'!$Q73:$Q82) | F10: =AVERAGE('Exact Methods'!$W73:$W82) | G10: =AVERAGE('Exact Methods'!$AC73:$AC82)
A11: wfjsp9 | B11: 15×5×5 | C11: =AVERAGE('Exact Methods'!$F83:$F92) | D11: =AVERAGE('Exact Methods'!$K83:$K92) | E11: =AVERAGE('Exact Methods'!$Q83:$Q92) | F11: =AVERAGE('Exact Methods'!$W83:$W92) | G11: =AVERAGE('Exact Methods'!$AC83:$AC92)
A12: wfjsp10 | B12: 20×10×10 | C12: =AVERAGE('Exact Methods'!$F93:$F102) | D12: =AVERAGE('Exact Methods'!$K93:$K102) | E12: =AVERAGE('Exact Methods'!$Q93:$Q102) | F12: =AVERAGE('Exact Methods'!$W93:$W102) | G12: =AVERAGE('Exact Methods'!$AC93:$AC102)
A13: wfjsp11 | B13: 20×10×10 | C13: =AVERAGE('Exact Methods'!$F103:$F112) | D13: =AVERAGE('Exact Methods'!$K103:$K112) | E13: =AVERAGE('Exact Methods'!$Q103:$Q112) | F13: =AVERAGE('Exact Methods'!$W103:$W112) | G13: =AVERAGE('Exact Methods'!$AC103:$AC112)
A14: wfjsp12 | B14: 25×10×10 | C14: =AVERAGE('Exact Methods'!$F113:$F122) | D14: =AVERAGE('Exact Methods'!$K113:$K122) | E14: =AVERAGE('Exact Methods'!$Q113:$Q122) | F14: =AVERAGE('Exact Methods'!$W113:$W122) | G14: =AVERAGE('Exact Methods'!$AC113:$AC122)
A15: wfjsp13 | B15: 25×15×15 | C15: =AVERAGE('Exact Methods'!$F123:$F132) | D15: =AVERAGE('Exact Methods'!$K123:$K132) | E15: =AVERAGE('Exact Methods'!$Q123:$Q132) | F15: =AVERAGE('Exact Methods'!$W123:$W132) | G15: =AVERAGE('Exact Methods'!$AC123:$AC132)
A16: wfjsp14 | B16: 30×15×15 | C16: =AVERAGE('Exact Methods'!$F133:$F142) | D16: =AVERAGE('Exact Methods'!$K133:$K142) | E16: =AVERAGE('Exact Methods'!$Q133:$Q142) | F16: =AVERAGE('Exact Methods'!$W133:$W142) | G16: =AVERAGE('Exact Methods'!$AC133:$AC142)
A17: wfjsp15 | B17: 30×15×15 | C17: =AVERAGE('Exact Methods'!$F143:$F152) | D17: =AVERAGE('Exact Methods'!$K143:$K152) | E17: =AVERAGE('Exact Methods'!$Q143:$Q152) | F17: =AVERAGE('Exact Methods'!$W143:$W152) | G17: =AVERAGE('Exact Methods'!$AC143:$AC152)
A18: wfjsp16 | B18: 40×15×15 | C18: =AVERAGE('Exact Methods'!$F153:$F162) | D18: =AVERAGE('Exact Methods'!$K153:$K162) | E18: =AVERAGE('Exact Methods'!$Q153:$Q162) | F18: =AVERAGE('Exact Methods'!$W153:$W162) | G18: =AVERAGE('Exact Methods'!$AC153:$AC162)
A19: wfjsp17 | B19: 15×5×4 | C19: =AVERAGE('Exact Methods'!$F163:$F172) | D19: =AVERAGE('Exact Methods'!$K163:$K172) | E19: =AVERAGE('Exact Methods'!$Q163:$Q172) | F19: =AVERAGE('Exact Methods'!$W163:$W172) | G19: =AVERAGE('Exact Methods'!$AC163:$AC172)
A20: wfjsp18 | B20: 20×10×8 | C20: =AVERAGE('Exact Methods'!$F173:$F182) | D20: =AVERAGE('Exact Methods'!$K173:$K182) | E20: =AVERAGE('Exact Methods'!$Q173:$Q182) | F20: =AVERAGE('Exact Methods'!$W173:$W182) | G20: =AVERAGE('Exact Methods'!$AC173:$AC182)
A21: wfjsp19 | B21: 20×10×8 | C21: =AVERAGE('Exact Methods'!$F183:$F192) | D21: =AVERAGE('Exact Methods'!$K183:$K192) | E21: =AVERAGE('Exact Methods'!$Q183:$Q192) | F21: =AVERAGE('Exact Methods'!$W183:$W192) | G21: =AVERAGE('Exact Methods'!$AC183:$AC192)
A22: wfjsp20 | B22: 25×10×8 | C22: =AVERAGE('Exact Methods'!$F193:$F202) | D22: =AVERAGE('Exact Methods'!$K193:$K202) | E22: =AVERAGE('Exact Methods'!$Q193:$Q202) | F22: =AVERAGE('Exact Methods'!$W193:$W202) | G22: =AVERAGE('Exact Methods'!$AC193:$AC202)
A23: wfjsp21 | B23: 25×15×12 | C23: =AVERAGE('Exact Methods'!$F203:$F212) | D23: =AVERAGE('Exact Methods'!$K203:$K212) | E23: =AVERAGE('Exact Methods'!$Q203:$Q212) | F23: =AVERAGE('Exact Methods'!$W203:$W212) | G23: =AVERAGE('Exact Methods'!$AC203:$AC212)
A24: wfjsp22 | B24: 30×15×12 | C24: =AVERAGE('Exact Methods'!$F213:$F222) | D24: =AVERAGE('Exact Methods'!$K213:$K222) | E24: =AVERAGE('Exact Methods'!$Q213:$Q222) | F24: =AVERAGE('Exact Methods'!$W213:$W222) | G24: =AVERAGE('Exact Methods'!$AC213:$AC222)
A25: wfjsp23 | B25: 30×15×12 | C25: =AVERAGE('Exact Methods'!$F223:$F232) | D25: =AVERAGE('Exact Methods'!$K223:$K232) | E25: =AVERAGE('Exact Methods'!$Q223:$Q232) | F25: =AVERAGE('Exact Methods'!$W223:$W232) | G25: =AVERAGE('Exact Methods'!$AC223:$AC232)
A26: wfjsp24 | B26: 40×15×12 | C26: =AVERAGE('Exact Methods'!$F233:$F242) | D26: =AVERAGE('Exact Methods'!$K233:$K242) | E26: =AVERAGE('Exact Methods'!$Q233:$Q242) | F26: =AVERAGE('Exact Methods'!$W233:$W242) | G26: =AVERAGE('Exact Methods'!$AC233:$AC242)
A27: Average | C27: =AVERAGE(C3:C26) | D27: =AVERAGE(D3:D26) | E27: =AVERAGE(E3:E26) | F27: =AVERAGE(F3:F26) | G27: =AVERAGE(G3:G26)
A30: Number of optimal solutions (Gap = 0)
A31: Instance set | B31: Scale | C31: CP | D31: LBBD_CP_TS | E31: LBBD_CP | F31: CP_LBBD_CP | G31: CP_LBBD_CP_TS
A32: wfjsp1 | B32: 5×3×3 | C32: =COUNTIF('Exact Methods'!F3:F12,0) | D32: =COUNTIF('Exact Methods'!K3:K12,0) | E32: =COUNTIF('Exact Methods'!Q3:Q12,0) | F32: =COUNTIF('Exact Methods'!W3:W12,0) | G32: =COUNTIF('Exact Methods'!AC3:AC12,0)
A33: wfjsp2 | B33: 7×3×3 | C33: =COUNTIF('Exact Methods'!F13:F22,0) | D33: =COUNTIF('Exact Methods'!K13:K22,0) | E33: =COUNTIF('Exact Methods'!Q13:Q22,0) | F33: =COUNTIF('Exact Methods'!W13:W22,0) | G33: =COUNTIF('Exact Methods'!AC13:AC22,0)
A34: wfjsp3 | B34: 7×4×4 | C34: =COUNTIF('Exact Methods'!F23:F32,0) | D34: =COUNTIF('Exact Methods'!K23:K32,0) | E34: =COUNTIF('Exact Methods'!Q23:Q32,0) | F34: =COUNTIF('Exact Methods'!W23:W32,0) | G34: =COUNTIF('Exact Methods'!AC23:AC32,0)
A35: wfjsp4 | B35: 10×5×5 | C35: =COUNTIF('Exact Methods'!F33:F42,0) | D35: =COUNTIF('Exact Methods'!K33:K42,0) | E35: =COUNTIF('Exact Methods'!Q33:Q42,0) | F35: =COUNTIF('Exact Methods'!W33:W42,0) | G35: =COUNTIF('Exact Methods'!AC33:AC42,0)
A36: wfjsp5 | B36: 10×5×5 | C36: =COUNTIF('Exact Methods'!F43:F52,0) | D36: =COUNTIF('Exact Methods'!K43:K52,0) | E36: =COUNTIF('Exact Methods'!Q43:Q52,0) | F36: =COUNTIF('Exact Methods'!W43:W52,0) | G36: =COUNTIF('Exact Methods'!AC43:AC52,0)
A37: wfjsp6 | B37: 12×5×5 | C37: =COUNTIF('Exact Methods'!F53:F62,0) | D37: =COUNTIF('Exact Methods'!K53:K62,0) | E37: =COUNTIF('Exact Methods'!Q53:Q62,0) | F37: =COUNTIF('Exact Methods'!W53:W62,0) | G37: =COUNTIF('Exact Methods'!AC53:AC62,0)
A38: wfjsp7 | B38: 12×5×5 | C38: =COUNTIF('Exact Methods'!F63:F72,0) | D38: =COUNTIF('Exact Methods'!K63:K72,0) | E38: =COUNTIF('Exact Methods'!Q63:Q72,0) | F38: =COUNTIF('Exact Methods'!W63:W72,0) | G38: =COUNTIF('Exact Methods'!AC63:AC72,0)
A39: wfjsp8 | B39: 15×5×5 | C39: =COUNTIF('Exact Methods'!F73:F82,0) | D39: =COUNTIF('Exact Methods'!K73:K82,0) | E39: =COUNTIF('Exact Methods'!Q73:Q82,0) | F39: =COUNTIF('Exact Methods'!W73:W82,0) | G39: =COUNTIF('Exact Methods'!AC73:AC82,0)
A40: wfjsp9 | B40: 15×5×5 | C40: =COUNTIF('Exact Methods'!F83:F92,0) | D40: =COUNTIF('Exact Methods'!K83:K92,0) | E40: =COUNTIF('Exact Methods'!Q83:Q92,0) | F40: =COUNTIF('Exact Methods'!W83:W92,0) | G40: =COUNTIF('Exact Methods'!AC83:AC92,0)
A41: wfjsp10 | B41: 20×10×10 | C41: =COUNTIF('Exact Methods'!F93:F102,0) | D41: =COUNTIF('Exact Methods'!K93:K102,0) | E41: =COUNTIF('Exact Methods'!Q93:Q102,0) | F41: =COUNTIF('Exact Methods'!W93:W102,0) | G41: =COUNTIF('Exact Methods'!AC93:AC102,0)
A42: wfjsp11 | B42: 20×10×10 | C42: =COUNTIF('Exact Methods'!F103:F112,0) | D42: =COUNTIF('Exact Methods'!K103:K112,0) | E42: =COUNTIF('Exact Methods'!Q103:Q112,0) | F42: =COUNTIF('Exact Methods'!W103:W112,0) | G42: =COUNTIF('Exact Methods'!AC103:AC112,0)
...

Sheet TSvsF&F
A1: Deviation from the CP solution (CP 1 h, HPC), WFJSP; FaF chain = mean over seeds 1-5, "Best" = per-instance best of the 5 seeds
A2: Instance set | B2: Scale | C2: TS_1000_2_5 | D2: TS_2000_5_5 | E2: TS_5000_5_5 | F2: TS_10000_10_5 | G2: TS_25000_15_10 | H2: TS_50000_30_20 | I2: FaF | J2: FaFM | K2: FaFMJ | L2: FaFMx2 | M2: TS@FaF | N2: TS@FaFM | O2: TSN1@FaFM | P2: FaF Best | Q2: FaFM Best | R2: TSN1_2000_5_5 | S2: TSN1_10000_10_5 | T2: FaFMx3
A3: wfjsp1 | B3: 5×3×3 | C3: =AVERAGE(TS!E3:E12) | D3: =AVERAGE(TS!H3:H12) | E3: =AVERAGE(TS!K3:K12) | F3: =AVERAGE(TS!N3:N12) | G3: =AVERAGE(TS!Q3:Q12) | H3: =AVERAGE(TS!T3:T12) | I3: =AVERAGE(FaF!G3:G12) | J3: =AVERAGE(FaF!L3:L12) | K3: =AVERAGE(FaF!Q3:Q12) | L3: =AVERAGE(FaF!V3:V12) | M3: =AVERAGE(FaF!AA3:AA12) | N3: =AVERAGE(FaF!AF3:AF12) | O3: =AVERAGE(FaF!AK3:AK12) | P3: =AVERAGE(FaF!H3:H12) | Q3: =AVERAGE(FaF!M3:M12) | R3: =AVERAGE(FaF!AO3:AO12) | S3: =AVERAGE(FaF!AR3:AR12) | T3: =AVERAGE(FaF!AV3:AV12)
A4: wfjsp2 | B4: 7×3×3 | C4: =AVERAGE(TS!E13:E22) | D4: =AVERAGE(TS!H13:H22) | E4: =AVERAGE(TS!K13:K22) | F4: =AVERAGE(TS!N13:N22) | G4: =AVERAGE(TS!Q13:Q22) | H4: =AVERAGE(TS!T13:T22) | I4: =AVERAGE(FaF!G13:G22) | J4: =AVERAGE(FaF!L13:L22) | K4: =AVERAGE(FaF!Q13:Q22) | L4: =AVERAGE(FaF!V13:V22) | M4: =AVERAGE(FaF!AA13:AA22) | N4: =AVERAGE(FaF!AF13:AF22) | O4: =AVERAGE(FaF!AK13:AK22) | P4: =AVERAGE(FaF!H13:H22) | Q4: =AVERAGE(FaF!M13:M22) | R4: =AVERAGE(FaF!AO13:AO22) | S4: =AVERAGE(FaF!AR13:AR22) | T4: =AVERAGE(FaF!AV13:AV22)
A5: wfjsp3 | B5: 7×4×4 | C5: =AVERAGE(TS!E23:E32) | D5: =AVERAGE(TS!H23:H32) | E5: =AVERAGE(TS!K23:K32) | F5: =AVERAGE(TS!N23:N32) | G5: =AVERAGE(TS!Q23:Q32) | H5: =AVERAGE(TS!T23:T32) | I5: =AVERAGE(FaF!G23:G32) | J5: =AVERAGE(FaF!L23:L32) | K5: =AVERAGE(FaF!Q23:Q32) | L5: =AVERAGE(FaF!V23:V32) | M5: =AVERAGE(FaF!AA23:AA32) | N5: =AVERAGE(FaF!AF23:AF32) | O5: =AVERAGE(FaF!AK23:AK32) | P5: =AVERAGE(FaF!H23:H32) | Q5: =AVERAGE(FaF!M23:M32) | R5: =AVERAGE(FaF!AO23:AO32) | S5: =AVERAGE(FaF!AR23:AR32) | T5: =AVERAGE(FaF!AV23:AV32)
A6: wfjsp4 | B6: 10×5×5 | C6: =AVERAGE(TS!E33:E42) | D6: =AVERAGE(TS!H33:H42) | E6: =AVERAGE(TS!K33:K42) | F6: =AVERAGE(TS!N33:N42) | G6: =AVERAGE(TS!Q33:Q42) | H6: =AVERAGE(TS!T33:T42) | I6: =AVERAGE(FaF!G33:G42) | J6: =AVERAGE(FaF!L33:L42) | K6: =AVERAGE(FaF!Q33:Q42) | L6: =AVERAGE(FaF!V33:V42) | M6: =AVERAGE(FaF!AA33:AA42) | N6: =AVERAGE(FaF!AF33:AF42) | O6: =AVERAGE(FaF!AK33:AK42) | P6: =AVERAGE(FaF!H33:H42) | Q6: =AVERAGE(FaF!M33:M42) | R6: =AVERAGE(FaF!AO33:AO42) | S6: =AVERAGE(FaF!AR33:AR42) | T6: =AVERAGE(FaF!AV33:AV42)
A7: wfjsp5 | B7: 10×5×5 | C7: =AVERAGE(TS!E43:E52) | D7: =AVERAGE(TS!H43:H52) | E7: =AVERAGE(TS!K43:K52) | F7: =AVERAGE(TS!N43:N52) | G7: =AVERAGE(TS!Q43:Q52) | H7: =AVERAGE(TS!T43:T52) | I7: =AVERAGE(FaF!G43:G52) | J7: =AVERAGE(FaF!L43:L52) | K7: =AVERAGE(FaF!Q43:Q52) | L7: =AVERAGE(FaF!V43:V52) | M7: =AVERAGE(FaF!AA43:AA52) | N7: =AVERAGE(FaF!AF43:AF52) | O7: =AVERAGE(FaF!AK43:AK52) | P7: =AVERAGE(FaF!H43:H52) | Q7: =AVERAGE(FaF!M43:M52) | R7: =AVERAGE(FaF!AO43:AO52) | S7: =AVERAGE(FaF!AR43:AR52) | T7: =AVERAGE(FaF!AV43:AV52)
A8: wfjsp6 | B8: 12×5×5 | C8: =AVERAGE(TS!E53:E62) | D8: =AVERAGE(TS!H53:H62) | E8: =AVERAGE(TS!K53:K62) | F8: =AVERAGE(TS!N53:N62) | G8: =AVERAGE(TS!Q53:Q62) | H8: =AVERAGE(TS!T53:T62) | I8: =AVERAGE(FaF!G53:G62) | J8: =AVERAGE(FaF!L53:L62) | K8: =AVERAGE(FaF!Q53:Q62) | L8: =AVERAGE(FaF!V53:V62) | M8: =AVERAGE(FaF!AA53:AA62) | N8: =AVERAGE(FaF!AF53:AF62) | O8: =AVERAGE(FaF!AK53:AK62) | P8: =AVERAGE(FaF!H53:H62) | Q8: =AVERAGE(FaF!M53:M62) | R8: =AVERAGE(FaF!AO53:AO62) | S8: =AVERAGE(FaF!AR53:AR62) | T8: =AVERAGE(FaF!AV53:AV62)
A9: wfjsp7 | B9: 12×5×5 | C9: =AVERAGE(TS!E63:E72) | D9: =AVERAGE(TS!H63:H72) | E9: =AVERAGE(TS!K63:K72) | F9: =AVERAGE(TS!N63:N72) | G9: =AVERAGE(TS!Q63:Q72) | H9: =AVERAGE(TS!T63:T72) | I9: =AVERAGE(FaF!G63:G72) | J9: =AVERAGE(FaF!L63:L72) | K9: =AVERAGE(FaF!Q63:Q72) | L9: =AVERAGE(FaF!V63:V72) | M9: =AVERAGE(FaF!AA63:AA72) | N9: =AVERAGE(FaF!AF63:AF72) | O9: =AVERAGE(FaF!AK63:AK72) | P9: =AVERAGE(FaF!H63:H72) | Q9: =AVERAGE(FaF!M63:M72) | R9: =AVERAGE(FaF!AO63:AO72) | S9: =AVERAGE(FaF!AR63:AR72) | T9: =AVERAGE(FaF!AV63:AV72)
A10: wfjsp8 | B10: 15×5×5 | C10: =AVERAGE(TS!E73:E82) | D10: =AVERAGE(TS!H73:H82) | E10: =AVERAGE(TS!K73:K82) | F10: =AVERAGE(TS!N73:N82) | G10: =AVERAGE(TS!Q73:Q82) | H10: =AVERAGE(TS!T73:T82) | I10: =AVERAGE(FaF!G73:G82) | J10: =AVERAGE(FaF!L73:L82) | K10: =AVERAGE(FaF!Q73:Q82) | L10: =AVERAGE(FaF!V73:V82) | M10: =AVERAGE(FaF!AA73:AA82) | N10: =AVERAGE(FaF!AF73:AF82) | O10: =AVERAGE(FaF!AK73:AK82) | P10: =AVERAGE(FaF!H73:H82) | Q10: =AVERAGE(FaF!M73:M82) | R10: =AVERAGE(FaF!AO73:AO82) | S10: =AVERAGE(FaF!AR73:AR82) | T10: =AVERAGE(FaF!AV73:AV82)
A11: wfjsp9 | B11: 15×5×5 | C11: =AVERAGE(TS!E83:E92) | D11: =AVERAGE(TS!H83:H92) | E11: =AVERAGE(TS!K83:K92) | F11: =AVERAGE(TS!N83:N92) | G11: =AVERAGE(TS!Q83:Q92) | H11: =AVERAGE(TS!T83:T92) | I11: =AVERAGE(FaF!G83:G92) | J11: =AVERAGE(FaF!L83:L92) | K11: =AVERAGE(FaF!Q83:Q92) | L11: =AVERAGE(FaF!V83:V92) | M11: =AVERAGE(FaF!AA83:AA92) | N11: =AVERAGE(FaF!AF83:AF92) | O11: =AVERAGE(FaF!AK83:AK92) | P11: =AVERAGE(FaF!H83:H92) | Q11: =AVERAGE(FaF!M83:M92) | R11: =AVERAGE(FaF!AO83:AO92) | S11: =AVERAGE(FaF!AR83:AR92) | T11: =AVERAGE(FaF!AV83:AV92)
A12: wfjsp10 | B12: 20×10×10 | C12: =AVERAGE(TS!E93:E102) | D12: =AVERAGE(TS!H93:H102) | E12: =AVERAGE(TS!K93:K102) | F12: =AVERAGE(TS!N93:N102) | G12: =AVERAGE(TS!Q93:Q102) | H12: =AVERAGE(TS!T93:T102) | I12: =AVERAGE(FaF!G93:G102) | J12: =AVERAGE(FaF!L93:L102) | K12: =AVERAGE(FaF!Q93:Q102) | L12: =AVERAGE(FaF!V93:V102) | M12: =AVERAGE(FaF!AA93:AA102) | N12: =AVERAGE(FaF!AF93:AF102) | O12: =AVERAGE(FaF!AK93:AK102) | P12: =AVERAGE(FaF!H93:H102) | Q12: =AVERAGE(FaF!M93:M102) | R12: =AVERAGE(FaF!AO93:AO102) | S12: =AVERAGE(FaF!AR93:AR102) | T12: =AVERAGE(FaF!AV93:AV102)
A13: wfjsp11 | B13: 20×10×10 | C13: =AVERAGE(TS!E103:E112) | D13: =AVERAGE(TS!H103:H112) | E13: =AVERAGE(TS!K103:K112) | F13: =AVERAGE(TS!N103:N112) | G13: =AVERAGE(TS!Q103:Q112) | H13: =AVERAGE(TS!T103:T112) | I13: =AVERAGE(FaF!G103:G112) | J13: =AVERAGE(FaF!L103:L112) | K13: =AVERAGE(FaF!Q103:Q112) | L13: =AVERAGE(FaF!V103:V112) | M13: =AVERAGE(FaF!AA103:AA112) | N13: =AVERAGE(FaF!AF103:AF112) | O13: =AVERAGE(FaF!AK103:AK112) | P13: =AVERAGE(FaF!H103:H112) | Q13: =AVERAGE(FaF!M103:M112) | R13: =AVERAGE(FaF!AO103:AO112) | S13: =AVERAGE(FaF!AR103:AR112) | T13: =AVERAGE(FaF!AV103:AV112)
A14: wfjsp12 | B14: 25×10×10 | C14: =AVERAGE(TS!E113:E122) | D14: =AVERAGE(TS!H113:H122) | E14: =AVERAGE(TS!K113:K122) | F14: =AVERAGE(TS!N113:N122) | G14: =AVERAGE(TS!Q113:Q122) | H14: =AVERAGE(TS!T113:T122) | I14: =AVERAGE(FaF!G113:G122) | J14: =AVERAGE(FaF!L113:L122) | K14: =AVERAGE(FaF!Q113:Q122) | L14: =AVERAGE(FaF!V113:V122) | M14: =AVERAGE(FaF!AA113:AA122) | N14: =AVERAGE(FaF!AF113:AF122) | O14: =AVERAGE(FaF!AK113:AK122) | P14: =AVERAGE(FaF!H113:H122) | Q14: =AVERAGE(FaF!M113:M122) | R14: =AVERAGE(FaF!AO113:AO122) | S14: =AVERAGE(FaF!AR113:AR122) | T14: =AVERAGE(FaF!AV113:AV122)
A15: wfjsp13 | B15: 25×15×15 | C15: =AVERAGE(TS!E123:E132) | D15: =AVERAGE(TS!H123:H132) | E15: =AVERAGE(TS!K123:K132) | F15: =AVERAGE(TS!N123:N132) | G15: =AVERAGE(TS!Q123:Q132) | H15: =AVERAGE(TS!T123:T132) | I15: =AVERAGE(FaF!G123:G132) | J15: =AVERAGE(FaF!L123:L132) | K15: =AVERAGE(FaF!Q123:Q132) | L15: =AVERAGE(FaF!V123:V132) | M15: =AVERAGE(FaF!AA123:AA132) | N15: =AVERAGE(FaF!AF123:AF132) | O15: =AVERAGE(FaF!AK123:AK132) | P15: =AVERAGE(FaF!H123:H132) | Q15: =AVERAGE(FaF!M123:M132) | R15: =AVERAGE(FaF!AO123:AO132) | S15: =AVERAGE(FaF!AR123:AR132) | T15: =AVERAGE(FaF!AV123:AV132)
A16: wfjsp14 | B16: 30×15×15 | C16: =AVERAGE(TS!E133:E142) | D16: =AVERAGE(TS!H133:H142) | E16: =AVERAGE(TS!K133:K142) | F16: =AVERAGE(TS!N133:N142) | G16: =AVERAGE(TS!Q133:Q142) | H16: =AVERAGE(TS!T133:T142) | I16: =AVERAGE(FaF!G133:G142) | J16: =AVERAGE(FaF!L133:L142) | K16: =AVERAGE(FaF!Q133:Q142) | L16: =AVERAGE(FaF!V133:V142) | M16: =AVERAGE(FaF!AA133:AA142) | N16: =AVERAGE(FaF!AF133:AF142) | O16: =AVERAGE(FaF!AK133:AK142) | P16: =AVERAGE(FaF!H133:H142) | Q16: =AVERAGE(FaF!M133:M142) | R16: =AVERAGE(FaF!AO133:AO142) | S16: =AVERAGE(FaF!AR133:AR142) | T16: =AVERAGE(FaF!AV133:AV142)
A17: wfjsp15 | B17: 30×15×15 | C17: =AVERAGE(TS!E143:E152) | D17: =AVERAGE(TS!H143:H152) | E17: =AVERAGE(TS!K143:K152) | F17: =AVERAGE(TS!N143:N152) | G17: =AVERAGE(TS!Q143:Q152) | H17: =AVERAGE(TS!T143:T152) | I17: =AVERAGE(FaF!G143:G152) | J17: =AVERAGE(FaF!L143:L152) | K17: =AVERAGE(FaF!Q143:Q152) | L17: =AVERAGE(FaF!V143:V152) | M17: =AVERAGE(FaF!AA143:AA152) | N17: =AVERAGE(FaF!AF143:AF152) | O17: =AVERAGE(FaF!AK143:AK152) | P17: =AVERAGE(FaF!H143:H152) | Q17: =AVERAGE(FaF!M143:M152) | R17: =AVERAGE(FaF!AO143:AO152) | S17: =AVERAGE(FaF!AR143:AR152) | T17: =AVERAGE(FaF!AV143:AV152)
A18: wfjsp16 | B18: 40×15×15 | C18: =AVERAGE(TS!E153:E162) | D18: =AVERAGE(TS!H153:H162) | E18: =AVERAGE(TS!K153:K162) | F18: =AVERAGE(TS!N153:N162) | G18: =AVERAGE(TS!Q153:Q162) | H18: =AVERAGE(TS!T153:T162) | I18: =AVERAGE(FaF!G153:G162) | J18: =AVERAGE(FaF!L153:L162) | K18: =AVERAGE(FaF!Q153:Q162) | L18: =AVERAGE(FaF!V153:V162) | M18: =AVERAGE(FaF!AA153:AA162) | N18: =AVERAGE(FaF!AF153:AF162) | O18: =AVERAGE(FaF!AK153:AK162) | P18: =AVERAGE(FaF!H153:H162) | Q18: =AVERAGE(FaF!M153:M162) | R18: =AVERAGE(FaF!AO153:AO162) | S18: =AVERAGE(FaF!AR153:AR162) | T18: =AVERAGE(FaF!AV153:AV162)
A19: wfjsp17 | B19: 15×5×4 | C19: =AVERAGE(TS!E163:E172) | D19: =AVERAGE(TS!H163:H172) | E19: =AVERAGE(TS!K163:K172) | F19: =AVERAGE(TS!N163:N172) | G19: =AVERAGE(TS!Q163:Q172) | H19: =AVERAGE(TS!T163:T172) | I19: =AVERAGE(FaF!G163:G172) | J19: =AVERAGE(FaF!L163:L172) | K19: =AVERAGE(FaF!Q163:Q172) | L19: =AVERAGE(FaF!V163:V172) | M19: =AVERAGE(FaF!AA163:AA172) | N19: =AVERAGE(FaF!AF163:AF172) | O19: =AVERAGE(FaF!AK163:AK172) | P19: =AVERAGE(FaF!H163:H172) | Q19: =AVERAGE(FaF!M163:M172) | R19: =AVERAGE(FaF!AO163:AO172) | S19: =AVERAGE(FaF!AR163:AR172) | T19: =AVERAGE(FaF!AV163:AV172)
A20: wfjsp18 | B20: 20×10×8 | C20: =AVERAGE(TS!E173:E182) | D20: =AVERAGE(TS!H173:H182) | E20: =AVERAGE(TS!K173:K182) | F20: =AVERAGE(TS!N173:N182) | G20: =AVERAGE(TS!Q173:Q182) | H20: =AVERAGE(TS!T173:T182) | I20: =AVERAGE(FaF!G173:G182) | J20: =AVERAGE(FaF!L173:L182) | K20: =AVERAGE(FaF!Q173:Q182) | L20: =AVERAGE(FaF!V173:V182) | M20: =AVERAGE(FaF!AA173:AA182) | N20: =AVERAGE(FaF!AF173:AF182) | O20: =AVERAGE(FaF!AK173:AK182) | P20: =AVERAGE(FaF!H173:H182) | Q20: =AVERAGE(FaF!M173:M182) | R20: =AVERAGE(FaF!AO173:AO182) | S20: =AVERAGE(FaF!AR173:AR182) | T20: =AVERAGE(FaF!AV173:AV182)
A21: wfjsp19 | B21: 20×10×8 | C21: =AVERAGE(TS!E183:E192) | D21: =AVERAGE(TS!H183:H192) | E21: =AVERAGE(TS!K183:K192) | F21: =AVERAGE(TS!N183:N192) | G21: =AVERAGE(TS!Q183:Q192) | H21: =AVERAGE(TS!T183:T192) | I21: =AVERAGE(FaF!G183:G192) | J21: =AVERAGE(FaF!L183:L192) | K21: =AVERAGE(FaF!Q183:Q192) | L21: =AVERAGE(FaF!V183:V192) | M21: =AVERAGE(FaF!AA183:AA192) | N21: =AVERAGE(FaF!AF183:AF192) | O21: =AVERAGE(FaF!AK183:AK192) | P21: =AVERAGE(FaF!H183:H192) | Q21: =AVERAGE(FaF!M183:M192) | R21: =AVERAGE(FaF!AO183:AO192) | S21: =AVERAGE(FaF!AR183:AR192) | T21: =AVERAGE(FaF!AV183:AV192)
A22: wfjsp20 | B22: 25×10×8 | C22: =AVERAGE(TS!E193:E202) | D22: =AVERAGE(TS!H193:H202) | E22: =AVERAGE(TS!K193:K202) | F22: =AVERAGE(TS!N193:N202) | G22: =AVERAGE(TS!Q193:Q202) | H22: =AVERAGE(TS!T193:T202) | I22: =AVERAGE(FaF!G193:G202) | J22: =AVERAGE(FaF!L193:L202) | K22: =AVERAGE(FaF!Q193:Q202) | L22: =AVERAGE(FaF!V193:V202) | M22: =AVERAGE(FaF!AA193:AA202) | N22: =AVERAGE(FaF!AF193:AF202) | O22: =AVERAGE(FaF!AK193:AK202) | P22: =AVERAGE(FaF!H193:H202) | Q22: =AVERAGE(FaF!M193:M202) | R22: =AVERAGE(FaF!AO193:AO202) | S22: =AVERAGE(FaF!AR193:AR202) | T22: =AVERAGE(FaF!AV193:AV202)
A23: wfjsp21 | B23: 25×15×12 | C23: =AVERAGE(TS!E203:E212) | D23: =AVERAGE(TS!H203:H212) | E23: =AVERAGE(TS!K203:K212) | F23: =AVERAGE(TS!N203:N212) | G23: =AVERAGE(TS!Q203:Q212) | H23: =AVERAGE(TS!T203:T212) | I23: =AVERAGE(FaF!G203:G212) | J23: =AVERAGE(FaF!L203:L212) | K23: =AVERAGE(FaF!Q203:Q212) | L23: =AVERAGE(FaF!V203:V212) | M23: =AVERAGE(FaF!AA203:AA212) | N23: =AVERAGE(FaF!AF203:AF212) | O23: =AVERAGE(FaF!AK203:AK212) | P23: =AVERAGE(FaF!H203:H212) | Q23: =AVERAGE(FaF!M203:M212) | R23: =AVERAGE(FaF!AO203:AO212) | S23: =AVERAGE(FaF!AR203:AR212) | T23: =AVERAGE(FaF!AV203:AV212)
A24: wfjsp22 | B24: 30×15×12 | C24: =AVERAGE(TS!E213:E222) | D24: =AVERAGE(TS!H213:H222) | E24: =AVERAGE(TS!K213:K222) | F24: =AVERAGE(TS!N213:N222) | G24: =AVERAGE(TS!Q213:Q222) | H24: =AVERAGE(TS!T213:T222) | I24: =AVERAGE(FaF!G213:G222) | J24: =AVERAGE(FaF!L213:L222) | K24: =AVERAGE(FaF!Q213:Q222) | L24: =AVERAGE(FaF!V213:V222) | M24: =AVERAGE(FaF!AA213:AA222) | N24: =AVERAGE(FaF!AF213:AF222) | O24: =AVERAGE(FaF!AK213:AK222) | P24: =AVERAGE(FaF!H213:H222) | Q24: =AVERAGE(FaF!M213:M222) | R24: =AVERAGE(FaF!AO213:AO222) | S24: =AVERAGE(FaF!AR213:AR222) | T24: =AVERAGE(FaF!AV213:AV222)
A25: wfjsp23 | B25: 30×15×12 | C25: =AVERAGE(TS!E223:E232) | D25: =AVERAGE(TS!H223:H232) | E25: =AVERAGE(TS!K223:K232) | F25: =AVERAGE(TS!N223:N232) | G25: =AVERAGE(TS!Q223:Q232) | H25: =AVERAGE(TS!T223:T232) | I25: =AVERAGE(FaF!G223:G232) | J25: =AVERAGE(FaF!L223:L232) | K25: =AVERAGE(FaF!Q223:Q232) | L25: =AVERAGE(FaF!V223:V232) | M25: =AVERAGE(FaF!AA223:AA232) | N25: =AVERAGE(FaF!AF223:AF232) | O25: =AVERAGE(FaF!AK223:AK232) | P25: =AVERAGE(FaF!H223:H232) | Q25: =AVERAGE(FaF!M223:M232) | R25: =AVERAGE(FaF!AO223:AO232) | S25: =AVERAGE(FaF!AR223:AR232) | T25: =AVERAGE(FaF!AV223:AV232)
A26: wfjsp24 | B26: 40×15×12 | C26: =AVERAGE(TS!E233:E242) | D26: =AVERAGE(TS!H233:H242) | E26: =AVERAGE(TS!K233:K242) | F26: =AVERAGE(TS!N233:N242) | G26: =AVERAGE(TS!Q233:Q242) | H26: =AVERAGE(TS!T233:T242) | I26: =AVERAGE(FaF!G233:G242) | J26: =AVERAGE(FaF!L233:L242) | K26: =AVERAGE(FaF!Q233:Q242) | L26: =AVERAGE(FaF!V233:V242) | M26: =AVERAGE(FaF!AA233:AA242) | N26: =AVERAGE(FaF!AF233:AF242) | O26: =AVERAGE(FaF!AK233:AK242) | P26: =AVERAGE(FaF!H233:H242) | Q26: =AVERAGE(FaF!M233:M242) | R26: =AVERAGE(FaF!AO233:AO242) | S26: =AVERAGE(FaF!AR233:AR242) | T26: =AVERAGE(FaF!AV233:AV242)
A27: Average | C27: =AVERAGE(C3:C26) | D27: =AVERAGE(D3:D26) | E27: =AVERAGE(E3:E26) | F27: =AVERAGE(F3:F26) | G27: =AVERAGE(G3:G26) | H27: =AVERAGE(H3:H26) | I27: =AVERAGE(I3:I26) | J27: =AVERAGE(J3:J26) | ... T27: =AVERAGE(T3:T26)
A30: Average CPU time (s), WFJSP
A31: Instance set | B31: Scale | C31: TS_1000_2_5 | D31: TS_2000_5_5 | E31: TS_5000_5_5 | F31: TS_10000_10_5 | G31: TS_25000_15_10 | H31: TS_50000_30_20 | I31: FaF | J31: FaFM | K31: FaFMJ | L31: FaFMx2 | M31: TS@FaF | N31: TS@FaFM | O31: TSN1@FaFM | P31: TSN1_2000_5_5 | Q31: TSN1_10000_10_5 | T31: FaFMx3
A32: wfjsp1 | B32: 5×3×3 | C32: =AVERAGE(TS!D3:D12) | D32: =AVERAGE(TS!G3:G12) | E32: =AVERAGE(TS!J3:J12) | F32: =AVERAGE(TS!M3:M12) | G32: =AVERAGE(TS!P3:P12) | H32: =AVERAGE(TS!S3:S12) | I32: =AVERAGE(FaF!F3:F12) | J32: =AVERAGE(FaF!K3:K12) | K32: =AVERAGE(FaF!P3:P12) | L32: =AVERAGE(FaF!U3:U12) | M32: =AVERAGE(FaF!Z3:Z12) | N32: =AVERAGE(FaF!AE3:AE12) | O32: =AVERAGE(FaF!AJ3:AJ12) | P32: =AVERAGE(FaF!AN3:AN12) | Q32: =AVERAGE(FaF!AQ3:AQ12) | T32: =AVERAGE(FaF!AU3:AU12)
A33: wfjsp2 | B33: 7×3×3 | C33: =AVERAGE(TS!D13:D22) | D33: =AVERAGE(TS!G13:G22) | E33: =AVERAGE(TS!J13:J22) | F33: =AVERAGE(TS!M13:M22) | G33: =AVERAGE(TS!P13:P22) | H33: =AVERAGE(TS!S13:S22) | I33: =AVERAGE(FaF!F13:F22) | J33: =AVERAGE(FaF!K13:K22) | K33: =AVERAGE(FaF!P13:P22) | L33: =AVERAGE(FaF!U13:U22) | M33: =AVERAGE(FaF!Z13:Z22) | N33: =AVERAGE(FaF!AE13:AE22) | O33: =AVERAGE(FaF!AJ13:AJ22) | P33: =AVERAGE(FaF!AN13:AN22) | Q33: =AVERAGE(FaF!AQ13:AQ22) | T33: =AVERAGE(FaF!AU13:AU22)
A34: wfjsp3 | B34: 7×4×4 | C34: =AVERAGE(TS!D23:D32) | D34: =AVERAGE(TS!G23:G32) | E34: =AVERAGE(TS!J23:J32) | F34: =AVERAGE(TS!M23:M32) | G34: =AVERAGE(TS!P23:P32) | H34: =AVERAGE(TS!S23:S32) | I34: =AVERAGE(FaF!F23:F32) | J34: =AVERAGE(FaF!K23:K32) | K34: =AVERAGE(FaF!P23:P32) | L34: =AVERAGE(FaF!U23:U32) | M34: =AVERAGE(FaF!Z23:Z32) | N34: =AVERAGE(FaF!AE23:AE32) | O34: =AVERAGE(FaF!AJ23:AJ32) | P34: =AVERAGE(FaF!AN23:AN32) | Q34: =AVERAGE(FaF!AQ23:AQ32) | T34: =AVERAGE(FaF!AU23:AU32)
A35: wfjsp4 | B35: 10×5×5 | C35: =AVERAGE(TS!D33:D42) | D35: =AVERAGE(TS!G33:G42) | E35: =AVERAGE(TS!J33:J42) | F35: =AVERAGE(TS!M33:M42) | G35: =AVERAGE(TS!P33:P42) | H35: =AVERAGE(TS!S33:S42) | I35: =AVERAGE(FaF!F33:F42) | J35: =AVERAGE(FaF!K33:K42) | K35: =AVERAGE(FaF!P33:P42) | L35: =AVERAGE(FaF!U33:U42) | M35: =AVERAGE(FaF!Z33:Z42) | N35: =AVERAGE(FaF!AE33:AE42) | O35: =AVERAGE(FaF!AJ33:AJ42) | P35: =AVERAGE(FaF!AN33:AN42) | Q35: =AVERAGE(FaF!AQ33:AQ42) | T35: =AVERAGE(FaF!AU33:AU42)
A36: wfjsp5 | B36: 10×5×5 | C36: =AVERAGE(TS!D43:D52) | D36: =AVERAGE(TS!G43:G52) | E36: =AVERAGE(TS!J43:J52) | F36: =AVERAGE(TS!M43:M52) | G36: =AVERAGE(TS!P43:P52) | H36: =AVERAGE(TS!S43:S52) | I36: =AVERAGE(FaF!F43:F52) | J36: =AVERAGE(FaF!K43:K52) | K36: =AVERAGE(FaF!P43:P52) | L36: =AVERAGE(FaF!U43:U52) | M36: =AVERAGE(FaF!Z43:Z52) | N36: =AVERAGE(FaF!AE43:AE52) | O36: =AVERAGE(FaF!AJ43:AJ52) | P36: =AVERAGE(FaF!AN43:AN52) | Q36: =AVERAGE(FaF!AQ43:AQ52) | T36: =AVERAGE(FaF!AU43:AU52)
A37: wfjsp6 | B37: 12×5×5 | C37: =AVERAGE(TS!D53:D62) | D37: =AVERAGE(TS!G53:G62) | E37: =AVERAGE(TS!J53:J62) | F37: =AVERAGE(TS!M53:M62) | G37: =AVERAGE(TS!P53:P62) | H37: =AVERAGE(TS!S53:S62) | I37: =AVERAGE(FaF!F53:F62) | J37: =AVERAGE(FaF!K53:K62) | K37: =AVERAGE(FaF!P53:P62) | L37: =AVERAGE(FaF!U53:U62) | M37: =AVERAGE(FaF!Z53:Z62) | N37: =AVERAGE(FaF!AE53:AE62) | O37: =AVERAGE(FaF!AJ53:AJ62) | P37: =AVERAGE(FaF!AN53:AN62) | Q37: =AVERAGE(FaF!AQ53:AQ62) | T37: =AVERAGE(FaF!AU53:AU62)
A38: wfjsp7 | B38: 12×5×5 | C38: =AVERAGE(TS!D63:D72) | D38: =AVERAGE(TS!G63:G72) | E38: =AVERAGE(TS!J63:J72) | F38: =AVERAGE(TS!M63:M72) | G38: =AVERAGE(TS!P63:P72) | H38: =AVERAGE(TS!S63:S72) | I38: =AVERAGE(FaF!F63:F72) | J38: =AVERAGE(FaF!K63:K72) | K38: =AVERAGE(FaF!P63:P72) | L38: =AVERAGE(FaF!U63:U72) | M38: =AVERAGE(FaF!Z63:Z72) | N38: =AVERAGE(FaF!AE63:AE72) | O38: =AVERAGE(FaF!AJ63:AJ72) | P38: =AVERAGE(FaF!AN63:AN72) | Q38: =AVERAGE(FaF!AQ63:AQ72) | T38: =AVERAGE(FaF!AU63:AU72)
A39: wfjsp8 | B39: 15×5×5 | C39: =AVERAGE(TS!D73:D82) | D39: =AVERAGE(TS!G73:G82) | E39: =AVERAGE(TS!J73:J82) | F39: =AVERAGE(TS!M73:M82) | G39: =AVERAGE(TS!P73:P82) | H39: =AVERAGE(TS!S73:S82) | I39: =AVERAGE(FaF!F73:F82) | J39: =AVERAGE(FaF!K73:K82) | K39: =AVERAGE(FaF!P73:P82) | L39: =AVERAGE(FaF!U73:U82) | M39: =AVERAGE(FaF!Z73:Z82) | N39: =AVERAGE(FaF!AE73:AE82) | O39: =AVERAGE(FaF!AJ73:AJ82) | P39: =AVERAGE(FaF!AN73:AN82) | Q39: =AVERAGE(FaF!AQ73:AQ82) | T39: =AVERAGE(FaF!AU73:AU82)
A40: wfjsp9 | B40: 15×5×5 | C40: =AVERAGE(TS!D83:D92) | D40: =AVERAGE(TS!G83:G92) | E40: =AVERAGE(TS!J83:J92) | F40: =AVERAGE(TS!M83:M92) | G40: =AVERAGE(TS!P83:P92) | H40: =AVERAGE(TS!S83:S92) | I40: =AVERAGE(FaF!F83:F92) | J40: =AVERAGE(FaF!K83:K92) | K40: =AVERAGE(FaF!P83:P92) | L40: =AVERAGE(FaF!U83:U92) | M40: =AVERAGE(FaF!Z83:Z92) | N40: =AVERAGE(FaF!AE83:AE92) | O40: =AVERAGE(FaF!AJ83:AJ92) | P40: =AVERAGE(FaF!AN83:AN92) | Q40: =AVERAGE(FaF!AQ83:AQ92) | T40: =AVERAGE(FaF!AU83:AU92)
A41: wfjsp10 | B41: 20×10×10 | C41: =AVERAGE(TS!D93:D102) | D41: =AVERAGE(TS!G93:G102) | E41: =AVERAGE(TS!J93:J102) | F41: =AVERAGE(TS!M93:M102) | G41: =AVERAGE(TS!P93:P102) | H41: =AVERAGE(TS!S93:S102) | I41: =AVERAGE(FaF!F93:F102) | J41: =AVERAGE(FaF!K93:K102) | K41: =AVERAGE(FaF!P93:P102) | L41: =AVERAGE(FaF!U93:U102) | M41: =AVERAGE(FaF!Z93:Z102) | N41: =AVERAGE(FaF!AE93:AE102) | O41: =AVERAGE(FaF!AJ93:AJ102) | P41: =AVERAGE(FaF!AN93:AN102) | Q41: =AVERAGE(FaF!AQ93:AQ102) | T41: =AVERAGE(FaF!AU93:AU102)
A42: wfjsp11 | B42: 20×10×10 | C42: =AVERAGE(TS!D103:D112) | D42: =AVERAGE(TS!G103:G112) | E42: =AVERAGE(TS!J103:J112) | F42: =AVERAGE(TS!M103:M112) | G42: =AVERAGE(TS!P103:P112) | H42: =AVERAGE(TS!S103:S112) | I42: =AVERAGE(FaF!F103:F112) | J42: =AVERAGE(FaF!K103:K112) | K42: =AVERAGE(FaF!P103:P112) | L42: =AVERAGE(FaF!U103:U112) | M42: =AVERAGE(FaF!Z103:Z112) | N42: =AVERAGE(FaF!AE103:AE112) | O42: =AVERAGE(FaF!AJ103:AJ112) | P42: =AVERAGE(FaF!AN103:AN112) | Q42: =AVERAGE(FaF!AQ103:AQ112) | T42: =AVERAGE(FaF!AU103:AU112)
...

Sheet Exact Methods
A1: Scale(Jobs,M,W) | B1: Instance | C1: CP (IBM CP optimizer, 1 h, HPC) | H1: LBBD_CP_TS | N1: LBBD_CP | T1: CP_LBBD_CP | Z1: CP_LBBD_CP_TS
C2: UB | D2: LB | E2: CPU Time | F2: Gap% | G2: RPD | H2: UB | I2: LB | J2: CPU Time | K2: Gap% | L2: RPD | M2: Q | N2: UB | O2: LB | P2: CPU Time | Q2: Gap% | R2: RPD | S2: Q | T2: UB | U2: LB | V2: CPU Time | W2: Gap% | X2: RPD | Y2: Q | Z2: UB | AA2: LB | AB2: CPU Time | AC2: Gap% | AD2: RPD | AE2: Q
A3: 5*3*3 | B3: wfjsp_1_1 | C3: 268 | D3: 268 | E3: 1.375 | F3: =(C3-D3)/C3 | G3: =(C3-MIN(C3,H3,N3,T3,Z3))/MIN(C3,H3,N3,T3,Z3) | H3: 268 | I3: 268 | J3: 383.835 | K3: =(H3-I3)/H3 | L3: =(H3-MIN(C3,H3,N3,T3,Z3))/MIN(C3,H3,N3,T3,Z3) | M3: =(H3-C3)/C3 | N3: 268 | O3: 268 | P3: 410.896 | Q3: =(N3-O3)/N3 | R3: =(N3-MIN(C3,H3,N3,T3,Z3))/MIN(C3,H3,N3,T3,Z3) | S3: =(N3-C3)/C3 | T3: 268 | U3: 268 | V3: 1.34613 | W3: =(T3-U3)/T3 | X3: =(T3-MIN(C3,H3,N3,T3,Z3))/MIN(C3,H3,N3,T3,Z3) | Y3: =(T3-C3)/C3 | Z3: 268 | AA3: 268 | AB3: 1.39944 | AC3: =(Z3-AA3)/Z3 | AD3: =(Z3-MIN(C3,H3,N3,T3,Z3))/MIN(C3,H3,N3,T3,Z3) | AE3: =(Z3-C3)/C3
B4: wfjsp_1_2 | C4: 287 | D4: 287 | E4: 0.25 | F4: =(C4-D4)/C4 | G4: =(C4-MIN(C4,H4,N4,T4,Z4))/MIN(C4,H4,N4,T4,Z4) | H4: 287 | I4: 287 | J4: 212.453 | K4: =(H4-I4)/H4 | L4: =(H4-MIN(C4,H4,N4,T4,Z4))/MIN(C4,H4,N4,T4,Z4) | M4: =(H4-C4)/C4 | N4: 287 | O4: 287 | P4: 132.54 | Q4: =(N4-O4)/N4 | R4: =(N4-MIN(C4,H4,N4,T4,Z4))/MIN(C4,H4,N4,T4,Z4) | S4: =(N4-C4)/C4 | T4: 287 | U4: 287 | V4: 0.212552 | W4: =(T4-U4)/T4 | X4: =(T4-MIN(C4,H4,N4,T4,Z4))/MIN(C4,H4,N4,T4,Z4) | Y4: =(T4-C4)/C4 | Z4: 287 | AA4: 287 | AB4: 0.223913 | AC4: =(Z4-AA4)/Z4 | AD4: =(Z4-MIN(C4,H4,N4,T4,Z4))/MIN(C4,H4,N4,T4,Z4) | AE4: =(Z4-C4)/C4
B5: wfjsp_1_3 | C5: 347 | D5: 347 | E5: 0.875 | F5: =(C5-D5)/C5 | G5: =(C5-MIN(C5,H5,N5,T5,Z5))/MIN(C5,H5,N5,T5,Z5) | H5: 347 | I5: 347 | J5: 113.705 | K5: =(H5-I5)/H5 | L5: =(H5-MIN(C5,H5,N5,T5,Z5))/MIN(C5,H5,N5,T5,Z5) | M5: =(H5-C5)/C5 | N5: 347 | O5: 347 | P5: 42.4248 | Q5: =(N5-O5)/N5 | R5: =(N5-MIN(C5,H5,N5,T5,Z5))/MIN(C5,H5,N5,T5,Z5) | S5: =(N5-C5)/C5 | T5: 347 | U5: 347 | V5: 0.870813 | W5: =(T5-U5)/T5 | X5: =(T5-MIN(C5,H5,N5,T5,Z5))/MIN(C5,H5,N5,T5,Z5) | Y5: =(T5-C5)/C5 | Z5: 347 | AA5: 347 | AB5: 0.964943 | AC5: =(Z5-AA5)/Z5 | AD5: =(Z5-MIN(C5,H5,N5,T5,Z5))/MIN(C5,H5,N5,T5,Z5) | AE5: =(Z5-C5)/C5
B6: wfjsp_1_4 | C6: 315 | D6: 315 | E6: 2.5625 | F6: =(C6-D6)/C6 | G6: =(C6-MIN(C6,H6,N6,T6,Z6))/MIN(C6,H6,N6,T6,Z6) | H6: 315 | I6: 315 | J6: 1418.81 | K6: =(H6-I6)/H6 | L6: =(H6-MIN(C6,H6,N6,T6,Z6))/MIN(C6,H6,N6,T6,Z6) | M6: =(H6-C6)/C6 | N6: 315 | O6: 315 | P6: 1148.15 | Q6: =(N6-O6)/N6 | R6: =(N6-MIN(C6,H6,N6,T6,Z6))/MIN(C6,H6,N6,T6,Z6) | S6: =(N6-C6)/C6 | T6: 315 | U6: 315 | V6: 3.03582 | W6: =(T6-U6)/T6 | X6: =(T6-MIN(C6,H6,N6,T6,Z6))/MIN(C6,H6,N6,T6,Z6) | Y6: =(T6-C6)/C6 | Z6: 315 | AA6: 315 | AB6: 2.72624 | AC6: =(Z6-AA6)/Z6 | AD6: =(Z6-MIN(C6,H6,N6,T6,Z6))/MIN(C6,H6,N6,T6,Z6) | AE6: =(Z6-C6)/C6
B7: wfjsp_1_5 | C7: 265 | D7: 265 | E7: 0.875 | F7: =(C7-D7)/C7 | G7: =(C7-MIN(C7,H7,N7,T7,Z7))/MIN(C7,H7,N7,T7,Z7) | H7: 265 | I7: 265 | J7: 22.4485 | K7: =(H7-I7)/H7 | L7: =(H7-MIN(C7,H7,N7,T7,Z7))/MIN(C7,H7,N7,T7,Z7) | M7: =(H7-C7)/C7 | N7: 265 | O7: 265 | P7: 9.66402 | Q7: =(N7-O7)/N7 | R7: =(N7-MIN(C7,H7,N7,T7,Z7))/MIN(C7,H7,N7,T7,Z7) | S7: =(N7-C7)/C7 | T7: 265 | U7: 265 | V7: 0.987526 | W7: =(T7-U7)/T7 | X7: =(T7-MIN(C7,H7,N7,T7,Z7))/MIN(C7,H7,N7,T7,Z7) | Y7: =(T7-C7)/C7 | Z7: 265 | AA7: 265 | AB7: 0.971988 | AC7: =(Z7-AA7)/Z7 | AD7: =(Z7-MIN(C7,H7,N7,T7,Z7))/MIN(C7,H7,N7,T7,Z7) | AE7: =(Z7-C7)/C7
B8: wfjsp_1_6 | C8: 291 | D8: 291 | E8: 2.625 | F8: =(C8-D8)/C8 | G8: =(C8-MIN(C8,H8,N8,T8,Z8))/MIN(C8,H8,N8,T8,Z8) | H8: 291 | I8: 286 | J8: 3600.06 | K8: =(H8-I8)/H8 | L8: =(H8-MIN(C8,H8,N8,T8,Z8))/MIN(C8,H8,N8,T8,Z8) | M8: =(H8-C8)/C8 | N8: 291 | O8: 286 | P8: 3600.07 | Q8: =(N8-O8)/N8 | R8: =(N8-MIN(C8,H8,N8,T8,Z8))/MIN(C8,H8,N8,T8,Z8) | S8: =(N8-C8)/C8 | T8: 291 | U8: 291 | V8: 2.83098 | W8: =(T8-U8)/T8 | X8: =(T8-MIN(C8,H8,N8,T8,Z8))/MIN(C8,H8,N8,T8,Z8) | Y8: =(T8-C8)/C8 | Z8: 291 | AA8: 291 | AB8: 2.62391 | AC8: =(Z8-AA8)/Z8 | AD8: =(Z8-MIN(C8,H8,N8,T8,Z8))/MIN(C8,H8,N8,T8,Z8) | AE8: =(Z8-C8)/C8
B9: wfjsp_1_7 | C9: 265 | D9: 265 | E9: 2.625 | F9: =(C9-D9)/C9 | G9: =(C9-MIN(C9,H9,N9,T9,Z9))/MIN(C9,H9,N9,T9,Z9) | H9: 265 | I9: 265 | J9: 217.106 | K9: =(H9-I9)/H9 | L9: =(H9-MIN(C9,H9,N9,T9,Z9))/MIN(C9,H9,N9,T9,Z9) | M9: =(H9-C9)/C9 | N9: 265 | O9: 265 | P9: 132.094 | Q9: =(N9-O9)/N9 | R9: =(N9-MIN(C9,H9,N9,T9,Z9))/MIN(C9,H9,N9,T9,Z9) | S9: =(N9-C9)/C9 | T9: 265 | U9: 265 | V9: 2.62812 | W9: =(T9-U9)/T9 | X9: =(T9-MIN(C9,H9,N9,T9,Z9))/MIN(C9,H9,N9,T9,Z9) | Y9: =(T9-C9)/C9 | Z9: 265 | AA9: 265 | AB9: 2.8956 | AC9: =(Z9-AA9)/Z9 | AD9: =(Z9-MIN(C9,H9,N9,T9,Z9))/MIN(C9,H9,N9,T9,Z9) | AE9: =(Z9-C9)/C9
B10: wfjsp_1_8 | C10: 328 | D10: 328 | E10: 2.0625 | F10: =(C10-D10)/C10 | G10: =(C10-MIN(C10,H10,N10,T10,Z10))/MIN(C10,H10,N10,T10,Z10) | H10: 328 | I10: 328 | J10: 17.6488 | K10: =(H10-I10)/H10 | L10: =(H10-MIN(C10,H10,N10,T10,Z10))/MIN(C10,H10,N10,T10,Z10) | M10: =(H10-C10)/C10 | N10: 328 | O10: 328 | P10: 33.7391 | Q10: =(N10-O10)/N10 | R10: =(N10-MIN(C10,H10,N10,T10,Z10))/MIN(C10,H10,N10,T10,Z10) | S10: =(N10-C10)/C10 | T10: 328 | U10: 328 | V10: 2.08766 | W10: =(T10-U10)/T10 | X10: =(T10-MIN(C10,H10,N10,T10,Z10))/MIN(C10,H10,N10,T10,Z10) | Y10: =(T10-C10)/C10 | Z10: 328 | AA10: 328 | AB10: 2.23358 | AC10: =(Z10-AA10)/Z10 | AD10: =(Z10-MIN(C10,H10,N10,T10,Z10))/MIN(C10,H10,N10,T10,Z10) | AE10: =(Z10-C10)/C10
B11: wfjsp_1_9 | C11: 252 | D11: 252 | E11: 1.375 | F11: =(C11-D11)/C11 | G11: =(C11-MIN(C11,H11,N11,T11,Z11))/MIN(C11,H11,N11,T11,Z11) | H11: 252 | I11: 252 | J11: 33.4599 | K11: =(H11-I11)/H11 | L11: =(H11-MIN(C11,H11,N11,T11,Z11))/MIN(C11,H11,N11,T11,Z11) | M11: =(H11-C11)/C11 | N11: 252 | O11: 252 | P11: 17.5265 | Q11: =(N11-O11)/N11 | R11: =(N11-MIN(C11,H11,N11,T11,Z11))/MIN(C11,H11,N11,T11,Z11) | S11: =(N11-C11)/C11 | T11: 252 | U11: 252 | V11: 1.38111 | W11: =(T11-U11)/T11 | X11: =(T11-MIN(C11,H11,N11,T11,Z11))/MIN(C11,H11,N11,T11,Z11) | Y11: =(T11-C11)/C11 | Z11: 252 | AA11: 252 | AB11: 1.45413 | AC11: =(Z11-AA11)/Z11 | AD11: =(Z11-MIN(C11,H11,N11,T11,Z11))/MIN(C11,H11,N11,T11,Z11) | AE11: =(Z11-C11)/C11
B12: wfjsp_1_10 | C12: 316 | D12: 316 | E12: 8.125 | F12: =(C12-D12)/C12 | G12: =(C12-MIN(C12,H12,N12,T12,Z12))/MIN(C12,H12,N12,T12,Z12) | H12: 316 | I12: 316 | J12: 4.02357 | K12: =(H12-I12)/H12 | L12: =(H12-MIN(C12,H12,N12,T12,Z12))/MIN(C12,H12,N12,T12,Z12) | M12: =(H12-C12)/C12 | N12: 316 | O12: 316 | P12: 9.01683 | Q12: =(N12-O12)/N12 | R12: =(N12-MIN(C12,H12,N12,T12,Z12))/MIN(C12,H12,N12,T12,Z12) | S12: =(N12-C12)/C12 | T12: 316 | U12: 316 | V12: 8.91891 | W12: =(T12-U12)/T12 | X12: =(T12-MIN(C12,H12,N12,T12,Z12))/MIN(C12,H12,N12,T12,Z12) | Y12: =(T12-C12)/C12 | Z12: 316 | AA12: 316 | AB12: 8.16091 | AC12: =(Z12-AA12)/Z12 | AD12: =(Z12-MIN(C12,H12,N12,T12,Z12))/MIN(C12,H12,N12,T12,Z12) | AE12: =(Z12-C12)/C12
A13: 7*3*3 | B13: wfjsp_2_1 | C13: 336 | D13: 336 | E13: 32.2812 | F13: =(C13-D13)/C13 | G13: =(C13-MIN(C13,H13,N13,T13,Z13))/MIN(C13,H13,N13,T13,Z13) | H13: 336 | I13: 336 | J13: 108.112 | K13: =(H13-I13)/H13 | L13: =(H13-MIN(C13,H13,N13,T13,Z13))/MIN(C13,H13,N13,T13,Z13) | M13: =(H13-C13)/C13 | N13: 336 | O13: 336 | P13: 102.309 | Q13: =(N13-O13)/N13 | R13: =(N13-MIN(C13,H13,N13,T13,Z13))/MIN(C13,H13,N13,T13,Z13) | S13: =(N13-C13)/C13 | T13: 336 | U13: 336 | V13: 37.5062 | W13: =(T13-U13)/T13 | X13: =(T13-MIN(C13,H13,N13,T13,Z13))/MIN(C13,H13,N13,T13,Z13) | Y13: =(T13-C13)/C13 | Z13: 336 | AA13: 336 | AB13: 35.4842 | AC13: =(Z13-AA13)/Z13 | AD13: =(Z13-MIN(C13,H13,N13,T13,Z13))/MIN(C13,H13,N13,T13,Z13) | AE13: =(Z13-C13)/C13
B14: wfjsp_2_2 | C14: 368 | D14: 368 | E14: 29 | F14: =(C14-D14)/C14 | G14: =(C14-MIN(C14,H14,N14,T14,Z14))/MIN(C14,H14,N14,T14,Z14) | H14: 368 | I14: 368 | J14: 18.1698 | K14: =(H14-I14)/H14 | L14: =(H14-MIN(C14,H14,N14,T14,Z14))/MIN(C14,H14,N14,T14,Z14) | M14: =(H14-C14)/C14 | N14: 368 | O14: 368 | P14: 16.3102 | Q14: =(N14-O14)/N14 | R14: =(N14-MIN(C14,H14,N14,T14,Z14))/MIN(C14,H14,N14,T14,Z14) | S14: =(N14-C14)/C14 | T14: 368 | U14: 368 | V14: 31.315 | W14: =(T14-U14)/T14 | X14: =(T14-MIN(C14,H14,N14,T14,Z14))/MIN(C14,H14,N14,T14,Z14) | Y14: =(T14-C14)/C14 | Z14: 368 | AA14: 368 | AB14: 30.6267 | AC14: =(Z14-AA14)/Z14 | AD14: =(Z14-MIN(C14,H14,N14,T14,Z14))/MIN(C14,H14,N14,T14,Z14) | AE14: =(Z14-C14)/C14
B15: wfjsp_2_3 | C15: 421 | D15: 421 | E15: 16.5 | F15: =(C15-D15)/C15 | G15: =(C15-MIN(C15,H15,N15,T15,Z15))/MIN(C15,H15,N15,T15,Z15) | H15: 421 | I15: 417 | J15: 3600 | K15: =(H15-I15)/H15 | L15: =(H15-MIN(C15,H15,N15,T15,Z15))/MIN(C15,H15,N15,T15,Z15) | M15: =(H15-C15)/C15 | N15: 421 | O15: 416 | P15: 3600.27 | Q15: =(N15-O15)/N15 | R15: =(N15-MIN(C15,H15,N15,T15,Z15))/MIN(C15,H15,N15,T15,Z15) | S15: =(N15-C15)/C15 | T15: 421 | U15: 421 | V15: 16.0182 | W15: =(T15-U15)/T15 | X15: =(T15-MIN(C15,H15,N15,T15,Z15))/MIN(C15,H15,N15,T15,Z15) | Y15: =(T15-C15)/C15 | Z15: 421 | AA15: 421 | AB15: 18.2531 | AC15: =(Z15-AA15)/Z15 | AD15: =(Z15-MIN(C15,H15,N15,T15,Z15))/MIN(C15,H15,N15,T15,Z15) | AE15: =(Z15-C15)/C15
B16: wfjsp_2_4 | C16: 378 | D16: 378 | E16: 54.3125 | F16: =(C16-D16)/C16 | G16: =(C16-MIN(C16,H16,N16,T16,Z16))/MIN(C16,H16,N16,T16,Z16) | H16: 378 | I16: 378 | J16: 101.257 | K16: =(H16-I16)/H16 | L16: =(H16-MIN(C16,H16,N16,T16,Z16))/MIN(C16,H16,N16,T16,Z16) | M16: =(H16-C16)/C16 | N16: 378 | O16: 378 | P16: 63.3897 | Q16: =(N16-O16)/N16 | R16: =(N16-MIN(C16,H16,N16,T16,Z16))/MIN(C16,H16,N16,T16,Z16) | S16: =(N16-C16)/C16 | T16: 378 | U16: 378 | V16: 54.0686 | W16: =(T16-U16)/T16 | X16: =(T16-MIN(C16,H16,N16,T16,Z16))/MIN(C16,H16,N16,T16,Z16) | Y16: =(T16-C16)/C16 | Z16: 378 | AA16: 378 | AB16: 54.2218 | AC16: =(Z16-AA16)/Z16 | AD16: =(Z16-MIN(C16,H16,N16,T16,Z16))/MIN(C16,H16,N16,T16,Z16) | AE16: =(Z16-C16)/C16
B17: wfjsp_2_5 | C17: 270 | D17: 270 | E17: 1.75 | F17: =(C17-D17)/C17 | G17: =(C17-MIN(C17,H17,N17,T17,Z17))/MIN(C17,H17,N17,T17,Z17) | H17: 270 | I17: 270 | J17: 2.73361 | K17: =(H17-I17)/H17 | L17: =(H17-MIN(C17,H17,N17,T17,Z17))/MIN(C17,H17,N17,T17,Z17) | M17: =(H17-C17)/C17 | N17: 270 | O17: 270 | P17: 2.79719 | Q17: =(N17-O17)/N17 | R17: =(N17-MIN(C17,H17,N17,T17,Z17))/MIN(C17,H17,N17,T17,Z17) | S17: =(N17-C17)/C17 | T17: 270 | U17: 270 | V17: 1.92023 | W17: =(T17-U17)/T17 | X17: =(T17-MIN(C17,H17,N17,T17,Z17))/MIN(C17,H17,N17,T17,Z17) | Y17: =(T17-C17)/C17 | Z17: 270 | AA17: 270 | AB17: 1.81399 | AC17: =(Z17-AA17)/Z17 | AD17: =(Z17-MIN(C17,H17,N17,T17,Z17))/MIN(C17,H17,N17,T17,Z17) | AE17: =(Z17-C17)/C17
B18: wfjsp_2_6 | C18: 416 | D18: 416 | E18: 135.125 | F18: =(C18-D18)/C18 | G18: =(C18-MIN(C18,H18,N18,T18,Z18))/MIN(C18,H18,N18,T18,Z18) | H18: 416 | I18: 416 | J18: 81.8405 | K18: =(H18-I18)/H18 | L18: =(H18-MIN(C18,H18,N18,T18,Z18))/MIN(C18,H18,N18,T18,Z18) | M18: =(H18-C18)/C18 | N18: 416 | O18: 416 | P18: 54.6786 | Q18: =(N18-O18)/N18 | R18: =(N18-MIN(C18,H18,N18,T18,Z18))/MIN(C18,H18,N18,T18,Z18) | S18: =(N18-C18)/C18 | T18: 416 | U18: 416 | V18: 141.921 | W18: =(T18-U18)/T18 | X18: =(T18-MIN(C18,H18,N18,T18,Z18))/MIN(C18,H18,N18,T18,Z18) | Y18: =(T18-C18)/C18 | Z18: 416 | AA18: 416 | AB18: 129.214 | AC18: =(Z18-AA18)/Z18 | AD18: =(Z18-MIN(C18,H18,N18,T18,Z18))/MIN(C18,H18,N18,T18,Z18) | AE18: =(Z18-C18)/C18
B19: wfjsp_2_7 | C19: 395 | D19: 395 | E19: 194.625 | F19: =(C19-D19)/C19 | G19: =(C19-MIN(C19,H19,N19,T19,Z19))/MIN(C19,H19,N19,T19,Z19) | H19: 395 | I19: 395 | J19: 426.381 | K19: =(H19-I19)/H19 | L19: =(H19-MIN(C19,H19,N19,T19,Z19))/MIN(C19,H19,N19,T19,Z19) | M19: =(H19-C19)/C19 | N19: 395 | O19: 395 | P19: 401.003 | Q19: =(N19-O19)/N19 | R19: =(N19-MIN(C19,H19,N19,T19,Z19))/MIN(C19,H19,N19,T19,Z19) | S19: =(N19-C19)/C19 | T19: 395 | U19: 395 | V19: 201.031 | W19: =(T19-U19)/T19 | X19: =(T19-MIN(C19,H19,N19,T19,Z19))/MIN(C19,H19,N19,T19,Z19) | Y19: =(T19-C19)/C19 | Z19: 395 | AA19: 395 | AB19: 189.994 | AC19: =(Z19-AA19)/Z19 | AD19: =(Z19-MIN(C19,H19,N19,T19,Z19))/MIN(C19,H19,N19,T19,Z19) | AE19: =(Z19-C19)/C19
B20: wfjsp_2_8 | C20: 414 | D20: 414 | E20: 68 | F20: =(C20-D20)/C20 | G20: =(C20-MIN(C20,H20,N20,T20,Z20))/MIN(C20,H20,N20,T20,Z20) | H20: 414 | I20: 414 | J20: 74.9522 | K20: =(H20-I20)/H20 | L20: =(H20-MIN(C20,H20,N20,T20,Z20))/MIN(C20,H20,N20,T20,Z20) | M20: =(H20-C20)/C20 | N20: 414 | O20: 414 | P20: 169.635 | Q20: =(N20-O20)/N20 | R20: =(N20-MIN(C20,H20,N20,T20,Z20))/MIN(C20,H20,N20,T20,Z20) | S20: =(N20-C20)/C20 | T20: 414 | U20: 414 | V20: 78.6095 | W20: =(T20-U20)/T20 | X20: =(T20-MIN(C20,H20,N20,T20,Z20))/MIN(C20,H20,N20,T20,Z20) | Y20: =(T20-C20)/C20 | Z20: 414 | AA20: 414 | AB20: 68.7183 | AC20: =(Z20-AA20)/Z20 | AD20: =(Z20-MIN(C20,H20,N20,T20,Z20))/MIN(C20,H20,N20,T20,Z20) | AE20: =(Z20-C20)/C20
B21: wfjsp_2_9 | C21: 329 | D21: 329 | E21: 12.25 | F21: =(C21-D21)/C21 | G21: =(C21-MIN(C21,H21,N21,T21,Z21))/MIN(C21,H21,N21,T21,Z21) | H21: 329 | I21: 329 | J21: 113.883 | K21: =(H21-I21)/H21 | L21: =(H21-MIN(C21,H21,N21,T21,Z21))/MIN(C21,H21,N21,T21,Z21) | M21: =(H21-C21)/C21 | N21: 329 | O21: 329 | P21: 65.7746 | Q21: =(N21-O21)/N21 | R21: =(N21-MIN(C21,H21,N21,T21,Z21))/MIN(C21,H21,N21,T21,Z21) | S21: =(N21-C21)/C21 | T21: 329 | U21: 329 | V21: 13.2989 | W21: =(T21-U21)/T21 | X21: =(T21-MIN(C21,H21,N21,T21,Z21))/MIN(C21,H21,N21,T21,Z21) | Y21: =(T21-C21)/C21 | Z21: 329 | AA21: 329 | AB21: 12.2505 | AC21: =(Z21-AA21)/Z21 | AD21: =(Z21-MIN(C21,H21,N21,T21,Z21))/MIN(C21,H21,N21,T21,Z21) | AE21: =(Z21-C21)/C21
B22: wfjsp_2_10 | C22: 489 | D22: 230 | E22: 3600 | F22: =(C22-D22)/C22 | G22: =(C22-MIN(C22,H22,N22,T22,Z22))/MIN(C22,H22,N22,T22,Z22) | H22: 489 | I22: 489 | J22: 1.9847 | K22: =(H22-I22)/H22 | L22: =(H22-MIN(C22,H22,N22,T22,Z22))/MIN(C22,H22,N22,T22,Z22) | M22: =(H22-C22)/C22 | N22: 489 | O22: 489 | P22: 28.6586 | Q22: =(N22-O22)/N22 | R22: =(N22-MIN(C22,H22,N22,T22,Z22))/MIN(C22,H22,N22,T22,Z22) | S22: =(N22-C22)/C22 | T22: 489 | U22: 489 | V22: 1801.06 | W22: =(T22-U22)/T22 | X22: =(T22-MIN(C22,H22,N22,T22,Z22))/MIN(C22,H22,N22,T22,Z22) | Y22: =(T22-C22)/C22 | Z22: 489 | AA22: 489 | AB22: 1800.39 | AC22: =(Z22-AA22)/Z22 | AD22: =(Z22-MIN(C22,H22,N22,T22,Z22))/MIN(C22,H22,N22,T22,Z22) | AE22: =(Z22-C22)/C22
A23: 7*4*4 | B23: wfjsp_3_1 | C23: 419 | D23: 419 | E23: 81.8594 | F23: =(C23-D23)/C23 | G23: =(C23-MIN(C23,H23,N23,T23,Z23))/MIN(C23,H23,N23,T23,Z23) | H23: 419 | I23: 418 | J23: 3600.52 | K23: =(H23-I23)/H23 | L23: =(H23-MIN(C23,H23,N23,T23,Z23))/MIN(C23,H23,N23,T23,Z23) | M23: =(H23-C23)/C23 | N23: 419 | O23: 418 | P23: 3600.16 | Q23: =(N23-O23)/N23 | R23: =(N23-MIN(C23,H23,N23,T23,Z23))/MIN(C23,H23,N23,T23,Z23) | S23: =(N23-C23)/C23 | T23: 419 | U23: 419 | V23: 81.1368 | W23: =(T23-U23)/T23 | X23: =(T23-MIN(C23,H23,N23,T23,Z23))/MIN(C23,H23,N23,T23,Z23) | Y23: =(T23-C23)/C23 | Z23: 419 | AA23: 419 | AB23: 88.2001 | AC23: =(Z23-AA23)/Z23 | AD23: =(Z23-MIN(C23,H23,N23,T23,Z23))/MIN(C23,H23,N23,T23,Z23) | AE23: =(Z23-C23)/C23
B24: wfjsp_3_2 | C24: 543 | D24: 543 | E24: 202.594 | F24: =(C24-D24)/C24 | G24: =(C24-MIN(C24,H24,N24,T24,Z24))/MIN(C24,H24,N24,T24,Z24) | H24: 543 | I24: 538 | J24: 3600 | K24: =(H24-I24)/H24 | L24: =(H24-MIN(C24,H24,N24,T24,Z24))/MIN(C24,H24,N24,T24,Z24) | M24: =(H24-C24)/C24 | N24: 543 | O24: 538 | P24: 3600.03 | Q24: =(N24-O24)/N24 | R24: =(N24-MIN(C24,H24,N24,T24,Z24))/MIN(C24,H24,N24,T24,Z24) | S24: =(N24-C24)/C24 | T24: 543 | U24: 543 | V24: 223.209 | W24: =(T24-U24)/T24 | X24: =(T24-MIN(C24,H24,N24,T24,Z24))/MIN(C24,H24,N24,T24,Z24) | Y24: =(T24-C24)/C24 | Z24: 543 | AA24: 543 | AB24: 212.717 | AC24: =(Z24-AA24)/Z24 | AD24: =(Z24-MIN(C24,H24,N24,T24,Z24))/MIN(C24,H24,N24,T24,Z24) | AE24: =(Z24-C24)/C24
B25: wfjsp_3_3 | C25: 383 | D25: 383 | E25: 1.5 | F25: =(C25-D25)/C25 | G25: =(C25-MIN(C25,H25,N25,T25,Z25))/MIN(C25,H25,N25,T25,Z25) | H25: 383 | I25: 371 | J25: 3600 | K25: =(H25-I25)/H25 | L25: =(H25-MIN(C25,H25,N25,T25,Z25))/MIN(C25,H25,N25,T25,Z25) | M25: =(H25-C25)/C25 | N25: 383 | O25: 371 | P25: 3600.38 | Q25: =(N25-O25)/N25 | R25: =(N25-MIN(C25,H25,N25,T25,Z25))/MIN(C25,H25,N25,T25,Z25) | S25: =(N25-C25)/C25 | T25: 383 | U25: 383 | V25: 1.50785 | W25: =(T25-U25)/T25 | X25: =(T25-MIN(C25,H25,N25,T25,Z25))/MIN(C25,H25,N25,T25,Z25) | Y25: =(T25-C25)/C25 | Z25: 383 | AA25: 383 | AB25: 1.3114 | AC25: =(Z25-AA25)/Z25 | AD25: =(Z25-MIN(C25,H25,N25,T25,Z25))/MIN(C25,H25,N25,T25,Z25) | AE25: =(Z25-C25)/C25
B26: wfjsp_3_4 | C26: 443 | D26: 443 | E26: 70.875 | F26: =(C26-D26)/C26 | G26: =(C26-MIN(C26,H26,N26,T26,Z26))/MIN(C26,H26,N26,T26,Z26) | H26: 443 | I26: 437 | J26: 3600 | K26: =(H26-I26)/H26 | L26: =(H26-MIN(C26,H26,N26,T26,Z26))/MIN(C26,H26,N26,T26,Z26) | M26: =(H26-C26)/C26 | N26: 446 | O26: 437 | P26: 3600.02 | Q26: =(N26-O26)/N26 | R26: =(N26-MIN(C26,H26,N26,T26,Z26))/MIN(C26,H26,N26,T26,Z26) | S26: =(N26-C26)/C26 | T26: 443 | U26: 443 | V26: 77.8614 | W26: =(T26-U26)/T26 | X26: =(T26-MIN(C26,H26,N26,T26,Z26))/MIN(C26,H26,N26,T26,Z26) | Y26: =(T26-C26)/C26 | Z26: 443 | AA26: 443 | AB26: 74.1245 | AC26: =(Z26-AA26)/Z26 | AD26: =(Z26-MIN(C26,H26,N26,T26,Z26))/MIN(C26,H26,N26,T26,Z26) | AE26: =(Z26-C26)/C26
B27: wfjsp_3_5 | C27: 284 | D27: 284 | E27: 5.25 | F27: =(C27-D27)/C27 | G27: =(C27-MIN(C27,H27,N27,T27,Z27))/MIN(C27,H27,N27,T27,Z27) | H27: 284 | I27: 277 | J27: 3600.09 | K27: =(H27-I27)/H27 | L27: =(H27-MIN(C27,H27,N27,T27,Z27))/MIN(C27,H27,N27,T27,Z27) | M27: =(H27-C27)/C27 | N27: 284 | O27: 277 | P27: 3600.24 | Q27: =(N27-O27)/N27 | R27: =(N27-MIN(C27,H27,N27,T27,Z27))/MIN(C27,H27,N27,T27,Z27) | S27: =(N27-C27)/C27 | T27: 284 | U27: 284 | V27: 6.12289 | W27: =(T27-U27)/T27 | X27: =(T27-MIN(C27,H27,N27,T27,Z27))/MIN(C27,H27,N27,T27,Z27) | Y27: =(T27-C27)/C27 | Z27: 284 | AA27: 284 | AB27: 5.64674 | AC27: =(Z27-AA27)/Z27 | AD27: =(Z27-MIN(C27,H27,N27,T27,Z27))/MIN(C27,H27,N27,T27,Z27) | AE27: =(Z27-C27)/C27
B28: wfjsp_3_6 | C28: 529 | D28: 529 | E28: 2663.88 | F28: =(C28-D28)/C28 | G28: =(C28-MIN(C28,H28,N28,T28,Z28))/MIN(C28,H28,N28,T28,Z28) | H28: 529 | I28: 510 | J28: 3600.33 | K28: =(H28-I28)/H28 | L28: =(H28-MIN(C28,H28,N28,T28,Z28))/MIN(C28,H28,N28,T28,Z28) | M28: =(H28-C28)/C28 | N28: 532 | O28: 510 | P28: 3600.91 | Q28: =(N28-O28)/N28 | R28: =(N28-MIN(C28,H28,N28,T28,Z28))/MIN(C28,H28,N28,T28,Z28) | S28: =(N28-C28)/C28 | T28: 529 | U28: 509 | V28: 3600.17 | W28: =(T28-U28)/T28 | X28: =(T28-MIN(C28,H28,N28,T28,Z28))/MIN(C28,H28,N28,T28,Z28) | Y28: =(T28-C28)/C28 | Z28: 529 | AA28: 509 | AB28: 3601.05 | AC28: =(Z28-AA28)/Z28 | AD28: =(Z28-MIN(C28,H28,N28,T28,Z28))/MIN(C28,H28,N28,T28,Z28) | AE28: =(Z28-C28)/C28
B29: wfjsp_3_7 | C29: 342 | D29: 342 | E29: 7.34375 | F29: =(C29-D29)/C29 | G29: =(C29-MIN(C29,H29,N29,T29,Z29))/MIN(C29,H29,N29,T29,Z29) | H29: 342 | I29: 334 | J29: 3600 | K29: =(H29-I29)/H29 | L29: =(H29-MIN(C29,H29,N29,T29,Z29))/MIN(C29,H29,N29,T29,Z29) | M29: =(H29-C29)/C29 | N29: 345 | O29: 334 | P29: 3600.15 | Q29: =(N29-O29)/N29 | R29: =(N29-MIN(C29,H29,N29,T29,Z29))/MIN(C29,H29,N29,T29,Z29) | S29: =(N29-C29)/C29 | T29: 342 | U29: 342 | V29: 9.16911 | W29: =(T29-U29)/T29 | X29: =(T29-MIN(C29,H29,N29,T29,Z29))/MIN(C29,H29,N29,T29,Z29) | Y29: =(T29-C29)/C29 | Z29: 342 | AA29: 342 | AB29: 8.22108 | AC29: =(Z29-AA29)/Z29 | AD29: =(Z29-MIN(C29,H29,N29,T29,Z29))/MIN(C29,H29,N29,T29,Z29) | AE29: =(Z29-C29)/C29
B30: wfjsp_3_8 | C30: 492 | D30: 492 | E30: 163.312 | F30: =(C30-D30)/C30 | G30: =(C30-MIN(C30,H30,N30,T30,Z30))/MIN(C30,H30,N30,T30,Z30) | H30: 492 | I30: 486 | J30: 3600.08 | K30: =(H30-I30)/H30 | L30: =(H30-MIN(C30,H30,N30,T30,Z30))/MIN(C30,H30,N30,T30,Z30) | M30: =(H30-C30)/C30 | N30: 492 | O30: 486 | P30: 3600.02 | Q30: =(N30-O30)/N30 | R30: =(N30-MIN(C30,H30,N30,T30,Z30))/MIN(C30,H30,N30,T30,Z30) | S30: =(N30-C30)/C30 | T30: 492 | U30: 492 | V30: 170.911 | W30: =(T30-U30)/T30 | X30: =(T30-MIN(C30,H30,N30,T30,Z30))/MIN(C30,H30,N30,T30,Z30) | Y30: =(T30-C30)/C30 | Z30: 492 | AA30: 492 | AB30: 162.087 | AC30: =(Z30-AA30)/Z30 | AD30: =(Z30-MIN(C30,H30,N30,T30,Z30))/MIN(C30,H30,N30,T30,Z30) | AE30: =(Z30-C30)/C30
B31: wfjsp_3_9 | C31: 534 | D31: 534 | E31: 2 | F31: =(C31-D31)/C31 | G31: =(C31-MIN(C31,H31,N31,T31,Z31))/MIN(C31,H31,N31,T31,Z31) | H31: 534 | I31: 497 | J31: 3600.28 | K31: =(H31-I31)/H31 | L31: =(H31-MIN(C31,H31,N31,T31,Z31))/MIN(C31,H31,N31,T31,Z31) | M31: =(H31-C31)/C31 | N31: 534 | O31: 497 | P31: 3601.38 | Q31: =(N31-O31)/N31 | R31: =(N31-MIN(C31,H31,N31,T31,Z31))/MIN(C31,H31,N31,T31,Z31) | S31: =(N31-C31)/C31 | T31: 534 | U31: 534 | V31: 2.11329 | W31: =(T31-U31)/T31 | X31: =(T31-MIN(C31,H31,N31,T31,Z31))/MIN(C31,H31,N31,T31,Z31) | Y31: =(T31-C31)/C31 | Z31: 534 | AA31: 534 | AB31: 2.14756 | AC31: =(Z31-AA31)/Z31 | AD31: =(Z31-MIN(C31,H31,N31,T31,Z31))/MIN(C31,H31,N31,T31,Z31) | AE31: =(Z31-C31)/C31
B32: wfjsp_3_10 | C32: 455 | D32: 455 | E32: 11.125 | F32: =(C32-D32)/C32 | G32: =(C32-MIN(C32,H32,N32,T32,Z32))/MIN(C32,H32,N32,T32,Z32) | H32: 455 | I32: 410 | J32: 3600.09 | K32: =(H32-I32)/H32 | L32: =(H32-MIN(C32,H32,N32,T32,Z32))/MIN(C32,H32,N32,T32,Z32) | M32: =(H32-C32)/C32 | N32: 455 | O32: 409 | P32: 3600.29 | Q32: =(N32-O32)/N32 | R32: =(N32-MIN(C32,H32,N32,T32,Z32))/MIN(C32,H32,N32,T32,Z32) | S32: =(N32-C32)/C32 | T32: 455 | U32: 455 | V32: 11.5272 | W32: =(T32-U32)/T32 | X32: =(T32-MIN(C32,H32,N32,T32,Z32))/MIN(C32,H32,N32,T32,Z32) | Y32: =(T32-C32)/C32 | Z32: 455 | AA32: 455 | AB32: 11.0019 | AC32: =(Z32-AA32)/Z32 | AD32: =(Z32-MIN(C32,H32,N32,T32,Z32))/MIN(C32,H32,N32,T32,Z32) | AE32: =(Z32-C32)/C32
A33: 10*5*5 | B33: wfjsp_4_1 | C33: 277 | D33: 277 | E33: 1230 | F33: =(C33-D33)/C33 | G33: =(C33-MIN(C33,H33,N33,T33,Z33))/MIN(C33,H33,N33,T33,Z33) | H33: 281 | I33: 272 | J33: 3600.32 | K33: =(H33-I33)/H33 | L33: =(H33-MIN(C33,H33,N33,T33,Z33))/MIN(C33,H33,N33,T33,Z33) | M33: =(H33-C33)/C33 | N33: 288 | O33: 272 | P33: 3600.57 | Q33: =(N33-O33)/N33 | R33: =(N33-MIN(C33,H33,N33,T33,Z33))/MIN(C33,H33,N33,T33,Z33) | S33: =(N33-C33)/C33 | T33: 277 | U33: 277 | V33: 1345.61 | W33: =(T33-U33)/T33 | X33: =(T33-MIN(C33,H33,N33,T33,Z33))/MIN(C33,H33,N33,T33,Z33) | Y33: =(T33-C33)/C33 | Z33: 277 | AA33: 277 | AB33: 1163.27 | AC33: =(Z33-AA33)/Z33 | AD33: =(Z33-MIN(C33,H33,N33,T33,Z33))/MIN(C33,H33,N33,T33,Z33) | AE33: =(Z33-C33)/C33
B34: wfjsp_4_2 | C34: 350 | D34: 253 | E34: 3600 | F34: =(C34-D34)/C34 | G34: =(C34-MIN(C34,H34,N34,T34,Z34))/MIN(C34,H34,N34,T34,Z34) | H34: 348 | I34: 343 | J34: 3600 | K34: =(H34-I34)/H34 | L34: =(H34-MIN(C34,H34,N34,T34,Z34))/MIN(C34,H34,N34,T34,Z34) | M34: =(H34-C34)/C34 | N34: 352 | O34: 343 | P34: 3601.12 | Q34: =(N34-O34)/N34 | R34: =(N34-MIN(C34,H34,N34,T34,Z34))/MIN(C34,H34,N34,T34,Z34) | S34: =(N34-C34)/C34 | T34: 350 | U34: 342 | V34: 3600.52 | W34: =(T34-U34)/T34 | X34: =(T34-MIN(C34,H34,N34,T34,Z34))/MIN(C34,H34,N34,T34,Z34) | Y34: =(T34-C34)/C34 | Z34: 350 | AA34: 342 | AB34: 3600.79 | AC34: =(Z34-AA34)/Z34 | AD34: =(Z34-MIN(C34,H34,N34,T34,Z34))/MIN(C34,H34,N34,T34,Z34) | AE34: =(Z34-C34)/C34
B35: wfjsp_4_3 | C35: 360 | D35: 360 | E35: 376.5 | F35: =(C35-D35)/C35 | G35: =(C35-MIN(C35,H35,N35,T35,Z35))/MIN(C35,H35,N35,T35,Z35) | H35: 360 | I35: 350 | J35: 3601.11 | K35: =(H35-I35)/H35 | L35: =(H35-MIN(C35,H35,N35,T35,Z35))/MIN(C35,H35,N35,T35,Z35) | M35: =(H35-C35)/C35 | N35: 376 | O35: 350 | P35: 3600.04 | Q35: =(N35-O35)/N35 | R35: =(N35-MIN(C35,H35,N35,T35,Z35))/MIN(C35,H35,N35,T35,Z35) | S35: =(N35-C35)/C35 | T35: 360 | U35: 360 | V35: 388.593 | W35: =(T35-U35)/T35 | X35: =(T35-MIN(C35,H35,N35,T35,Z35))/MIN(C35,H35,N35,T35,Z35) | Y35: =(T35-C35)/C35 | Z35: 360 | AA35: 360 | AB35: 413.864 | AC35: =(Z35-AA35)/Z35 | AD35: =(Z35-MIN(C35,H35,N35,T35,Z35))/MIN(C35,H35,N35,T35,Z35) | AE35: =(Z35-C35)/C35
B36: wfjsp_4_4 | C36: 320 | D36: 227 | E36: 3600.03 | F36: =(C36-D36)/C36 | G36: =(C36-MIN(C36,H36,N36,T36,Z36))/MIN(C36,H36,N36,T36,Z36) | H36: 321 | I36: 313 | J36: 3600.3 | K36: =(H36-I36)/H36 | L36: =(H36-MIN(C36,H36,N36,T36,Z36))/MIN(C36,H36,N36,T36,Z36) | M36: =(H36-C36)/C36 | N36: 321 | O36: 313 | P36: 3600.54 | Q36: =(N36-O36)/N36 | R36: =(N36-MIN(C36,H36,N36,T36,Z36))/MIN(C36,H36,N36,T36,Z36) | S36: =(N36-C36)/C36 | T36: 320 | U36: 312 | V36: 3600.5 | W36: =(T36-U36)/T36 | X36: =(T36-MIN(C36,H36,N36,T36,Z36))/MIN(C36,H36,N36,T36,Z36) | Y36: =(T36-C36)/C36 | Z36: 320 | AA36: 312 | AB36: 3601.02 | AC36: =(Z36-AA36)/Z36 | AD36: =(Z36-MIN(C36,H36,N36,T36,Z36))/MIN(C36,H36,N36,T36,Z36) | AE36: =(Z36-C36)/C36
B37: wfjsp_4_5 | C37: 290 | D37: 290 | E37: 2.5 | F37: =(C37-D37)/C37 | G37: =(C37-MIN(C37,H37,N37,T37,Z37))/MIN(C37,H37,N37,T37,Z37) | H37: 290 | I37: 260 | J37: 3600 | K37: =(H37-I37)/H37 | L37: =(H37-MIN(C37,H37,N37,T37,Z37))/MIN(C37,H37,N37,T37,Z37) | M37: =(H37-C37)/C37 | N37: 290 | O37: 260 | P37: 3600.67 | Q37: =(N37-O37)/N37 | R37: =(N37-MIN(C37,H37,N37,T37,Z37))/MIN(C37,H37,N37,T37,Z37) | S37: =(N37-C37)/C37 | T37: 290 | U37: 290 | V37: 3.18454 | W37: =(T37-U37)/T37 | X37: =(T37-MIN(C37,H37,N37,T37,Z37))/MIN(C37,H37,N37,T37,Z37) | Y37: =(T37-C37)/C37 | Z37: 290 | AA37: 290 | AB37: 2.58886 | AC37: =(Z37-AA37)/Z37 | AD37: =(Z37-MIN(C37,H37,N37,T37,Z37))/MIN(C37,H37,N37,T37,Z37) | AE37: =(Z37-C37)/C37
B38: wfjsp_4_6 | C38: 355 | D38: 260 | E38: 3600.12 | F38: =(C38-D38)/C38 | G38: =(C38-MIN(C38,H38,N38,T38,Z38))/MIN(C38,H38,N38,T38,Z38) | H38: 355 | I38: 346 | J38: 3600.5 | K38: =(H38-I38)/H38 | L38: =(H38-MIN(C38,H38,N38,T38,Z38))/MIN(C38,H38,N38,T38,Z38) | M38: =(H38-C38)/C38 | N38: 371 | O38: 346 | P38: 3600.81 | Q38: =(N38-O38)/N38 | R38: =(N38-MIN(C38,H38,N38,T38,Z38))/MIN(C38,H38,N38,T38,Z38) | S38: =(N38-C38)/C38 | T38: 355 | U38: 346 | V38: 3600.73 | W38: =(T38-U38)/T38 | X38: =(T38-MIN(C38,H38,N38,T38,Z38))/MIN(C38,H38,N38,T38,Z38) | Y38: =(T38-C38)/C38 | Z38: 355 | AA38: 346 | AB38: 3600.49 | AC38: =(Z38-AA38)/Z38 | AD38: =(Z38-MIN(C38,H38,N38,T38,Z38))/MIN(C38,H38,N38,T38,Z38) | AE38: =(Z38-C38)/C38
B39: wfjsp_4_7 | C39: 288 | D39: 288 | E39: 442 | F39: =(C39-D39)/C39 | G39: =(C39-MIN(C39,H39,N39,T39,Z39))/MIN(C39,H39,N39,T39,Z39) | H39: 290 | I39: 286 | J39: 3600.22 | K39: =(H39-I39)/H39 | L39: =(H39-MIN(C39,H39,N39,T39,Z39))/MIN(C39,H39,N39,T39,Z39) | M39: =(H39-C39)/C39 | N39: 291 | O39: 286 | P39: 3600.34 | Q39: =(N39-O39)/N39 | R39: =(N39-MIN(C39,H39,N39,T39,Z39))/MIN(C39,H39,N39,T39,Z39) | S39: =(N39-C39)/C39 | T39: 288 | U39: 288 | V39: 440.422 | W39: =(T39-U39)/T39 | X39: =(T39-MIN(C39,H39,N39,T39,Z39))/MIN(C39,H39,N39,T39,Z39) | Y39: =(T39-C39)/C39 | Z39: 288 | AA39: 288 | AB39: 451.101 | AC39: =(Z39-AA39)/Z39 | AD39: =(Z39-MIN(C39,H39,N39,T39,Z39))/MIN(C39,H39,N39,T39,Z39) | AE39: =(Z39-C39)/C39
B40: wfjsp_4_8 | C40: 316 | D40: 213 | E40: 3600.02 | F40: =(C40-D40)/C40 | G40: =(C40-MIN(C40,H40,N40,T40,Z40))/MIN(C40,H40,N40,T40,Z40) | H40: 317 | I40: 307 | J40: 3600 | K40: =(H40-I40)/H40 | L40: =(H40-MIN(C40,H40,N40,T40,Z40))/MIN(C40,H40,N40,T40,Z40) | M40: =(H40-C40)/C40 | N40: 320 | O40: 307 | P40: 3600.02 | Q40: =(N40-O40)/N40 | R40: =(N40-MIN(C40,H40,N40,T40,Z40))/MIN(C40,H40,N40,T40,Z40) | S40: =(N40-C40)/C40 | T40: 316 | U40: 307 | V40: 3600.52 | W40: =(T40-U40)/T40 | X40: =(T40-MIN(C40,H40,N40,T40,Z40))/MIN(C40,H40,N40,T40,Z40) | Y40: =(T40-C40)/C40 | Z40: 316 | AA40: 307 | AB40: 3600 | AC40: =(Z40-AA40)/Z40 | AD40: =(Z40-MIN(C40,H40,N40,T40,Z40))/MIN(C40,H40,N40,T40,Z40) | AE40: =(Z40-C40)/C40
...

Sheet Exact Methods_lit
A1: Scale(Jobs,M,W) | B1: Instance | C1: CP (IBM CP optimizer, 1 h, HPC) | H1: LBBD_CP_TS | N1: LBBD_CP | T1: CP_LBBD_CP | Z1: CP_LBBD_CP_TS
C2: UB | D2: LB | E2: CPU Time | F2: Gap% | G2: RPD | H2: UB | I2: LB | J2: CPU Time | K2: Gap% | L2: RPD | M2: Q | N2: UB | O2: LB | P2: CPU Time | Q2: Gap% | R2: RPD | S2: Q | T2: UB | U2: LB | V2: CPU Time | W2: Gap% | X2: RPD | Y2: Q | Z2: UB | AA2: LB | AB2: CPU Time | AC2: Gap% | AD2: RPD | AE2: Q
A3: 10*6*4 | B3: Mk01 | C3: 70 | D3: 40 | E3: 3600 | F3: =(C3-D3)/C3 | G3: =(C3-MIN(C3,H3,N3,T3,Z3))/MIN(C3,H3,N3,T3,Z3) | H3: 71 | I3: 68 | J3: 3600 | K3: =(H3-I3)/H3 | L3: =(H3-MIN(C3,H3,N3,T3,Z3))/MIN(C3,H3,N3,T3,Z3) | M3: =(H3-C3)/C3 | N3: 71 | O3: 68 | P3: 3600.03 | Q3: =(N3-O3)/N3 | R3: =(N3-MIN(C3,H3,N3,T3,Z3))/MIN(C3,H3,N3,T3,Z3) | S3: =(N3-C3)/C3 | T3: 70 | U3: 68 | V3: 3600.03 | W3: =(T3-U3)/T3 | X3: =(T3-MIN(C3,H3,N3,T3,Z3))/MIN(C3,H3,N3,T3,Z3) | Y3: =(T3-C3)/C3 | Z3: 70 | AA3: 68 | AB3: 3601.06 | AC3: =(Z3-AA3)/Z3 | AD3: =(Z3-MIN(C3,H3,N3,T3,Z3))/MIN(C3,H3,N3,T3,Z3) | AE3: =(Z3-C3)/C3
B4: Mk02 | C4: 67 | D4: 36 | E4: 3600.62 | F4: =(C4-D4)/C4 | G4: =(C4-MIN(C4,H4,N4,T4,Z4))/MIN(C4,H4,N4,T4,Z4) | H4: 68 | I4: 66 | J4: 3601.04 | K4: =(H4-I4)/H4 | L4: =(H4-MIN(C4,H4,N4,T4,Z4))/MIN(C4,H4,N4,T4,Z4) | M4: =(H4-C4)/C4 | N4: 68 | O4: 66 | P4: 3600.05 | Q4: =(N4-O4)/N4 | R4: =(N4-MIN(C4,H4,N4,T4,Z4))/MIN(C4,H4,N4,T4,Z4) | S4: =(N4-C4)/C4 | T4: 67 | U4: 66 | V4: 3600.05 | W4: =(T4-U4)/T4 | X4: =(T4-MIN(C4,H4,N4,T4,Z4))/MIN(C4,H4,N4,T4,Z4) | Y4: =(T4-C4)/C4 | Z4: 67 | AA4: 66 | AB4: 3600 | AC4: =(Z4-AA4)/Z4 | AD4: =(Z4-MIN(C4,H4,N4,T4,Z4))/MIN(C4,H4,N4,T4,Z4) | AE4: =(Z4-C4)/C4
