Workbook

Sheet README
A1: Paired t-tests of Section 5
A3: Summary: one row per test (10 tests of Section 5.1 on the optimality gap and the RPD, 10 comparisons of Section 5.3 on the deviation from the CP solutions: the 8 columns of Table 4 and 2 comparisons quoted in the text only).
A4: S51_1 ... S51_10, T4_1 ... T4_10: one sheet per test. Columns C-E per instance, column Q the t-test step by step (n, mean, sd, standard error, t, df, p = T.DIST.2T(|t|, df), checked against T.TEST), the 95% CI, skewness and kurtosis, and, as values, the SciPy, permutation and bootstrap results.
A5: Data_Inst: one row per (method, instance) of the exact methods and the TS configurations (results/instances.csv). Data_FaF: one row per run of the filter-and-fan comparison (results/faf_runs.csv, seeds 1-5), plus the TS configurations (seed 1); the deviation is recomputed from the makespans, (Cmax / Cmax_CP - 1) x 100, so that equal makespans are exact ties. Every number on the test sheets except the 'value' rows is a formula on them.
A7: Method
A8: Two-sided paired-samples t-test over all 262 instances, H0: the mean difference over the instances is 0. Instances with a difference of 0 are kept. For methods run with five seeds, the seeds are averaged per instance first; when a method with five seeds is compared with a method run with seed 1 only, seed 1 of both is used.

Sheet Summary
A1: sheet | B1: method A | C1: method B | D1: measure | E1: n | F1: better / equal / worse | G1: mean diff A-B (pp) | H1: 95% CI (t) | I1: t | J1: p t-test (Excel) | K1: p t-test (SciPy) | L1: p permutation | M1: reported in the paper
A2: S51_1 | B2: LBBD_CP_TS | C2: LBBD_CP | D2: gap | E2: ='S51_1'!Q3 | F2: ='S51_1'!Q14 | G2: ='S51_1'!Q5 | H2: =TEXT('S51_1'!Q12,"0.000")&" to "&TEXT('S51_1'!Q13,"0.000") | I2: ='S51_1'!Q8 | J2: ='S51_1'!Q10 | K2: ='S51_1'!Q17 | L2: ='S51_1'!Q18 | M2: Section 5.1
A3: S51_2 | B3: LBBD_CP_TS | C3: LBBD_CP | D3: RPD | E3: ='S51_2'!Q3 | F3: ='S51_2'!Q14 | G3: ='S51_2'!Q5 | H3: =TEXT('S51_2'!Q12,"0.000")&" to "&TEXT('S51_2'!Q13,"0.000") | I3: ='S51_2'!Q8 | J3: ='S51_2'!Q10 | K3: ='S51_2'!Q17 | L3: ='S51_2'!Q18
A4: S51_3 | B4: CP_LBBD_CP_TS | C4: CP_LBBD_CP | D4: gap | E4: ='S51_3'!Q3 | F4: ='S51_3'!Q14 | G4: ='S51_3'!Q5 | H4: =TEXT('S51_3'!Q12,"0.000")&" to "&TEXT('S51_3'!Q13,"0.000") | I4: ='S51_3'!Q8 | J4: ='S51_3'!Q10 | K4: ='S51_3'!Q17 | L4: ='S51_3'!Q18 | M4: Section 5.1
A5: S51_4 | B5: CP_LBBD_CP_TS | C5: CP_LBBD_CP | D5: RPD | E5: ='S51_4'!Q3 | F5: ='S51_4'!Q14 | G5: ='S51_4'!Q5 | H5: =TEXT('S51_4'!Q12,"0.000")&" to "&TEXT('S51_4'!Q13,"0.000") | I5: ='S51_4'!Q8 | J5: ='S51_4'!Q10 | K5: ='S51_4'!Q17 | L5: ='S51_4'!Q18
A6: S51_5 | B6: CP_LBBD_CP_TS | C6: LBBD_CP_TS | D6: gap | E6: ='S51_5'!Q3 | F6: ='S51_5'!Q14 | G6: ='S51_5'!Q5 | H6: =TEXT('S51_5'!Q12,"0.000")&" to "&TEXT('S51_5'!Q13,"0.000") | I6: ='S51_5'!Q8 | J6: ='S51_5'!Q10 | K6: ='S51_5'!Q17 | L6: ='S51_5'!Q18 | M6: Section 5.1
A7: S51_6 | B7: CP_LBBD_CP_TS | C7: LBBD_CP_TS | D7: RPD | E7: ='S51_6'!Q3 | F7: ='S51_6'!Q14 | G7: ='S51_6'!Q5 | H7: =TEXT('S51_6'!Q12,"0.000")&" to "&TEXT('S51_6'!Q13,"0.000") | I7: ='S51_6'!Q8 | J7: ='S51_6'!Q10 | K7: ='S51_6'!Q17 | L7: ='S51_6'!Q18
A8: S51_7 | B8: LBBD_CP_TS | C8: CP | D8: gap | E8: ='S51_7'!Q3 | F8: ='S51_7'!Q14 | G8: ='S51_7'!Q5 | H8: =TEXT('S51_7'!Q12,"0.000")&" to "&TEXT('S51_7'!Q13,"0.000") | I8: ='S51_7'!Q8 | J8: ='S51_7'!Q10 | K8: ='S51_7'!Q17 | L8: ='S51_7'!Q18
A9: S51_8 | B9: LBBD_CP_TS | C9: CP | D9: RPD | E9: ='S51_8'!Q3 | F9: ='S51_8'!Q14 | G9: ='S51_8'!Q5 | H9: =TEXT('S51_8'!Q12,"0.000")&" to "&TEXT('S51_8'!Q13,"0.000") | I9: ='S51_8'!Q8 | J9: ='S51_8'!Q10 | K9: ='S51_8'!Q17 | L9: ='S51_8'!Q18
A10: S51_9 | B10: CP_LBBD_CP_TS | C10: CP | D10: gap | E10: ='S51_9'!Q3 | F10: ='S51_9'!Q14 | G10: ='S51_9'!Q5 | H10: =TEXT('S51_9'!Q12,"0.000")&" to "&TEXT('S51_9'!Q13,"0.000") | I10: ='S51_9'!Q8 | J10: ='S51_9'!Q10 | K10: ='S51_9'!Q17 | L10: ='S51_9'!Q18 | M10: Section 5.1
A11: S51_10 | B11: CP_LBBD_CP_TS | C11: CP | D11: RPD | E11: ='S51_10'!Q3 | F11: ='S51_10'!Q14 | G11: ='S51_10'!Q5 | H11: =TEXT('S51_10'!Q12,"0.000")&" to "&TEXT('S51_10'!Q13,"0.000") | I11: ='S51_10'!Q8 | J11: ='S51_10'!Q10 | K11: ='S51_10'!Q17 | L11: ='S51_10'!Q18
A12: T4_1 | B12: TS@FaF | C12: FaF | D12: dev. from CP | E12: ='T4_1'!Q3 | F12: ='T4_1'!Q14 | G12: ='T4_1'!Q5 | H12: =TEXT('T4_1'!Q12,"0.000")&" to "&TEXT('T4_1'!Q13,"0.000") | I12: ='T4_1'!Q8 | J12: ='T4_1'!Q10 | K12: ='T4_1'!Q17 | L12: ='T4_1'!Q18 | M12: Table 4 + Section 5.3
A13: T4_2 | B13: TS@FaFM | C13: FaFM | D13: dev. from CP | E13: ='T4_2'!Q3 | F13: ='T4_2'!Q14 | G13: ='T4_2'!Q5 | H13: =TEXT('T4_2'!Q12,"0.000")&" to "&TEXT('T4_2'!Q13,"0.000") | I13: ='T4_2'!Q8 | J13: ='T4_2'!Q10 | K13: ='T4_2'!Q17 | L13: ='T4_2'!Q18 | M13: Table 4 + Section 5.3
A14: T4_3 | B14: TS@FaFM | C14: TSN1@FaFM | D14: dev. from CP | E14: ='T4_3'!Q3 | F14: ='T4_3'!Q14 | G14: ='T4_3'!Q5 | H14: =TEXT('T4_3'!Q12,"0.000")&" to "&TEXT('T4_3'!Q13,"0.000") | I14: ='T4_3'!Q8 | J14: ='T4_3'!Q10 | K14: ='T4_3'!Q17 | L14: ='T4_3'!Q18 | M14: Table 4
A15: T4_4 | B15: TS_2000_5_5 | C15: TSN1_2000_5_5 | D15: dev. from CP | E15: ='T4_4'!Q3 | F15: ='T4_4'!Q14 | G15: ='T4_4'!Q5 | H15: =TEXT('T4_4'!Q12,"0.000")&" to "&TEXT('T4_4'!Q13,"0.000") | I15: ='T4_4'!Q8 | J15: ='T4_4'!Q10 | K15: ='T4_4'!Q17 | L15: ='T4_4'!Q18 | M15: Table 4
A16: T4_5 | B16: TS_10000_10_5 | C16: TSN1_10000_10_5 | D16: dev. from CP | E16: ='T4_5'!Q3 | F16: ='T4_5'!Q14 | G16: ='T4_5'!Q5 | H16: =TEXT('T4_5'!Q12,"0.000")&" to "&TEXT('T4_5'!Q13,"0.000") | I16: ='T4_5'!Q8 | J16: ='T4_5'!Q10 | K16: ='T4_5'!Q17 | L16: ='T4_5'!Q18 | M16: Table 4
A17: T4_6 | B17: FaFMJ | C17: FaFM | D17: dev. from CP | E17: ='T4_6'!Q3 | F17: ='T4_6'!Q14 | G17: ='T4_6'!Q5 | H17: =TEXT('T4_6'!Q12,"0.000")&" to "&TEXT('T4_6'!Q13,"0.000") | I17: ='T4_6'!Q8 | J17: ='T4_6'!Q10 | K17: ='T4_6'!Q17 | L17: ='T4_6'!Q18 | M17: Table 4
A18: T4_7 | B18: TS_5000_5_5 | C18: FaFMx2 | D18: dev. from CP | E18: ='T4_7'!Q3 | F18: ='T4_7'!Q14 | G18: ='T4_7'!Q5 | H18: =TEXT('T4_7'!Q12,"0.000")&" to "&TEXT('T4_7'!Q13,"0.000") | I18: ='T4_7'!Q8 | J18: ='T4_7'!Q10 | K18: ='T4_7'!Q17 | L18: ='T4_7'!Q18 | M18: Table 4 + Section 5.3
A19: T4_8 | B19: TS_25000_15_10 | C19: FaFMx3 | D19: dev. from CP | E19: ='T4_8'!Q3 | F19: ='T4_8'!Q14 | G19: ='T4_8'!Q5 | H19: =TEXT('T4_8'!Q12,"0.000")&" to "&TEXT('T4_8'!Q13,"0.000") | I19: ='T4_8'!Q8 | J19: ='T4_8'!Q10 | K19: ='T4_8'!Q17 | L19: ='T4_8'!Q18 | M19: Table 4 + Section 5.3
A20: T4_9 | B20: TS_10000_10_5 | C20: FaFMx2 | D20: dev. from CP | E20: ='T4_9'!Q3 | F20: ='T4_9'!Q14 | G20: ='T4_9'!Q5 | H20: =TEXT('T4_9'!Q12,"0.000")&" to "&TEXT('T4_9'!Q13,"0.000") | I20: ='T4_9'!Q8 | J20: ='T4_9'!Q10 | K20: ='T4_9'!Q17 | L20: ='T4_9'!Q18 | M20: Section 5.3 (text)
A21: T4_10 | B21: TS_50000_30_20 | C21: FaFMx3 | D21: dev. from CP | E21: ='T4_10'!Q3 | F21: ='T4_10'!Q14 | G21: ='T4_10'!Q5 | H21: =TEXT('T4_10'!Q12,"0.000")&" to "&TEXT('T4_10'!Q13,"0.000") | I21: ='T4_10'!Q8 | J21: ='T4_10'!Q10 | K21: ='T4_10'!Q17 | L21: ='T4_10'!Q18 | M21: Section 5.3 (text)
A23: How to read: p t-test (Excel) is computed with formulas on the test sheet; SciPy is the same test in Python (must match). p permutation is an exact, distribution-free test of the same null hypothesis (mean difference = 0): if it agrees with the t-test, the normal approximation behind the t-test is adequate for these data. The smallest permutation p that can be resolved is 1/200,001 = 5.0e-06; a value at that floor means 'smaller than that'.
A25: The paper reports p (t-test); p-values below 0.0001 are reported as p < 0.0001.

Sheet Data_Inst
A1: method | B1: instance | C1: set | D1: UB | E1: LB | F1: gap | G1: RPD | H1: dev_CP | I1: time
A2: CP | B2: wfjsp1_1 | C2: wfjsp1 | D2: 268 | E2: 268 | F2: 0 | G2: 0 | H2: 0 | I2: 1.375
A3: CP | B3: wfjsp1_2 | C3: wfjsp1 | D3: 287 | E3: 287 | F3: 0 | G3: 0 | H3: 0 | I3: 0.25
A4: CP | B4: wfjsp1_3 | C4: wfjsp1 | D4: 347 | E4: 347 | F4: 0 | G4: 0 | H4: 0 | I4: 0.875
A5: CP | B5: wfjsp1_4 | C5: wfjsp1 | D5: 315 | E5: 315 | F5: 0 | G5: 0 | H5: 0 | I5: 2.5625
A6: CP | B6: wfjsp1_5 | C6: wfjsp1 | D6: 265 | E6: 265 | F6: 0 | G6: 0 | H6: 0 | I6: 0.875
A7: CP | B7: wfjsp1_6 | C7: wfjsp1 | D7: 291 | E7: 291 | F7: 0 | G7: 0 | H7: 0 | I7: 2.625
A8: CP | B8: wfjsp1_7 | C8: wfjsp1 | D8: 265 | E8: 265 | F8: 0 | G8: 0 | H8: 0 | I8: 2.625
A9: CP | B9: wfjsp1_8 | C9: wfjsp1 | D9: 328 | E9: 328 | F9: 0 | G9: 0 | H9: 0 | I9: 2.0625
A10: CP | B10: wfjsp1_9 | C10: wfjsp1 | D10: 252 | E10: 252 | F10: 0 | G10: 0 | H10: 0 | I10: 1.375
A11: CP | B11: wfjsp1_10 | C11: wfjsp1 | D11: 316 | E11: 316 | F11: 0 | G11: 0 | H11: 0 | I11: 8.125
A12: CP | B12: wfjsp2_1 | C12: wfjsp2 | D12: 336 | E12: 336 | F12: 0 | G12: 0 | H12: 0 | I12: 32.2812
A13: CP | B13: wfjsp2_2 | C13: wfjsp2 | D13: 368 | E13: 368 | F13: 0 | G13: 0 | H13: 0 | I13: 29
... A1311: CP_LBBD_CP_TS | B1311: DP12 | C1311: DP | D1311: 2809 | E1311: 2724 | F1311: 0.030259879 | G1311: 0.0032142857 | H1311: -0.010915493 | I1311: 3601.19
A1312: TS_1000_2_5 | B1312: wfjsp1_1 | C1312: wfjsp1 | D1312: 268 | E1312: 0 | G1312: 0 | H1312: 0 | I1312: 0.276
A1313: TS_1000_2_5 | B1313: wfjsp1_2 | C1313: wfjsp1 | D1313: 287 | E1313: 0 | G1313: 0 | H1313: 0 | I1313: 0.186619
A1314: TS_1000_2_5 | B1314: wfjsp1_3 | C1314: wfjsp1 | D1314: 350 | E1314: 0 | G1314: 0.0086455331 | H1314: 0.0086455331 | I1314: 0.220271
A1315: TS_1000_2_5 | B1315: wfjsp1_4 | C1315: wfjsp1 | D1315: 315 | E1315: 0 | G1315: 0 | H1315: 0 | I1315: 0.308504
A1316: TS_1000_2_5 | B1316: wfjsp1_5 | C1316: wfjsp1 | D1316: 265 | E1316: 0 | G1316: 0 | H1316: 0 | I1316: 0.146208
A1317: TS_1000_2_5 | B1317: wfjsp1_6 | C1317: wfjsp1 | D1317: 291 | E1317: 0 | G1317: 0 | H1317: 0 | I1317: 0.208164
A1318: TS_1000_2_5 | B1318: wfjsp1_7 | C1318: wfjsp1 | D1318: 267 | E1318: 0 | G1318: 0.0075471698 | H1318: 0.0075471698 | I1318: 0.307378
A1319: TS_1000_2_5 | B1319: wfjsp1_8 | C1319: wfjsp1 | D1319: 328 | E1319: 0 | G1319: 0 | H1319: 0 | I1319: 0.199313
A1320: TS_1000_2_5 | B1320: wfjsp1_9 | C1320: wfjsp1 | D1320: 254 | E1320: 0 | G1320: 0.0079365079 | H1320: 0.0079365079 | I1320: 0.0888969
A1321: TS_1000_2_5 | B1321: wfjsp1_10 | C1321: wfjsp1 | D1321: 317 | E1321: 0 | G1321: 0.003164557 | H1321: 0.003164557 | I1321: 0.208628
A1322: TS_1000_2_5 | B1322: wfjsp2_1 | C1322: wfjsp2 | D1322: 338 | E1322: 0 | G1322: 0.005952381 | H1322: 0.005952381 | I1322: 0.511869
A1323: TS_1000_2_5 | B1323: wfjsp2_2 | C1323: wfjsp2 | D1323: 370 | E1323: 0 | G1323: 0.0054347826 | H1323: 0.0054347826 | I1323: 0.429817
... A2883: TS_50000_30_20 | B2883: DP12 | C2883: DP | D2883: 2824 | E2883: 0 | G2883: 0.0085714286 | H2883: -0.0056338028 | I2883: 1800.02

Sheet Data_FaF
A1: method | B1: inst | C1: seed | D1: cmax | E1: gap | F1: time | G1: grp
A2: FaF | B2: DP1 | C2: 1 | D2: 3141 | E2: 7.5316672 | F2: 8.66021 | G2: DP
A3: FaF | B3: DP1 | C3: 2 | D3: 3083 | E3: 5.5460459 | F3: 12.1641 | G3: DP
A4: FaF | B4: DP1 | C4: 3 | D4: 3064 | E4: 4.8955837 | F4: 9.90509 | G4: DP
A5: FaF | B5: DP1 | C5: 4 | D5: 3141 | E5: 7.5316672 | F5: 4.65325 | G5: DP
A6: FaF | B6: DP1 | C6: 5 | D6: 3088 | E6: 5.7172201 | F6: 14.3427 | G6: DP
A7: FaF | B7: DP2 | C7: 1 | D7: 2927 | E7: 0.44612217 | F7: 18.957 | G7: DP
A8: FaF | B8: DP2 | C8: 2 | D8: 2942 | E8: 0.96087852 | F8: 12.343 | G8: DP
A9: FaF | B9: DP2 | C9: 3 | D9: 2954 | E9: 1.3726836 | F9: 9.59733 | G9: DP
A10: FaF | B10: DP2 | C10: 4 | D10: 2932 | E10: 0.61770762 | F10: 13.9287 | G10: DP
A11: FaF | B11: DP2 | C11: 5 | D11: 2937 | E11: 0.78929307 | F11: 23.4426 | G11: DP
A12: FaF | B12: DP3 | C12: 1 | D12: 2988 | E12: 2.6804124 | F12: 18.818 | G12: DP
A13: FaF | B13: DP3 | C13: 2 | D13: 2962 | E13: 1.7869416 | F13: 17.5698 | G13: DP
... A12577: TS_5000_5_5 | B12577: DP12 | C12577: 1 | D12577: 2832 | E12577: -0.28169014 | F12577: 224.542 | G12577: DP

Sheet S51_1
A1: Section 5.1: LBBD_CP_TS vs LBBD_CP, gap in % (one run per instance)
A2: Method A | B2: LBBD_CP_TS | P2: Step | Q2: Value | R2: Meaning
A3: Method B | B3: LBBD_CP | P3: n (instances) | Q3: =COUNT($E$12:$E$273) | R3: all 262 instances; none is discarded, ties (difference 0) included
A4: Measure | B4: gap | P4: zero differences | Q4: =COUNTIF($E$12:$E$273,0) | R4: instances where A and B are equal (kept in the t-test)
A5: Seeds averaged (1..n) | B5: - | P5: mean difference A - B | Q5: =AVERAGE($E$12:$E$273) | R5: in percentage points; negative favors A
A6: Reported in | B6: Section 5.1 | P6: std. dev. of differences | Q6: =_xlfn.STDEV.S($E$12:$E$273)
P7: standard error | Q7: =Q6/SQRT(Q3) | R7: sd / sqrt(n)
P8: t | Q8: =Q5/Q7 | R8: mean / standard error
P9: df | Q9: =Q3-1
A10: Steps: C, D = result of A and B per instance (in %); E = difference A - B; column Q = paired t-test on all instances. Changing the yellow cells B2:B5 tests another pair. | P10: p (t-test, two-sided) | Q10: =_xlfn.T.DIST.2T(ABS(Q8),Q9) | R10: H0: mean difference = 0
A11: instance | B11: group | C11: A (%) | D11: B (%) | E11: diff A-B | P11: p check: T.TEST | Q11: =_xlfn.T.TEST($C$12:$C$273,$D$12:$D$273,2,1) | R11: Excel's built-in paired test, must equal Q10
A12: wfjsp1_1 | B12: WFJSP 1-8 | C12: =AVERAGEIFS(Data_Inst!$F$2:$F$2883,Data_Inst!$A$2:$A$2883,$B$2,Data_Inst!$B$2:$B$2883,$A12)*100 | D12: =AVERAGEIFS(Data_Inst!$F$2:$F$2883,Data_Inst!$A$2:$A$2883,$B$3,Data_Inst!$B$2:$B$2883,$A12)*100 | E12: =ROUND(C12-D12,9) | P12: 95% CI low | Q12: =Q5-_xlfn.T.INV.2T(0.05,Q9)*Q7
A13: wfjsp1_2 | B13: WFJSP 1-8 | C13: =AVERAGEIFS(Data_Inst!$F$2:$F$2883,Data_Inst!$A$2:$A$2883,$B$2,Data_Inst!$B$2:$B$2883,$A13)*100 | D13: =AVERAGEIFS(Data_Inst!$F$2:$F$2883,Data_Inst!$A$2:$A$2883,$B$3,Data_Inst!$B$2:$B$2883,$A13)*100 | E13: =ROUND(C13-D13,9) | P13: 95% CI high | Q13: =Q5+_xlfn.T.INV.2T(0.05,Q9)*Q7
A14: wfjsp1_3 | B14: WFJSP 1-8 | C14: =AVERAGEIFS(Data_Inst!$F$2:$F$2883,Data_Inst!$A$2:$A$2883,$B$2,Data_Inst!$B$2:$B$2883,$A14)*100 | D14: =AVERAGEIFS(Data_Inst!$F$2:$F$2883,Data_Inst!$A$2:$A$2883,$B$3,Data_Inst!$B$2:$B$2883,$A14)*100 | E14: =ROUND(C14-D14,9) | P14: better / equal / worse | Q14: =COUNTIF($E$12:$E$273,"<0")&" / "&COUNTIF($E$12:$E$273,0)&" / "&COUNTIF($E$12:$E$273,">0") | R14: A better (smaller), equal, worse than B
A15: wfjsp1_4 | B15: WFJSP 1-8 | C15: =AVERAGEIFS(Data_Inst!$F$2:$F$2883,Data_Inst!$A$2:$A$2883,$B$2,Data_Inst!$B$2:$B$2883,$A15)*100 | D15: =AVERAGEIFS(Data_Inst!$F$2:$F$2883,Data_Inst!$A$2:$A$2883,$B$3,Data_Inst!$B$2:$B$2883,$A15)*100 | E15: =ROUND(C15-D15,9) | P15: skewness | Q15: =SKEW($E$12:$E$273) | R15: normality is not needed for n = 262 (central limit theorem), see the permutation check
A16: wfjsp1_5 | B16: WFJSP 1-8 | C16: =AVERAGEIFS(Data_Inst!$F$2:$F$2883,Data_Inst!$A$2:$A$2883,$B$2,Data_Inst!$B$2:$B$2883,$A16)*100 | D16: =AVERAGEIFS(Data_Inst!$F$2:$F$2883,Data_Inst!$A$2:$A$2883,$B$3,Data_Inst!$B$2:$B$2883,$A16)*100 | E16: =ROUND(C16-D16,9) | P16: excess kurtosis | Q16: =KURT($E$12:$E$273)
A17: wfjsp1_6 | B17: WFJSP 1-8 | C17: =AVERAGEIFS(Data_Inst!$F$2:$F$2883,Data_Inst!$A$2:$A$2883,$B$2,Data_Inst!$B$2:$B$2883,$A17)*100 | D17: =AVERAGEIFS(Data_Inst!$F$2:$F$2883,Data_Inst!$A$2:$A$2883,$B$3,Data_Inst!$B$2:$B$2883,$A17)*100 | E17: =ROUND(C17-D17,9) | P17: p (t-test, SciPy, value) | Q17: 1.6407644e-54 | R17: scipy.stats.ttest_1samp on the differences
A18: wfjsp1_7 | B18: WFJSP 1-8 | C18: =AVERAGEIFS(Data_Inst!$F$2:$F$2883,Data_Inst!$A$2:$A$2883,$B$2,Data_Inst!$B$2:$B$2883,$A18)*100 | D18: =AVERAGEIFS(Data_Inst!$F$2:$F$2883,Data_Inst!$A$2:$A$2883,$B$3,Data_Inst!$B$2:$B$2883,$A18)*100 | E18: =ROUND(C18-D18,9) | P18: p (permutation, value) | Q18: 4.999975e-06 | R18: exact test of the mean: random sign flips of the differences, 200,000 draws (smallest possible p = 1/200,001)
A19: wfjsp1_8 | B19: WFJSP 1-8 | C19: =AVERAGEIFS(Data_Inst!$F$2:$F$2883,Data_Inst!$A$2:$A$2883,$B$2,Data_Inst!$B$2:$B$2883,$A19)*100 | D19: =AVERAGEIFS(Data_Inst!$F$2:$F$2883,Data_Inst!$A$2:$A$2883,$B$3,Data_Inst!$B$2:$B$2883,$A19)*100 | E19: =ROUND(C19-D19,9) | P19: bootstrap 95% CI low (value) | Q19: -5.7750203 | R19: 20,000 bootstrap resamples of the instances
A20: wfjsp1_9 | B20: WFJSP 1-8 | C20: =AVERAGEIFS(Data_Inst!$F$2:$F$2883,Data_Inst!$A$2:$A$2883,$B$2,Data_Inst!$B$2:$B$2883,$A20)*100 | D20: =AVERAGEIFS(Data_Inst!$F$2:$F$2883,Data_Inst!$A$2:$A$2883,$B$3,Data_Inst!$B$2:$B$2883,$A20)*100 | E20: =ROUND(C20-D20,9) | P20: bootstrap 95% CI high (value) | Q20: -4.7392737
A21: wfjsp1_10 | B21: WFJSP 1-8 | C21: =AVERAGEIFS(Data_Inst!$F$2:$F$2883,Data_Inst!$A$2:$A$2883,$B$2,Data_Inst!$B$2:$B$2883,$A21)*100 | D21: =AVERAGEIFS(Data_Inst!$F$2:$F$2883,Data_Inst!$A$2:$A$2883,$B$3,Data_Inst!$B$2:$B$2883,$A21)*100 | E21: =ROUND(C21-D21,9)
A22: wfjsp2_1 | B22: WFJSP 1-8 | C22: =AVERAGEIFS(Data_Inst!$F$2:$F$2883,Data_Inst!$A$2:$A$2883,$B$2,Data_Inst!$B$2:$B$2883,$A22)*100 | D22: =AVERAGEIFS(Data_Inst!$F$2:$F$2883,Data_Inst!$A$2:$A$2883,$B$3,Data_Inst!$B$2:$B$2883,$A22)*100 | E22: =ROUND(C22-D22,9) | P22: Mean difference per group
A23: wfjsp2_2 | B23: WFJSP 1-8 | C23: =AVERAGEIFS(Data_Inst!$F$2:$F$2883,Data_Inst!$A$2:$A$2883,$B$2,Data_Inst!$B$2:$B$2883,$A23)*100 | D23: =AVERAGEIFS(Data_Inst!$F$2:$F$2883,Data_Inst!$A$2:$A$2883,$B$3,Data_Inst!$B$2:$B$2883,$A23)*100 | E23: =ROUND(C23-D23,9) | P23: WFJSP 1-8 | Q23: =AVERAGEIFS($E$12:$E$273,$B$12:$B$273,P23)
A24: wfjsp2_3 | B24: WFJSP 1-8 | C24: =AVERAGEIFS(Data_Inst!$F$2:$F$2883,Data_Inst!$A$2:$A$2883,$B$2,Data_Inst!$B$2:$B$2883,$A24)*100 | D24: =AVERAGEIFS(Data_Inst!$F$2:$F$2883,Data_Inst!$A$2:$A$2883,$B$3,Data_Inst!$B$2:$B$2883,$A24)*100 | E24: =ROUND(C24-D24,9) | P24: WFJSP 9-16 | Q24: =AVERAGEIFS($E$12:$E$273,$B$12:$B$273,P24)
A25: wfjsp2_4 | B25: WFJSP 1-8 | C25: =AVERAGEIFS(Data_Inst!$F$2:$F$2883,Data_Inst!$A$2:$A$2883,$B$2,Data_Inst!$B$2:$B$2883,$A25)*100 | D25: =AVERAGEIFS(Data_Inst!$F$2:$F$2883,Data_Inst!$A$2:$A$2883,$B$3,Data_Inst!$B$2:$B$2883,$A25)*100 | E25: =ROUND(C25-D25,9) | P25: WFJSP 17-24 | Q25: =AVERAGEIFS($E$12:$E$273,$B$12:$B$273,P25)
A26: wfjsp2_5 | B26: WFJSP 1-8 | C26: =AVERAGEIFS(Data_Inst!$F$2:$F$2883,Data_Inst!$A$2:$A$2883,$B$2,Data_Inst!$B$2:$B$2883,$A26)*100 | D26: =AVERAGEIFS(Data_Inst!$F$2:$F$2883,Data_Inst!$A$2:$A$2883,$B$3,Data_Inst!$B$2:$B$2883,$A26)*100 | E26: =ROUND(C26-D26,9) | P26: MK | Q26: =AVERAGEIFS($E$12:$E$273,$B$12:$B$273,P26)
A27: wfjsp2_6 | B27: WFJSP 1-8 | C27: =AVERAGEIFS(Data_Inst!$F$2:$F$2883,Data_Inst!$A$2:$A$2883,$B$2,Data_Inst!$B$2:$B$2883,$A27)*100 | D27: =AVERAGEIFS(Data_Inst!$F$2:$F$2883,Data_Inst!$A$2:$A$2883,$B$3,Data_Inst!$B$2:$B$2883,$A27)*100 | E27: =ROUND(C27-D27,9) | P27: DP | Q27: =AVERAGEIFS($E$12:$E$273,$B$12:$B$273,P27)
A28: wfjsp2_7 | B28: WFJSP 1-8 | C28: =AVERAGEIFS(Data_Inst!$F$2:$F$2883,Data_Inst!$A$2:$A$2883,$B$2,Data_Inst!$B$2:$B$2883,$A28)*100 | D28: =AVERAGEIFS(Data_Inst!$F$2:$F$2883,Data_Inst!$A$2:$A$2883,$B$3,Data_Inst!$B$2:$B$2883,$A28)*100 | E28: =ROUND(C28-D28,9)
A29: wfjsp2_8 | B29: WFJSP 1-8 | C29: =AVERAGEIFS(Data_Inst!$F$2:$F$2883,Data_Inst!$A$2:$A$2883,$B$2,Data_Inst!$B$2:$B$2883,$A29)*100 | D29: =AVERAGEIFS(Data_Inst!$F$2:$F$2883,Data_Inst!$A$2:$A$2883,$B$3,Data_Inst!$B$2:$B$2883,$A29)*100 | E29: =ROUND(C29-D29,9)
A30: wfjsp2_9 | B30: WFJSP 1-8 | C30: =AVERAGEIFS(Data_Inst!$F$2:$F$2883,Data_Inst!$A$2:$A$2883,$B$2,Data_Inst!$B$2:$B$2883,$A30)*100 | D30: =AVERAGEIFS(Data_Inst!$F$2:$F$2883,Data_Inst!$A$2:$A$2883,$B$3,Data_Inst!$B$2:$B$2883,$A30)*100 | E30: =ROUND(C30-D30,9)
A31: wfjsp2_10 | B31: WFJSP 1-8 | C31: =AVERAGEIFS(Data_Inst!$F$2:$F$2883,Data_Inst!$A$2:$A$2883,$B$2,Data_Inst!$B$2:$B$2883,$A31)*100 | D31: =AVERAGEIFS(Data_Inst!$F$2:$F$2883,Data_Inst!$A$2:$A$2883,$B$3,Data_Inst!$B$2:$B$2883,$A31)*100 | E31: =ROUND(C31-D31,9)
A32: wfjsp3_1 | B32: WFJSP 1-8 | C32: =AVERAGEIFS(Data_Inst!$F$2:$F$2883,Data_Inst!$A$2:$A$2883,$B$2,Data_Inst!$B$2:$B$2883,$A32)*100 | D32: =AVERAGEIFS(Data_Inst!$F$2:$F$2883,Data_Inst!$A$2:$A$2883,$B$3,Data_Inst!$B$2:$B$2883,$A32)*100 | E32: =ROUND(C32-D32,9)
A33: wfjsp3_2 | B33: WFJSP 1-8 | C33: =AVERAGEIFS(Data_Inst!$F$2:$F$2883,Data_Inst!$A$2:$A$2883,$B$2,Data_Inst!$B$2:$B$2883,$A33)*100 | D33: =AVERAGEIFS(Data_Inst!$F$2:$F$2883,Data_Inst!$A$2:$A$2883,$B$3,Data_Inst!$B$2:$B$2883,$A33)*100 | E33: =ROUND(C33-D33,9)
A34: wfjsp3_3 | B34: WFJSP 1-8 | C34: =AVERAGEIFS(Data_Inst!$F$2:$F$2883,Data_Inst!$A$2:$A$2883,$B$2,Data_Inst!$B$2:$B$2883,$A34)*100 | D34: =AVERAGEIFS(Data_Inst!$F$2:$F$2883,Data_Inst!$A$2:$A$2883,$B$3,Data_Inst!$B$2:$B$2883,$A34)*100 | E34: =ROUND(C34-D34,9)
A35: wfjsp3_4 | B35: WFJSP 1-8 | C35: =AVERAGEIFS(Data_Inst!$F$2:$F$2883,Data_Inst!$A$2:$A$2883,$B$2,Data_Inst!$B$2:$B$2883,$A35)*100 | D35: =AVERAGEIFS(Data_Inst!$F$2:$F$2883,Data_Inst!$A$2:$A$2883,$B$3,Data_Inst!$B$2:$B$2883,$A35)*100 | E35: =ROUND(C35-D35,9)
A36: wfjsp3_5 | B36: WFJSP 1-8 | C36: =AVERAGEIFS(Data_Inst!$F$2:$F$2883,Data_Inst!$A$2:$A$2883,$B$2,Data_Inst!$B$2:$B$2883,$A36)*100 | D36: =AVERAGEIFS(Data_Inst!$F$2:$F$2883,Data_Inst!$A$2:$A$2883,$B$3,Data_Inst!$B$2:$B$2883,$A36)*100 | E36: =ROUND(C36-D36,9)
A37: wfjsp3_6 | B37: WFJSP 1-8 | C37: =AVERAGEIFS(Data_Inst!$F$2:$F$2883,Data_Inst!$A$2:$A$2883,$B$2,Data_Inst!$B$2:$B$2883,$A37)*100 | D37: =AVERAGEIFS(Data_Inst!$F$2:$F$2883,Data_Inst!$A$2:$A$2883,$B$3,Data_Inst!$B$2:$B$2883,$A37)*100 | E37: =ROUND(C37-D37,9)
A38: wfjsp3_7 | B38: WFJSP 1-8 | C38: =AVERAGEIFS(Data_Inst!$F$2:$F$2883,Data_Inst!$A$2:$A$2883,$B$2,Data_Inst!$B$2:$B$2883,$A38)*100 | D38: =AVERAGEIFS(Data_Inst!$F$2:$F$2883,Data_Inst!$A$2:$A$2883,$B$3,Data_Inst!$B$2:$B$2883,$A38)*100 | E38: =ROUND(C38-D38,9)
A39: wfjsp3_8 | B39: WFJSP 1-8 | C39: =AVERAGEIFS(Data_Inst!$F$2:$F$2883,Data_Inst!$A$2:$A$2883,$B$2,Data_Inst!$B$2:$B$2883,$A39)*100 | D39: =AVERAGEIFS(Data_Inst!$F$2:$F$2883,Data_Inst!$A$2:$A$2883,$B$3,Data_Inst!$B$2:$B$2883,$A39)*100 | E39: =ROUND(C39-D39,9)
... A273: DP12 | B273: DP | C273: =AVERAGEIFS(Data_Inst!$F$2:$F$2883,Data_Inst!$A$2:$A$2883,$B$2,Data_Inst!$B$2:$B$2883,$A273)*100 | D273: =AVERAGEIFS(Data_Inst!$F$2:$F$2883,Data_Inst!$A$2:$A$2883,$B$3,Data_Inst!$B$2:$B$2883,$A273)*100 | E273: =ROUND(C273-D273,9)

Sheet S51_2
A1: Section 5.1: LBBD_CP_TS vs LBBD_CP, RPD in % (one run per instance)
A2: Method A | B2: LBBD_CP_TS | P2: Step | Q2: Value | R2: Meaning
A3: Method B | B3: LBBD_CP | P3: n (instances) | Q3: =COUNT($E$12:$E$273) | R3: all 262 instances; none is discarded, ties (difference 0) included
A4: Measure | B4: RPD | P4: zero differences | Q4: =COUNTIF($E$12:$E$273,0) | R4: instances where A and B are equal (kept in the t-test)
A5: Seeds averaged (1..n) | B5: - | P5: mean difference A - B | Q5: =AVERAGE($E$12:$E$273) | R5: in percentage points; negative favors A
A6: Reported in | B6: (not quoted in the text) | P6: std. dev. of differences | Q6: =_xlfn.STDEV.S($E$12:$E$273)
P7: standard error | Q7: =Q6/SQRT(Q3) | R7: sd / sqrt(n)
P8: t | Q8: =Q5/Q7 | R8: mean / standard error
P9: df | Q9: =Q3-1
A10: Steps: C, D = result of A and B per instance (in %); E = difference A - B; column Q = paired t-test on all instances. Changing the yellow cells B2:B5 tests another pair. | P10: p (t-test, two-sided) | Q10: =_xlfn.T.DIST.2T(ABS(Q8),Q9) | R10: H0: mean difference = 0
A11: instance | B11: group | C11: A (%) | D11: B (%) | E11: diff A-B | P11: p check: T.TEST | Q11: =_xlfn.T.TEST($C$12:$C$273,$D$12:$D$273,2,1) | R11: Excel's built-in paired test, must equal Q10
A12: wfjsp1_1 | B12: WFJSP 1-8 | C12: =AVERAGEIFS(Data_Inst!$G$2:$G$2883,Data_Inst!$A$2:$A$2883,$B$2,Data_Inst!$B$2:$B$2883,$A12)*100 | D12: =AVERAGEIFS(Data_Inst!$G$2:$G$2883,Data_Inst!$A$2:$A$2883,$B$3,Data_Inst!$B$2:$B$2883,$A12)*100 | E12: =ROUND(C12-D12,9) | P12: 95% CI low | Q12: =Q5-_xlfn.T.INV.2T(0.05,Q9)*Q7
A13: wfjsp1_2 | B13: WFJSP 1-8 | C13: =AVERAGEIFS(Data_Inst!$G$2:$G$2883,Data_Inst!$A$2:$A$2883,$B$2,Data_Inst!$B$2:$B$2883,$A13)*100 | D13: =AVERAGEIFS(Data_Inst!$G$2:$G$2883,Data_Inst!$A$2:$A$2883,$B$3,Data_Inst!$B$2:$B$2883,$A13)*100 | E13: =ROUND(C13-D13,9) | P13: 95% CI high | Q13: =Q5+_xlfn.T.INV.2T(0.05,Q9)*Q7
A14: wfjsp1_3 | B14: WFJSP 1-8 | C14: =AVERAGEIFS(Data_Inst!$G$2:$G$2883,Data_Inst!$A$2:$A$2883,$B$2,Data_Inst!$B$2:$B$2883,$A14)*100 | D14: =AVERAGEIFS(Data_Inst!$G$2:$G$2883,Data_Inst!$A$2:$A$2883,$B$3,Data_Inst!$B$2:$B$2883,$A14)*100 | E14: =ROUND(C14-D14,9) | P14: better / equal / worse | Q14: =COUNTIF($E$12:$E$273,"<0")&" / "&COUNTIF($E$12:$E$273,0)&" / "&COUNTIF($E$12:$E$273,">0") | R14: A better (smaller), equal, worse than B
A15: wfjsp1_4 | B15: WFJSP 1-8 | C15: =AVERAGEIFS(Data_Inst!$G$2:$G$2883,Data_Inst!$A$2:$A$2883,$B$2,Data_Inst!$B$2:$B$2883,$A15)*100 | D15: =AVERAGEIFS(Data_Inst!$G$2:$G$2883,Data_Inst!$A$2:$A$2883,$B$3,Data_Inst!$B$2:$B$2883,$A15)*100 | E15: =ROUND(C15-D15,9) | P15: skewness | Q15: =SKEW($E$12:$E$273) | R15: normality is not needed for n = 262 (central limit theorem), see the permutation check
A16: wfjsp1_5 | B16: WFJSP 1-8 | C16: =AVERAGEIFS(Data_Inst!$G$2:$G$2883,Data_Inst!$A$2:$A$2883,$B$2,Data_Inst!$B$2:$B$2883,$A16)*100 | D16: =AVERAGEIFS(Data_Inst!$G$2:$G$2883,Data_Inst!$A$2:$A$2883,$B$3,Data_Inst!$B$2:$B$2883,$A16)*100 | E16: =ROUND(C16-D16,9) | P16: excess kurtosis | Q16: =KURT($E$12:$E$273)
A17: wfjsp1_6 | B17: WFJSP 1-8 | C17: =AVERAGEIFS(Data_Inst!$G$2:$G$2883,Data_Inst!$A$2:$A$2883,$B$2,Data_Inst!$B$2:$B$2883,$A17)*100 | D17: =AVERAGEIFS(Data_Inst!$G$2:$G$2883,Data_Inst!$A$2:$A$2883,$B$3,Data_Inst!$B$2:$B$2883,$A17)*100 | E17: =ROUND(C17-D17,9) | P17: p (t-test, SciPy, value) | Q17: 6.8443603e-49 | R17: scipy.stats.ttest_1samp on the differences
A18: wfjsp1_7 | B18: WFJSP 1-8 | C18: =AVERAGEIFS(Data_Inst!$G$2:$G$2883,Data_Inst!$A$2:$A$2883,$B$2,Data_Inst!$B$2:$B$2883,$A18)*100 | D18: =AVERAGEIFS(Data_Inst!$G$2:$G$2883,Data_Inst!$A$2:$A$2883,$B$3,Data_Inst!$B$2:$B$2883,$A18)*100 | E18: =ROUND(C18-D18,9) | P18: p (permutation, value) | Q18: 4.999975e-06 | R18: exact test of the mean: random sign flips of the differences, 200,000 draws (smallest possible p = 1/200,001)
A19: wfjsp1_8 | B19: WFJSP 1-8 | C19: =AVERAGEIFS(Data_Inst!$G$2:$G$2883,Data_Inst!$A$2:$A$2883,$B$2,Data_Inst!$B$2:$B$2883,$A19)*100 | D19: =AVERAGEIFS(Data_Inst!$G$2:$G$2883,Data_Inst!$A$2:$A$2883,$B$3,Data_Inst!$B$2:$B$2883,$A19)*100 | E19: =ROUND(C19-D19,9) | P19: bootstrap 95% CI low (value) | Q19: -7.1533278 | R19: 20,000 bootstrap resamples of the instances
A20: wfjsp1_9 | B20: WFJSP 1-8 | C20: =AVERAGEIFS(Data_Inst!$G$2:$G$2883,Data_Inst!$A$2:$A$2883,$B$2,Data_Inst!$B$2:$B$2883,$A20)*100 | D20: =AVERAGEIFS(Data_Inst!$G$2:$G$2883,Data_Inst!$A$2:$A$2883,$B$3,Data_Inst!$B$2:$B$2883,$A20)*100 | E20: =ROUND(C20-D20,9) | P20: bootstrap 95% CI high (value) | Q20: -5.779709
A21: wfjsp1_10 | B21: WFJSP 1-8 | C21: =AVERAGEIFS(Data_Inst!$G$2:$G$2883,Data_Inst!$A$2:$A$2883,$B$2,Data_Inst!$B$2:$B$2883,$A21)*100 | D21: =AVERAGEIFS(Data_Inst!$G$2:$G$2883,Data_Inst!$A$2:$A$2883,$B$3,Data_Inst!$B$2:$B$2883,$A21)*100 | E21: =ROUND(C21-D21,9)
A22: wfjsp2_1 | B22: WFJSP 1-8 | C22: =AVERAGEIFS(Data_Inst!$G$2:$G$2883,Data_Inst!$A$2:$A$2883,$B$2,Data_Inst!$B$2:$B$2883,$A22)*100 | D22: =AVERAGEIFS(Data_Inst!$G$2:$G$2883,Data_Inst!$A$2:$A$2883,$B$3,Data_Inst!$B$2:$B$2883,$A22)*100 | E22: =ROUND(C22-D22,9) | P22: Mean difference per group
A23: wfjsp2_2 | B23: WFJSP 1-8 | C23: =AVERAGEIFS(Data_Inst!$G$2:$G$2883,Data_Inst!$A$2:$A$2883,$B$2,Data_Inst!$B$2:$B$2883,$A23)*100 | D23: =AVERAGEIFS(Data_Inst!$G$2:$G$2883,Data_Inst!$A$2:$A$2883,$B$3,Data_Inst!$B$2:$B$2883,$A23)*100 | E23: =ROUND(C23-D23,9) | P23: WFJSP 1-8 | Q23: =AVERAGEIFS($E$12:$E$273,$B$12:$B$273,P23)
A24: wfjsp2_3 | B24: WFJSP 1-8 | C24: =AVERAGEIFS(Data_Inst!$G$2:$G$2883,Data_Inst!$A$2:$A$2883,$B$2,Data_Inst!$B$2:$B$2883,$A24)*100 | D24: =AVERAGEIFS(Data_Inst!$G$2:$G$2883,Data_Inst!$A$2:$A$2883,$B$3,Data_Inst!$B$2:$B$2883,$A24)*100 | E24: =ROUND(C24-D24,9) | P24: WFJSP 9-16 | Q24: =AVERAGEIFS($E$12:$E$273,$B$12:$B$273,P24)
A25: wfjsp2_4 | B25: WFJSP 1-8 | C25: =AVERAGEIFS(Data_Inst!$G$2:$G$2883,Data_Inst!$A$2:$A$2883,$B$2,Data_Inst!$B$2:$B$2883,$A25)*100 | D25: =AVERAGEIFS(Data_Inst!$G$2:$G$2883,Data_Inst!$A$2:$A$2883,$B$3,Data_Inst!$B$2:$B$2883,$A25)*100 | E25: =ROUND(C25-D25,9) | P25: WFJSP 17-24 | Q25: =AVERAGEIFS($E$12:$E$273,$B$12:$B$273,P25)
A26: wfjsp2_5 | B26: WFJSP 1-8 | C26: =AVERAGEIFS(Data_Inst!$G$2:$G$2883,Data_Inst!$A$2:$A$2883,$B$2,Data_Inst!$B$2:$B$2883,$A26)*100 | D26: =AVERAGEIFS(Data_Inst!$G$2:$G$2883,Data_Inst!$A$2:$A$2883,$B$3,Data_Inst!$B$2:$B$2883,$A26)*100 | E26: =ROUND(C26-D26,9) | P26: MK | Q26: =AVERAGEIFS($E$12:$E$273,$B$12:$B$273,P26)
A27: wfjsp2_6 | B27: WFJSP 1-8 | C27: =AVERAGEIFS(Data_Inst!$G$2:$G$2883,Data_Inst!$A$2:$A$2883,$B$2,Data_Inst!$B$2:$B$2883,$A27)*100 | D27: =AVERAGEIFS(Data_Inst!$G$2:$G$2883,Data_Inst!$A$2:$A$2883,$B$3,Data_Inst!$B$2:$B$2883,$A27)*100 | E27: =ROUND(C27-D27,9) | P27: DP | Q27: =AVERAGEIFS($E$12:$E$273,$B$12:$B$273,P27)
A28: wfjsp2_7 | B28: WFJSP 1-8 | C28: =AVERAGEIFS(Data_Inst!$G$2:$G$2883,Data_Inst!$A$2:$A$2883,$B$2,Data_Inst!$B$2:$B$2883,$A28)*100 | D28: =AVERAGEIFS(Data_Inst!$G$2:$G$2883,Data_Inst!$A$2:$A$2883,$B$3,Data_Inst!$B$2:$B$2883,$A28)*100 | E28: =ROUND(C28-D28,9)
A29: wfjsp2_8 | B29: WFJSP 1-8 | C29: =AVERAGEIFS(Data_Inst!$G$2:$G$2883,Data_Inst!$A$2:$A$2883,$B$2,Data_Inst!$B$2:$B$2883,$A29)*100 | D29: =AVERAGEIFS(Data_Inst!$G$2:$G$2883,Data_Inst!$A$2:$A$2883,$B$3,Data_Inst!$B$2:$B$2883,$A29)*100 | E29: =ROUND(C29-D29,9)
A30: wfjsp2_9 | B30: WFJSP 1-8 | C30: =AVERAGEIFS(Data_Inst!$G$2:$G$2883,Data_Inst!$A$2:$A$2883,$B$2,Data_Inst!$B$2:$B$2883,$A30)*100 | D30: =AVERAGEIFS(Data_Inst!$G$2:$G$2883,Data_Inst!$A$2:$A$2883,$B$3,Data_Inst!$B$2:$B$2883,$A30)*100 | E30: =ROUND(C30-D30,9)
A31: wfjsp2_10 | B31: WFJSP 1-8 | C31: =AVERAGEIFS(Data_Inst!$G$2:$G$2883,Data_Inst!$A$2:$A$2883,$B$2,Data_Inst!$B$2:$B$2883,$A31)*100 | D31: =AVERAGEIFS(Data_Inst!$G$2:$G$2883,Data_Inst!$A$2:$A$2883,$B$3,Data_Inst!$B$2:$B$2883,$A31)*100 | E31: =ROUND(C31-D31,9)
A32: wfjsp3_1 | B32: WFJSP 1-8 | C32: =AVERAGEIFS(Data_Inst!$G$2:$G$2883,Data_Inst!$A$2:$A$2883,$B$2,Data_Inst!$B$2:$B$2883,$A32)*100 | D32: =AVERAGEIFS(Data_Inst!$G$2:$G$2883,Data_Inst!$A$2:$A$2883,$B$3,Data_Inst!$B$2:$B$2883,$A32)*100 | E32: =ROUND(C32-D32,9)
A33: wfjsp3_2 | B33: WFJSP 1-8 | C33: =AVERAGEIFS(Data_Inst!$G$2:$G$2883,Data_Inst!$A$2:$A$2883,$B$2,Data_Inst!$B$2:$B$2883,$A33)*100 | D33: =AVERAGEIFS(Data_Inst!$G$2:$G$2883,Data_Inst!$A$2:$A$2883,$B$3,Data_Inst!$B$2:$B$2883,$A33)*100 | E33: =ROUND(C33-D33,9)
A34: wfjsp3_3 | B34: WFJSP 1-8 | C34: =AVERAGEIFS(Data_Inst!$G$2:$G$2883,Data_Inst!$A$2:$A$2883,$B$2,Data_Inst!$B$2:$B$2883,$A34)*100 | D34: =AVERAGEIFS(Data_Inst!$G$2:$G$2883,Data_Inst!$A$2:$A$2883,$B$3,Data_Inst!$B$2:$B$2883,$A34)*100 | E34: =ROUND(C34-D34,9)
A35: wfjsp3_4 | B35: WFJSP 1-8 | C35: =AVERAGEIFS(Data_Inst!$G$2:$G$2883,Data_Inst!$A$2:$A$2883,$B$2,Data_Inst!$B$2:$B$2883,$A35)*100 | D35: =AVERAGEIFS(Data_Inst!$G$2:$G$2883,Data_Inst!$A$2:$A$2883,$B$3,Data_Inst!$B$2:$B$2883,$A35)*100 | E35: =ROUND(C35-D35,9)
A36: wfjsp3_5 | B36: WFJSP 1-8 | C36: =AVERAGEIFS(Data_Inst!$G$2:$G$2883,Data_Inst!$A$2:$A$2883,$B$2,Data_Inst!$B$2:$B$2883,$A36)*100 | D36: =AVERAGEIFS(Data_Inst!$G$2:$G$2883,Data_Inst!$A$2:$A$2883,$B$3,Data_Inst!$B$2:$B$2883,$A36)*100 | E36: =ROUND(C36-D36,9)
A37: wfjsp3_6 | B37: WFJSP 1-8 | C37: =AVERAGEIFS(Data_Inst!$G$2:$G$2883,Data_Inst!$A$2:$A$2883,$B$2,Data_Inst!$B$2:$B$2883,$A37)*100 | D37: =AVERAGEIFS(Data_Inst!$G$2:$G$2883,Data_Inst!$A$2:$A$2883,$B$3,Data_Inst!$B$2:$B$2883,$A37)*100 | E37: =ROUND(C37-D37,9)
A38: wfjsp3_7 | B38: WFJSP 1-8 | C38: =AVERAGEIFS(Data_Inst!$G$2:$G$2883,Data_Inst!$A$2:$A$2883,$B$2,Data_Inst!$B$2:$B$2883,$A38)*100 | D38: =AVERAGEIFS(Data_Inst!$G$2:$G$2883,Data_Inst!$A$2:$A$2883,$B$3,Data_Inst!$B$2:$B$2883,$A38)*100 | E38: =ROUND(C38-D38,9)
A39: wfjsp3_8 | B39: WFJSP 1-8 | C39: =AVERAGEIFS(Data_Inst!$G$2:$G$2883,Data_Inst!$A$2:$A$2883,$B$2,Data_Inst!$B$2:$B$2883,$A39)*100 | D39: =AVERAGEIFS(Data_Inst!$G$2:$G$2883,Data_Inst!$A$2:$A$2883,$B$3,Data_Inst!$B$2:$B$2883,$A39)*100 | E39: =ROUND(C39-D39,9)
... A273: DP12 | B273: DP | C273: =AVERAGEIFS(Data_Inst!$G$2:$G$2883,Data_Inst!$A$2:$A$2883,$B$2,Data_Inst!$B$2:$B$2883,$A273)*100 | D273: =AVERAGEIFS(Data_Inst!$G$2:$G$2883,Data_Inst!$A$2:$A$2883,$B$3,Data_Inst!$B$2:$B$2883,$A273)*100 | E273: =ROUND(C273-D273,9)

Sheet S51_3
A1: Section 5.1: CP_LBBD_CP_TS vs CP_LBBD_CP, gap in % (one run per instance)
A2: Method A | B2: CP_LBBD_CP_TS | P2: Step | Q2: Value | R2: Meaning
A3: Method B | B3: CP_LBBD_CP | P3: n (instances) | Q3: =COUNT($E$12:$E$273) | R3: all 262 instances; none is discarded, ties (difference 0) included
A4: Measure | B4: gap | P4: zero differences | Q4: =COUNTIF($E$12:$E$273,0) | R4: instances where A and B are equal (kept in the t-test)
A5: Seeds averaged (1..n) | B5: - | P5: mean difference A - B | Q5: =AVERAGE($E$12:$E$273) | R5: in percentage points; negative favors A
A6: Reported in | B6: Section 5.1 | P6: std. dev. of differences | Q6: =_xlfn.STDEV.S($E$12:$E$273)
P7: standard error | Q7: =Q6/SQRT(Q3) | R7: sd / sqrt(n)
P8: t | Q8: =Q5/Q7 | R8: mean / standard error
P9: df | Q9: =Q3-1
A10: Steps: C, D = result of A and B per instance (in %); E = difference A - B; column Q = paired t-test on all instances. Changing the yellow cells B2:B5 tests another pair. | P10: p (t-test, two-sided) | Q10: =_xlfn.T.DIST.2T(ABS(Q8),Q9) | R10: H0: mean difference = 0
A11: instance | B11: group | C11: A (%) | D11: B (%) | E11: diff A-B | P11: p check: T.TEST | Q11: =_xlfn.T.TEST($C$12:$C$273,$D$12:$D$273,2,1) | R11: Excel's built-in paired test, must equal Q10
A12: wfjsp1_1 | B12: WFJSP 1-8 | C12: =AVERAGEIFS(Data_Inst!$F$2:$F$2883,Data_Inst!$A$2:$A$2883,$B$2,Data_Inst!$B$2:$B$2883,$A12)*100 | D12: =AVERAGEIFS(Data_Inst!$F$2:$F$2883,Data_Inst!$A$2:$A$2883,$B$3,Data_Inst!$B$2:$B$2883,$A12)*100 | E12: =ROUND(C12-D12,9) | P12: 95% CI low | Q12: =Q5-_xlfn.T.INV.2T(0.05,Q9)*Q7
A13: wfjsp1_2 | B13: WFJSP 1-8 | C13: =AVERAGEIFS(Data_Inst!$F$2:$F$2883,Data_Inst!$A$2:$A$2883,$B$2,Data_Inst!$B$2:$B$2883,$A13)*100 | D13: =AVERAGEIFS(Data_Inst!$F$2:$F$2883,Data_Inst!$A$2:$A$2883,$B$3,Data_Inst!$B$2:$B$2883,$A13)*100 | E13: =ROUND(C13-D13,9) | P13: 95% CI high | Q13: =Q5+_xlfn.T.INV.2T(0.05,Q9)*Q7
A14: wfjsp1_3 | B14: WFJSP 1-8 | C14: =AVERAGEIFS(Data_Inst!$F$2:$F$2883,Data_Inst!$A$2:$A$2883,$B$2,Data_Inst!$B$2:$B$2883,$A14)*100 | D14: =AVERAGEIFS(Data_Inst!$F$2:$F$2883,Data_Inst!$A$2:$A$2883,$B$3,Data_Inst!$B$2:$B$2883,$A14)*100 | E14: =ROUND(C14-D14,9) | P14: better / equal / worse | Q14: =COUNTIF($E$12:$E$273,"<0")&" / "&COUNTIF($E$12:$E$273,0)&" / "&COUNTIF($E$12:$E$273,">0") | R14: A better (smaller), equal, worse than B
A15: wfjsp1_4 | B15: WFJSP 1-8 | C15: =AVERAGEIFS(Data_Inst!$F$2:$F$2883,Data_Inst!$A$2:$A$2883,$B$2,Data_Inst!$B$2:$B$2883,$A15)*100 | D15: =AVERAGEIFS(Data_Inst!$F$2:$F$2883,Data_Inst!$A$2:$A$2883,$B$3,Data_Inst!$B$2:$B$2883,$A15)*100 | E15: =ROUND(C15-D15,9) | P15: skewness | Q15: =SKEW($E$12:$E$273) | R15: normality is not needed for n = 262 (central limit theorem), see the permutation check
A16: wfjsp1_5 | B16: WFJSP 1-8 | C16: =AVERAGEIFS(Data_Inst!$F$2:$F$2883,Data_Inst!$A$2:$A$2883,$B$2,Data_Inst!$B$2:$B$2883,$A16)*100 | D16: =AVERAGEIFS(Data_Inst!$F$2:$F$2883,Data_Inst!$A$2:$A$2883,$B$3,Data_Inst!$B$2:$B$2883,$A16)*100 | E16: =ROUND(C16-D16,9) | P16: excess kurtosis | Q16: =KURT($E$12:$E$273)
A17: wfjsp1_6 | B17: WFJSP 1-8 | C17: =AVERAGEIFS(Data_Inst!$F$2:$F$2883,Data_Inst!$A$2:$A$2883,$B$2,Data_Inst!$B$2:$B$2883,$A17)*100 | D17: =AVERAGEIFS(Data_Inst!$F$2:$F$2883,Data_Inst!$A$2:$A$2883,$B$3,Data_Inst!$B$2:$B$2883,$A17)*100 | E17: =ROUND(C17-D17,9) | P17: p (t-test, SciPy, value) | Q17: 6.4479023e-24 | R17: scipy.stats.ttest_1samp on the differences
A18: wfjsp1_7 | B18: WFJSP 1-8 | C18: =AVERAGEIFS(Data_Inst!$F$2:$F$2883,Data_Inst!$A$2:$A$2883,$B$2,Data_Inst!$B$2:$B$2883,$A18)*100 | D18: =AVERAGEIFS(Data_Inst!$F$2:$F$2883,Data_Inst!$A$2:$A$2883,$B$3,Data_Inst!$B$2:$B$2883,$A18)*100 | E18: =ROUND(C18-D18,9) | P18: p (permutation, value) | Q18: 4.999975e-06 | R18: exact test of the mean: random sign flips of the differences, 200,000 draws (smallest possible p = 1/200,001)
A19: wfjsp1_8 | B19: WFJSP 1-8 | C19: =AVERAGEIFS(Data_Inst!$F$2:$F$2883,Data_Inst!$A$2:$A$2883,$B$2,Data_Inst!$B$2:$B$2883,$A19)*100 | D19: =AVERAGEIFS(Data_Inst!$F$2:$F$2883,Data_Inst!$A$2:$A$2883,$B$3,Data_Inst!$B$2:$B$2883,$A19)*100 | E19: =ROUND(C19-D19,9) | P19: bootstrap 95% CI low (value) | Q19: -0.99236654 | R19: 20,000 bootstrap resamples of the instances
A20: wfjsp1_9 | B20: WFJSP 1-8 | C20: =AVERAGEIFS(Data_Inst!$F$2:$F$2883,Data_Inst!$A$2:$A$2883,$B$2,Data_Inst!$B$2:$B$2883,$A20)*100 | D20: =AVERAGEIFS(Data_Inst!$F$2:$F$2883,Data_Inst!$A$2:$A$2883,$B$3,Data_Inst!$B$2:$B$2883,$A20)*100 | E20: =ROUND(C20-D20,9) | P20: bootstrap 95% CI high (value) | Q20: -0.69681001
A21: wfjsp1_10 | B21: WFJSP 1-8 | C21: =AVERAGEIFS(Data_Inst!$F$2:$F$2883,Data_Inst!$A$2:$A$2883,$B$2,Data_Inst!$B$2:$B$2883,$A21)*100 | D21: =AVERAGEIFS(Data_Inst!$F$2:$F$2883,Data_Inst!$A$2:$A$2883,$B$3,Data_Inst!$B$2:$B$2883,$A21)*100 | E21: =ROUND(C21-D21,9)
A22: wfjsp2_1 | B22: WFJSP 1-8 | C22: =AVERAGEIFS(Data_Inst!$F$2:$F$2883,Data_Inst!$A$2:$A$2883,$B$2,Data_Inst!$B$2:$B$2883,$A22)*100 | D22: =AVERAGEIFS(Data_Inst!$F$2:$F$2883,Data_Inst!$A$2:$A$2883,$B$3,Data_Inst!$B$2:$B$2883,$A22)*100 | E22: =ROUND(C22-D22,9) | P22: Mean difference per group
A23: wfjsp2_2 | B23: WFJSP 1-8 | C23: =AVERAGEIFS(Data_Inst!$F$2:$F$2883,Data_Inst!$A$2:$A$2883,$B$2,Data_Inst!$B$2:$B$2883,$A23)*100 | D23: =AVERAGEIFS(Data_Inst!$F$2:$F$2883,Data_Inst!$A$2:$A$2883,$B$3,Data_Inst!$B$2:$B$2883,$A23)*100 | E23: =ROUND(C23-D23,9) | P23: WFJSP 1-8 | Q23: =AVERAGEIFS($E$12:$E$273,$B$12:$B$273,P23)
A24: wfjsp2_3 | B24: WFJSP 1-8 | C24: =AVERAGEIFS(Data_Inst!$F$2:$F$2883,Data_Inst!$A$2:$A$2883,$B$2,Data_Inst!$B$2:$B$2883,$A24)*100 | D24: =AVERAGEIFS(Data_Inst!$F$2:$F$2883,Data_Inst!$A$2:$A$2883,$B$3,Data_Inst!$B$2:$B$2883,$A24)*100 | E24: =ROUND(C24-D24,9) | P24: WFJSP 9-16 | Q24: =AVERAGEIFS($E$12:$E$273,$B$12:$B$273,P24)
A25: wfjsp2_4 | B25: WFJSP 1-8 | C25: =AVERAGEIFS(Data_Inst!$F$2:$F$2883,Data_Inst!$A$2:$A$2883,$B$2,Data_Inst!$B$2:$B$2883,$A25)*100 | D25: =AVERAGEIFS(Data_Inst!$F$2:$F$2883,Data_Inst!$A$2:$A$2883,$B$3,Data_Inst!$B$2:$B$2883,$A25)*100 | E25: =ROUND(C25-D25,9) | P25: WFJSP 17-24 | Q25: =AVERAGEIFS($E$12:$E$273,$B$12:$B$273,P25)
A26: wfjsp2_5 | B26: WFJSP 1-8 | C26: =AVERAGEIFS(Data_Inst!$F$2:$F$2883,Data_Inst!$A$2:$A$2883,$B$2,Data_Inst!$B$2:$B$2883,$A26)*100 | D26: =AVERAGEIFS(Data_Inst!$F$2:$F$2883,Data_Inst!$A$2:$A$2883,$B$3,Data_Inst!$B$2:$B$2883,$A26)*100 | E26: =ROUND(C26-D26,9) | P26: MK | Q26: =AVERAGEIFS($E$12:$E$273,$B$12:$B$273,P26)
A27: wfjsp2_6 | B27: WFJSP 1-8 | C27: =AVERAGEIFS(Data_Inst!$F$2:$F$2883,Data_Inst!$A$2:$A$2883,$B$2,Data_Inst!$B$2:$B$2883,$A27)*100 | D27: =AVERAGEIFS(Data_Inst!$F$2:$F$2883,Data_Inst!$A$2:$A$2883,$B$3,Data_Inst!$B$2:$B$2883,$A27)*100 | E27: =ROUND(C27-D27,9) | P27: DP | Q27: =AVERAGEIFS($E$12:$E$273,$B$12:$B$273,P27)
A28: wfjsp2_7 | B28: WFJSP 1-8 | C28: =AVERAGEIFS(Data_Inst!$F$2:$F$2883,Data_Inst!$A$2:$A$2883,$B$2,Data_Inst!$B$2:$B$2883,$A28)*100 | D28: =AVERAGEIFS(Data_Inst!$F$2:$F$2883,Data_Inst!$A$2:$A$2883,$B$3,Data_Inst!$B$2:$B$2883,$A28)*100 | E28: =ROUND(C28-D28,9)
A29: wfjsp2_8 | B29: WFJSP 1-8 | C29: =AVERAGEIFS(Data_Inst!$F$2:$F$2883,Data_Inst!$A$2:$A$2883,$B$2,Data_Inst!$B$2:$B$2883,$A29)*100 | D29: =AVERAGEIFS(Data_Inst!$F$2:$F$2883,Data_Inst!$A$2:$A$2883,$B$3,Data_Inst!$B$2:$B$2883,$A29)*100 | E29: =ROUND(C29-D29,9)
A30: wfjsp2_9 | B30: WFJSP 1-8 | C30: =AVERAGEIFS(Data_Inst!$F$2:$F$2883,Data_Inst!$A$2:$A$2883,$B$2,Data_Inst!$B$2:$B$2883,$A30)*100 | D30: =AVERAGEIFS(Data_Inst!$F$2:$F$2883,Data_Inst!$A$2:$A$2883,$B$3,Data_Inst!$B$2:$B$2883,$A30)*100 | E30: =ROUND(C30-D30,9)
A31: wfjsp2_10 | B31: WFJSP 1-8 | C31: =AVERAGEIFS(Data_Inst!$F$2:$F$2883,Data_Inst!$A$2:$A$2883,$B$2,Data_Inst!$B$2:$B$2883,$A31)*100 | D31: =AVERAGEIFS(Data_Inst!$F$2:$F$2883,Data_Inst!$A$2:$A$2883,$B$3,Data_Inst!$B$2:$B$2883,$A31)*100 | E31: =ROUND(C31-D31,9)
A32: wfjsp3_1 | B32: WFJSP 1-8 | C32: =AVERAGEIFS(Data_Inst!$F$2:$F$2883,Data_Inst!$A$2:$A$2883,$B$2,Data_Inst!$B$2:$B$2883,$A32)*100 | D32: =AVERAGEIFS(Data_Inst!$F$2:$F$2883,Data_Inst!$A$2:$A$2883,$B$3,Data_Inst!$B$2:$B$2883,$A32)*100 | E32: =ROUND(C32-D32,9)
A33: wfjsp3_2 | B33: WFJSP 1-8 | C33: =AVERAGEIFS(Data_Inst!$F$2:$F$2883,Data_Inst!$A$2:$A$2883,$B$2,Data_Inst!$B$2:$B$2883,$A33)*100 | D33: =AVERAGEIFS(Data_Inst!$F$2:$F$2883,Data_Inst!$A$2:$A$2883,$B$3,Data_Inst!$B$2:$B$2883,$A33)*100 | E33: =ROUND(C33-D33,9)
A34: wfjsp3_3 | B34: WFJSP 1-8 | C34: =AVERAGEIFS(Data_Inst!$F$2:$F$2883,Data_Inst!$A$2:$A$2883,$B$2,Data_Inst!$B$2:$B$2883,$A34)*100 | D34: =AVERAGEIFS(Data_Inst!$F$2:$F$2883,Data_Inst!$A$2:$A$2883,$B$3,Data_Inst!$B$2:$B$2883,$A34)*100 | E34: =ROUND(C34-D34,9)
A35: wfjsp3_4 | B35: WFJSP 1-8 | C35: =AVERAGEIFS(Data_Inst!$F$2:$F$2883,Data_Inst!$A$2:$A$2883,$B$2,Data_Inst!$B$2:$B$2883,$A35)*100 | D35: =AVERAGEIFS(Data_Inst!$F$2:$F$2883,Data_Inst!$A$2:$A$2883,$B$3,Data_Inst!$B$2:$B$2883,$A35)*100 | E35: =ROUND(C35-D35,9)
A36: wfjsp3_5 | B36: WFJSP 1-8 | C36: =AVERAGEIFS(Data_Inst!$F$2:$F$2883,Data_Inst!$A$2:$A$2883,$B$2,Data_Inst!$B$2:$B$2883,$A36)*100 | D36: =AVERAGEIFS(Data_Inst!$F$2:$F$2883,Data_Inst!$A$2:$A$2883,$B$3,Data_Inst!$B$2:$B$2883,$A36)*100 | E36: =ROUND(C36-D36,9)
A37: wfjsp3_6 | B37: WFJSP 1-8 | C37: =AVERAGEIFS(Data_Inst!$F$2:$F$2883,Data_Inst!$A$2:$A$2883,$B$2,Data_Inst!$B$2:$B$2883,$A37)*100 | D37: =AVERAGEIFS(Data_Inst!$F$2:$F$2883,Data_Inst!$A$2:$A$2883,$B$3,Data_Inst!$B$2:$B$2883,$A37)*100 | E37: =ROUND(C37-D37,9)
A38: wfjsp3_7 | B38: WFJSP 1-8 | C38: =AVERAGEIFS(Data_Inst!$F$2:$F$2883,Data_Inst!$A$2:$A$2883,$B$2,Data_Inst!$B$2:$B$2883,$A38)*100 | D38: =AVERAGEIFS(Data_Inst!$F$2:$F$2883,Data_Inst!$A$2:$A$2883,$B$3,Data_Inst!$B$2:$B$2883,$A38)*100 | E38: =ROUND(C38-D38,9)
A39: wfjsp3_8 | B39: WFJSP 1-8 | C39: =AVERAGEIFS(Data_Inst!$F$2:$F$2883,Data_Inst!$A$2:$A$2883,$B$2,Data_Inst!$B$2:$B$2883,$A39)*100 | D39: =AVERAGEIFS(Data_Inst!$F$2:$F$2883,Data_Inst!$A$2:$A$2883,$B$3,Data_Inst!$B$2:$B$2883,$A39)*100 | E39: =ROUND(C39-D39,9)
... A273: DP12 | B273: DP | C273: =AVERAGEIFS(Data_Inst!$F$2:$F$2883,Data_Inst!$A$2:$A$2883,$B$2,Data_Inst!$B$2:$B$2883,$A273)*100 | D273: =AVERAGEIFS(Data_Inst!$F$2:$F$2883,Data_Inst!$A$2:$A$2883,$B$3,Data_Inst!$B$2:$B$2883,$A273)*100 | E273: =ROUND(C273-D273,9)

Sheet S51_4
A1: Section 5.1: CP_LBBD_CP_TS vs CP_LBBD_CP, RPD in % (one run per instance)
A2: Method A | B2: CP_LBBD_CP_TS | P2: Step | Q2: Value | R2: Meaning
A3: Method B | B3: CP_LBBD_CP | P3: n (instances) | Q3: =COUNT($E$12:$E$273) | R3: all 262 instances; none is discarded, ties (difference 0) included
A4: Measure | B4: RPD | P4: zero differences | Q4: =COUNTIF($E$12:$E$273,0) | R4: instances where A and B are equal (kept in the t-test)
A5: Seeds averaged (1..n) | B5: - | P5: mean difference A - B | Q5: =AVERAGE($E$12:$E$273) | R5: in percentage points; negative favors A
A6: Reported in | B6: (not quoted in the text) | P6: std. dev. of differences | Q6: =_xlfn.STDEV.S($E$12:$E$273)
P7: standard error | Q7: =Q6/SQRT(Q3) | R7: sd / sqrt(n)
P8: t | Q8: =Q5/Q7 | R8: mean / standard error
P9: df | Q9: =Q3-1
A10: Steps: C, D = result of A and B per instance (in %); E = difference A - B; column Q = paired t-test on all instances. Changing the yellow cells B2:B5 tests another pair. | P10: p (t-test, two-sided) | Q10: =_xlfn.T.DIST.2T(ABS(Q8),Q9) | R10: H0: mean difference = 0
A11: instance | B11: group | C11: A (%) | D11: B (%) | E11: diff A-B | P11: p check: T.TEST | Q11: =_xlfn.T.TEST($C$12:$C$273,$D$12:$D$273,2,1) | R11: Excel's built-in paired test, must equal Q10
A12: wfjsp1_1 | B12: WFJSP 1-8 | C12: =AVERAGEIFS(Data_Inst!$G$2:$G$2883,Data_Inst!$A$2:$A$2883,$B$2,Data_Inst!$B$2:$B$2883,$A12)*100 | D12: =AVERAGEIFS(Data_Inst!$G$2:$G$2883,Data_Inst!$A$2:$A$2883,$B$3,Data_Inst!$B$2:$B$2883,$A12)*100 | E12: =ROUND(C12-D12,9) | P12: 95% CI low | Q12: =Q5-_xlfn.T.INV.2T(0.05,Q9)*Q7
A13: wfjsp1_2 | B13: WFJSP 1-8 | C13: =AVERAGEIFS(Data_Inst!$G$2:$G$2883,Data_Inst!$A$2:$A$2883,$B$2,Data_Inst!$B$2:$B$2883,$A13)*100 | D13: =AVERAGEIFS(Data_Inst!$G$2:$G$2883,Data_Inst!$A$2:$A$2883,$B$3,Data_Inst!$B$2:$B$2883,$A13)*100 | E13: =ROUND(C13-D13,9) | P13: 95% CI high | Q13: =Q5+_xlfn.T.INV.2T(0.05,Q9)*Q7
A14: wfjsp1_3 | B14: WFJSP 1-8 | C14: =AVERAGEIFS(Data_Inst!$G$2:$G$2883,Data_Inst!$A$2:$A$2883,$B$2,Data_Inst!$B$2:$B$2883,$A14)*100 | D14: =AVERAGEIFS(Data_Inst!$G$2:$G$2883,Data_Inst!$A$2:$A$2883,$B$3,Data_Inst!$B$2:$B$2883,$A14)*100 | E14: =ROUND(C14-D14,9) | P14: better / equal / worse | Q14: =COUNTIF($E$12:$E$273,"<0")&" / "&COUNTIF($E$12:$E$273,0)&" / "&COUNTIF($E$12:$E$273,">0") | R14: A better (smaller), equal, worse than B
A15: wfjsp1_4 | B15: WFJSP 1-8 | C15: =AVERAGEIFS(Data_Inst!$G$2:$G$2883,Data_Inst!$A$2:$A$2883,$B$2,Data_Inst!$B$2:$B$2883,$A15)*100 | D15: =AVERAGEIFS(Data_Inst!$G$2:$G$2883,Data_Inst!$A$2:$A$2883,$B$3,Data_Inst!$B$2:$B$2883,$A15)*100 | E15: =ROUND(C15-D15,9) | P15: skewness | Q15: =SKEW($E$12:$E$273) | R15: normality is not needed for n = 262 (central limit theorem), see the permutation check
A16: wfjsp1_5 | B16: WFJSP 1-8 | C16: =AVERAGEIFS(Data_Inst!$G$2:$G$2883,Data_Inst!$A$2:$A$2883,$B$2,Data_Inst!$B$2:$B$2883,$A16)*100 | D16: =AVERAGEIFS(Data_Inst!$G$2:$G$2883,Data_Inst!$A$2:$A$2883,$B$3,Data_Inst!$B$2:$B$2883,$A16)*100 | E16: =ROUND(C16-D16,9) | P16: excess kurtosis | Q16: =KURT($E$12:$E$273)
A17: wfjsp1_6 | B17: WFJSP 1-8 | C17: =AVERAGEIFS(Data_Inst!$G$2:$G$2883,Data_Inst!$A$2:$A$2883,$B$2,Data_Inst!$B$2:$B$2883,$A17)*100 | D17: =AVERAGEIFS(Data_Inst!$G$2:$G$2883,Data_Inst!$A$2:$A$2883,$B$3,Data_Inst!$B$2:$B$2883,$A17)*100 | E17: =ROUND(C17-D17,9) | P17: p (t-test, SciPy, value) | Q17: 1.6292733e-23 | R17: scipy.stats.ttest_1samp on the differences
A18: wfjsp1_7 | B18: WFJSP 1-8 | C18: =AVERAGEIFS(Data_Inst!$G$2:$G$2883,Data_Inst!$A$2:$A$2883,$B$2,Data_Inst!$B$2:$B$2883,$A18)*100 | D18: =AVERAGEIFS(Data_Inst!$G$2:$G$2883,Data_Inst!$A$2:$A$2883,$B$3,Data_Inst!$B$2:$B$2883,$A18)*100 | E18: =ROUND(C18-D18,9) | P18: p (permutation, value) | Q18: 4.999975e-06 | R18: exact test of the mean: random sign flips of the differences, 200,000 draws (smallest possible p = 1/200,001)
A19: wfjsp1_8 | B19: WFJSP 1-8 | C19: =AVERAGEIFS(Data_Inst!$G$2:$G$2883,Data_Inst!$A$2:$A$2883,$B$2,Data_Inst!$B$2:$B$2883,$A19)*100 | D19: =AVERAGEIFS(Data_Inst!$G$2:$G$2883,Data_Inst!$A$2:$A$2883,$B$3,Data_Inst!$B$2:$B$2883,$A19)*100 | E19: =ROUND(C19-D19,9) | P19: bootstrap 95% CI low (value) | Q19: -1.1042655 | R19: 20,000 bootstrap resamples of the instances
A20: wfjsp1_9 | B20: WFJSP 1-8 | C20: =AVERAGEIFS(Data_Inst!$G$2:$G$2883,Data_Inst!$A$2:$A$2883,$B$2,Data_Inst!$B$2:$B$2883,$A20)*100 | D20: =AVERAGEIFS(Data_Inst!$G$2:$G$2883,Data_Inst!$A$2:$A$2883,$B$3,Data_Inst!$B$2:$B$2883,$A20)*100 | E20: =ROUND(C20-D20,9) | P20: bootstrap 95% CI high (value) | Q20: -0.77421834
A21: wfjsp1_10 | B21: WFJSP 1-8 | C21: =AVERAGEIFS(Data_Inst!$G$2:$G$2883,Data_Inst!$A$2:$A$2883,$B$2,Data_Inst!$B$2:$B$2883,$A21)*100 | D21: =AVERAGEIFS(Data_Inst!$G$2:$G$2883,Data_Inst!$A$2:$A$2883,$B$3,Data_Inst!$B$2:$B$2883,$A21)*100 | E21: =ROUND(C21-D21,9)
A22: wfjsp2_1 | B22: WFJSP 1-8 | C22: =AVERAGEIFS(Data_Inst!$G$2:$G$2883,Data_Inst!$A$2:$A$2883,$B$2,Data_Inst!$B$2:$B$2883,$A22)*100 | D22: =AVERAGEIFS(Data_Inst!$G$2:$G$2883,Data_Inst!$A$2:$A$2883,$B$3,Data_Inst!$B$2:$B$2883,$A22)*100 | E22: =ROUND(C22-D22,9) | P22: Mean difference per group
A23: wfjsp2_2 | B23: WFJSP 1-8 | C23: =AVERAGEIFS(Data_Inst!$G$2:$G$2883,Data_Inst!$A$2:$A$2883,$B$2,Data_Inst!$B$2:$B$2883,$A23)*100 | D23: =AVERAGEIFS(Data_Inst!$G$2:$G$2883,Data_Inst!$A$2:$A$2883,$B$3,Data_Inst!$B$2:$B$2883,$A23)*100 | E23: =ROUND(C23-D23,9) | P23: WFJSP 1-8 | Q23: =AVERAGEIFS($E$12:$E$273,$B$12:$B$273,P23)
A24: wfjsp2_3 | B24: WFJSP 1-8 | C24: =AVERAGEIFS(Data_Inst!$G$2:$G$2883,Data_Inst!$A$2:$A$2883,$B$2,Data_Inst!$B$2:$B$2883,$A24)*100 | D24: =AVERAGEIFS(Data_Inst!$G$2:$G$2883,Data_Inst!$A$2:$A$2883,$B$3,Data_Inst!$B$2:$B$2883,$A24)*100 | E24: =ROUND(C24-D24,9) | P24: WFJSP 9-16 | Q24: =AVERAGEIFS($E$12:$E$273,$B$12:$B$273,P24)
A25: wfjsp2_4 | B25: WFJSP 1-8 | C25: =AVERAGEIFS(Data_Inst!$G$2:$G$2883,Data_Inst!$A$2:$A$2883,$B$2,Data_Inst!$B$2:$B$2883,$A25)*100 | D25: =AVERAGEIFS(Data_Inst!$G$2:$G$2883,Data_Inst!$A$2:$A$2883,$B$3,Data_Inst!$B$2:$B$2883,$A25)*100 | E25: =ROUND(C25-D25,9) | P25: WFJSP 17-24 | Q25: =AVERAGEIFS($E$12:$E$273,$B$12:$B$273,P25)
A26: wfjsp2_5 | B26: WFJSP 1-8 | C26: =AVERAGEIFS(Data_Inst!$G$2:$G$2883,Data_Inst!$A$2:$A$2883,$B$2,Data_Inst!$B$2:$B$2883,$A26)*100 | D26: =AVERAGEIFS(Data_Inst!$G$2:$G$2883,Data_Inst!$A$2:$A$2883,$B$3,Data_Inst!$B$2:$B$2883,$A26)*100 | E26: =ROUND(C26-D26,9) | P26: MK | Q26: =AVERAGEIFS($E$12:$E$273,$B$12:$B$273,P26)
A27: wfjsp2_6 | B27: WFJSP 1-8 | C27: =AVERAGEIFS(Data_Inst!$G$2:$G$2883,Data_Inst!$A$2:$A$2883,$B$2,Data_Inst!$B$2:$B$2883,$A27)*100 | D27: =AVERAGEIFS(Data_Inst!$G$2:$G$2883,Data_Inst!$A$2:$A$2883,$B$3,Data_Inst!$B$2:$B$2883,$A27)*100 | E27: =ROUND(C27-D27,9) | P27: DP | Q27: =AVERAGEIFS($E$12:$E$273,$B$12:$B$273,P27)
A28: wfjsp2_7 | B28: WFJSP 1-8 | C28: =AVERAGEIFS(Data_Inst!$G$2:$G$2883,Data_Inst!$A$2:$A$2883,$B$2,Data_Inst!$B$2:$B$2883,$A28)*100 | D28: =AVERAGEIFS(Data_Inst!$G$2:$G$2883,Data_Inst!$A$2:$A$2883,$B$3,Data_Inst!$B$2:$B$2883,$A28)*100 | E28: =ROUND(C28-D28,9)
A29: wfjsp2_8 | B29: WFJSP 1-8 | C29: =AVERAGEIFS(Data_Inst!$G$2:$G$2883,Data_Inst!$A$2:$A$2883,$B$2,Data_Inst!$B$2:$B$2883,$A29)*100 | D29: =AVERAGEIFS(Data_Inst!$G$2:$G$2883,Data_Inst!$A$2:$A$2883,$B$3,Data_Inst!$B$2:$B$2883,$A29)*100 | E29: =ROUND(C29-D29,9)
A30: wfjsp2_9 | B30: WFJSP 1-8 | C30: =AVERAGEIFS(Data_Inst!$G$2:$G$2883,Data_Inst!$A$2:$A$2883,$B$2,Data_Inst!$B$2:$B$2883,$A30)*100 | D30: =AVERAGEIFS(Data_Inst!$G$2:$G$2883,Data_Inst!$A$2:$A$2883,$B$3,Data_Inst!$B$2:$B$2883,$A30)*100 | E30: =ROUND(C30-D30,9)
A31: wfjsp2_10 | B31: WFJSP 1-8 | C31: =AVERAGEIFS(Data_Inst!$G$2:$G$2883,Data_Inst!$A$2:$A$2883,$B$2,Data_Inst!$B$2:$B$2883,$A31)*100 | D31: =AVERAGEIFS(Data_Inst!$G$2:$G$2883,Data_Inst!$A$2:$A$2883,$B$3,Data_Inst!$B$2:$B$2883,$A31)*100 | E31: =ROUND(C31-D31,9)
A32: wfjsp3_1 | B32: WFJSP 1-8 | C32: =AVERAGEIFS(Data_Inst!$G$2:$G$2883,Data_Inst!$A$2:$A$2883,$B$2,Data_Inst!$B$2:$B$2883,$A32)*100 | D32: =AVERAGEIFS(Data_Inst!$G$2:$G$2883,Data_Inst!$A$2:$A$2883,$B$3,Data_Inst!$B$2:$B$2883,$A32)*100 | E32: =ROUND(C32-D32,9)
A33: wfjsp3_2 | B33: WFJSP 1-8 | C33: =AVERAGEIFS(Data_Inst!$G$2:$G$2883,Data_Inst!$A$2:$A$2883,$B$2,Data_Inst!$B$2:$B$2883,$A33)*100 | D33: =AVERAGEIFS(Data_Inst!$G$2:$G$2883,Data_Inst!$A$2:$A$2883,$B$3,Data_Inst!$B$2:$B$2883,$A33)*100 | E33: =ROUND(C33-D33,9)
A34: wfjsp3_3 | B34: WFJSP 1-8 | C34: =AVERAGEIFS(Data_Inst!$G$2:$G$2883,Data_Inst!$A$2:$A$2883,$B$2,Data_Inst!$B$2:$B$2883,$A34)*100 | D34: =AVERAGEIFS(Data_Inst!$G$2:$G$2883,Data_Inst!$A$2:$A$2883,$B$3,Data_Inst!$B$2:$B$2883,$A34)*100 | E34: =ROUND(C34-D34,9)
A35: wfjsp3_4 | B35: WFJSP 1-8 | C35: =AVERAGEIFS(Data_Inst!$G$2:$G$2883,Data_Inst!$A$2:$A$2883,$B$2,Data_Inst!$B$2:$B$2883,$A35)*100 | D35: =AVERAGEIFS(Data_Inst!$G$2:$G$2883,Data_Inst!$A$2:$A$2883,$B$3,Data_Inst!$B$2:$B$2883,$A35)*100 | E35: =ROUND(C35-D35,9)
A36: wfjsp3_5 | B36: WFJSP 1-8 | C36: =AVERAGEIFS(Data_Inst!$G$2:$G$2883,Data_Inst!$A$2:$A$2883,$B$2,Data_Inst!$B$2:$B$2883,$A36)*100 | D36: =AVERAGEIFS(Data_Inst!$G$2:$G$2883,Data_Inst!$A$2:$A$2883,$B$3,Data_Inst!$B$2:$B$2883,$A36)*100 | E36: =ROUND(C36-D36,9)
A37: wfjsp3_6 | B37: WFJSP 1-8 | C37: =AVERAGEIFS(Data_Inst!$G$2:$G$2883,Data_Inst!$A$2:$A$2883,$B$2,Data_Inst!$B$2:$B$2883,$A37)*100 | D37: =AVERAGEIFS(Data_Inst!$G$2:$G$2883,Data_Inst!$A$2:$A$2883,$B$3,Data_Inst!$B$2:$B$2883,$A37)*100 | E37: =ROUND(C37-D37,9)
A38: wfjsp3_7 | B38: WFJSP 1-8 | C38: =AVERAGEIFS(Data_Inst!$G$2:$G$2883,Data_Inst!$A$2:$A$2883,$B$2,Data_Inst!$B$2:$B$2883,$A38)*100 | D38: =AVERAGEIFS(Data_Inst!$G$2:$G$2883,Data_Inst!$A$2:$A$2883,$B$3,Data_Inst!$B$2:$B$2883,$A38)*100 | E38: =ROUND(C38-D38,9)
A39: wfjsp3_8 | B39: WFJSP 1-8 | C39: =AVERAGEIFS(Data_Inst!$G$2:$G$2883,Data_Inst!$A$2:$A$2883,$B$2,Data_Inst!$B$2:$B$2883,$A39)*100 | D39: =AVERAGEIFS(Data_Inst!$G$2:$G$2883,Data_Inst!$A$2:$A$2883,$B$3,Data_Inst!$B$2:$B$2883,$A39)*100 | E39: =ROUND(C39-D39,9)
... A273: DP12 | B273: DP | C273: =AVERAGEIFS(Data_Inst!$G$2:$G$2883,Data_Inst!$A$2:$A$2883,$B$2,Data_Inst!$B$2:$B$2883,$A273)*100 | D273: =AVERAGEIFS(Data_Inst!$G$2:$G$2883,Data_Inst!$A$2:$A$2883,$B$3,Data_Inst!$B$2:$B$2883,$A273)*100 | E273: =ROUND(C273-D273,9)

Sheet S51_5
A1: Section 5.1: CP_LBBD_CP_TS vs LBBD_CP_TS, gap in % (one run per instance)
A2: Method A | B2: CP_LBBD_CP_TS | P2: Step | Q2: Value | R2: Meaning
A3: Method B | B3: LBBD_CP_TS | P3: n (instances) | Q3: =COUNT($E$12:$E$273) | R3: all 262 instances; none is discarded, ties (difference 0) included
A4: Measure | B4: gap | P4: zero differences | Q4: =COUNTIF($E$12:$E$273,0) | R4: instances where A and B are equal (kept in the t-test)
A5: Seeds averaged (1..n) | B5: - | P5: mean difference A - B | Q5: =AVERAGE($E$12:$E$273) | R5: in percentage points; negative favors A
A6: Reported in | B6: Section 5.1 | P6: std. dev. of differences | Q6: =_xlfn.STDEV.S($E$12:$E$273)
P7: standard error | Q7: =Q6/SQRT(Q3) | R7: sd / sqrt(n)
P8: t | Q8: =Q5/Q7 | R8: mean / standard error
P9: df | Q9: =Q3-1
A10: Steps: C, D = result of A and B per instance (in %); E = difference A - B; column Q = paired t-test on all instances. Changing the yellow cells B2:B5 tests another pair. | P10: p (t-test, two-sided) | Q10: =_xlfn.T.DIST.2T(ABS(Q8),Q9) | R10: H0: mean difference = 0
A11: instance | B11: group | C11: A (%) | D11: B (%) | E11: diff A-B | P11: p check: T.TEST | Q11: =_xlfn.T.TEST($C$12:$C$273,$D$12:$D$273,2,1) | R11: Excel's built-in paired test, must equal Q10
A12: wfjsp1_1 | B12: WFJSP 1-8 | C12: =AVERAGEIFS(Data_Inst!$F$2:$F$2883,Data_Inst!$A$2:$A$2883,$B$2,Data_Inst!$B$2:$B$2883,$A12)*100 | D12: =AVERAGEIFS(Data_Inst!$F$2:$F$2883,Data_Inst!$A$2:$A$2883,$B$3,Data_Inst!$B$2:$B$2883,$A12)*100 | E12: =ROUND(C12-D12,9) | P12: 95% CI low | Q12: =Q5-_xlfn.T.INV.2T(0.05,Q9)*Q7
A13: wfjsp1_2 | B13: WFJSP 1-8 | C13: =AVERAGEIFS(Data_Inst!$F$2:$F$2883,Data_Inst!$A$2:$A$2883,$B$2,Data_Inst!$B$2:$B$2883,$A13)*100 | D13: =AVERAGEIFS(Data_Inst!$F$2:$F$2883,Data_Inst!$A$2:$A$2883,$B$3,Data_Inst!$B$2:$B$2883,$A13)*100 | E13: =ROUND(C13-D13,9) | P13: 95% CI high | Q13: =Q5+_xlfn.T.INV.2T(0.05,Q9)*Q7
A14: wfjsp1_3 | B14: WFJSP 1-8 | C14: =AVERAGEIFS(Data_Inst!$F$2:$F$2883,Data_Inst!$A$2:$A$2883,$B$2,Data_Inst!$B$2:$B$2883,$A14)*100 | D14: =AVERAGEIFS(Data_Inst!$F$2:$F$2883,Data_Inst!$A$2:$A$2883,$B$3,Data_Inst!$B$2:$B$2883,$A14)*100 | E14: =ROUND(C14-D14,9) | P14: better / equal / worse | Q14: =COUNTIF($E$12:$E$273,"<0")&" / "&COUNTIF($E$12:$E$273,0)&" / "&COUNTIF($E$12:$E$273,">0") | R14: A better (smaller), equal, worse than B
A15: wfjsp1_4 | B15: WFJSP 1-8 | C15: =AVERAGEIFS(Data_Inst!$F$2:$F$2883,Data_Inst!$A$2:$A$2883,$B$2,Data_Inst!$B$2:$B$2883,$A15)*100 | D15: =AVERAGEIFS(Data_Inst!$F$2:$F$2883,Data_Inst!$A$2:$A$2883,$B$3,Data_Inst!$B$2:$B$2883,$A15)*100 | E15: =ROUND(C15-D15,9) | P15: skewness | Q15: =SKEW($E$12:$E$273) | R15: normality is not needed for n = 262 (central limit theorem), see the permutation check
A16: wfjsp1_5 | B16: WFJSP 1-8 | C16: =AVERAGEIFS(Data_Inst!$F$2:$F$2883,Data_Inst!$A$2:$A$2883,$B$2,Data_Inst!$B$2:$B$2883,$A16)*100 | D16: =AVERAGEIFS(Data_Inst!$F$2:$F$2883,Data_Inst!$A$2:$A$2883,$B$3,Data_Inst!$B$2:$B$2883,$A16)*100 | E16: =ROUND(C16-D16,9) | P16: excess kurtosis | Q16: =KURT($E$12:$E$273)
A17: wfjsp1_6 | B17: WFJSP 1-8 | C17: =AVERAGEIFS(Data_Inst!$F$2:$F$2883,Data_Inst!$A$2:$A$2883,$B$2,Data_Inst!$B$2:$B$2883,$A17)*100 | D17: =AVERAGEIFS(Data_Inst!$F$2:$F$2883,Data_Inst!$A$2:$A$2883,$B$3,Data_Inst!$B$2:$B$2883,$A17)*100 | E17: =ROUND(C17-D17,9) | P17: p (t-test, SciPy, value) | Q17: 3.0804251e-05 | R17: scipy.stats.ttest_1samp on the differences
A18: wfjsp1_7 | B18: WFJSP 1-8 | C18: =AVERAGEIFS(Data_Inst!$F$2:$F$2883,Data_Inst!$A$2:$A$2883,$B$2,Data_Inst!$B$2:$B$2883,$A18)*100 | D18: =AVERAGEIFS(Data_Inst!$F$2:$F$2883,Data_Inst!$A$2:$A$2883,$B$3,Data_Inst!$B$2:$B$2883,$A18)*100 | E18: =ROUND(C18-D18,9) | P18: p (permutation, value) | Q18: 4.999975e-06 | R18: exact test of the mean: random sign flips of the differences, 200,000 draws (smallest possible p = 1/200,001)
A19: wfjsp1_8 | B19: WFJSP 1-8 | C19: =AVERAGEIFS(Data_Inst!$F$2:$F$2883,Data_Inst!$A$2:$A$2883,$B$2,Data_Inst!$B$2:$B$2883,$A19)*100 | D19: =AVERAGEIFS(Data_Inst!$F$2:$F$2883,Data_Inst!$A$2:$A$2883,$B$3,Data_Inst!$B$2:$B$2883,$A19)*100 | E19: =ROUND(C19-D19,9) | P19: bootstrap 95% CI low (value) | Q19: -0.57704447 | R19: 20,000 bootstrap resamples of the instances
A20: wfjsp1_9 | B20: WFJSP 1-8 | C20: =AVERAGEIFS(Data_Inst!$F$2:$F$2883,Data_Inst!$A$2:$A$2883,$B$2,Data_Inst!$B$2:$B$2883,$A20)*100 | D20: =AVERAGEIFS(Data_Inst!$F$2:$F$2883,Data_Inst!$A$2:$A$2883,$B$3,Data_Inst!$B$2:$B$2883,$A20)*100 | E20: =ROUND(C20-D20,9) | P20: bootstrap 95% CI high (value) | Q20: -0.22386782
A21: wfjsp1_10 | B21: WFJSP 1-8 | C21: =AVERAGEIFS(Data_Inst!$F$2:$F$2883,Data_Inst!$A$2:$A$2883,$B$2,Data_Inst!$B$2:$B$2883,$A21)*100 | D21: =AVERAGEIFS(Data_Inst!$F$2:$F$2883,Data_Inst!$A$2:$A$2883,$B$3,Data_Inst!$B$2:$B$2883,$A21)*100 | E21: =ROUND(C21-D21,9)
A22: wfjsp2_1 | B22: WFJSP 1-8 | C22: =AVERAGEIFS(Data_Inst!$F$2:$F$2883,Data_Inst!$A$2:$A$2883,$B$2,Data_Inst!$B$2:$B$2883,$A22)*100 | D22: =AVERAGEIFS(Data_Inst!$F$2:$F$2883,Data_Inst!$A$2:$A$2883,$B$3,Data_Inst!$B$2:$B$2883,$A22)*100 | E22: =ROUND(C22-D22,9) | P22: Mean difference per group
A23: wfjsp2_2 | B23: WFJSP 1-8 | C23: =AVERAGEIFS(Data_Inst!$F$2:$F$2883,Data_Inst!$A$2:$A$2883,$B$2,Data_Inst!$B$2:$B$2883,$A23)*100 | D23: =AVERAGEIFS(Data_Inst!$F$2:$F$2883,Data_Inst!$A$2:$A$2883,$B$3,Data_Inst!$B$2:$B$2883,$A23)*100 | E23: =ROUND(C23-D23,9) | P23: WFJSP 1-8 | Q23: =AVERAGEIFS($E$12:$E$273,$B$12:$B$273,P23)
A24: wfjsp2_3 | B24: WFJSP 1-8 | C24: =AVERAGEIFS(Data_Inst!$F$2:$F$2883,Data_Inst!$A$2:$A$2883,$B$2,Data_Inst!$B$2:$B$2883,$A24)*100 | D24: =AVERAGEIFS(Data_Inst!$F$2:$F$2883,Data_Inst!$A$2:$A$2883,$B$3,Data_Inst!$B$2:$B$2883,$A24)*100 | E24: =ROUND(C24-D24,9) | P24: WFJSP 9-16 | Q24: =AVERAGEIFS($E$12:$E$273,$B$12:$B$273,P24)
A25: wfjsp2_4 | B25: WFJSP 1-8 | C25: =AVERAGEIFS(Data_Inst!$F$2:$F$2883,Data_Inst!$A$2:$A$2883,$B$2,Data_Inst!$B$2:$B$2883,$A25)*100 | D25: =AVERAGEIFS(Data_Inst!$F$2:$F$2883,Data_Inst!$A$2:$A$2883,$B$3,Data_Inst!$B$2:$B$2883,$A25)*100 | E25: =ROUND(C25-D25,9) | P25: WFJSP 17-24 | Q25: =AVERAGEIFS($E$12:$E$273,$B$12:$B$273,P25)
A26: wfjsp2_5 | B26: WFJSP 1-8 | C26: =AVERAGEIFS(Data_Inst!$F$2:$F$2883,Data_Inst!$A$2:$A$2883,$B$2,Data_Inst!$B$2:$B$2883,$A26)*100 | D26: =AVERAGEIFS(Data_Inst!$F$2:$F$2883,Data_Inst!$A$2:$A$2883,$B$3,Data_Inst!$B$2:$B$2883,$A26)*100 | E26: =ROUND(C26-D26,9) | P26: MK | Q26: =AVERAGEIFS($E$12:$E$273,$B$12:$B$273,P26)
A27: wfjsp2_6 | B27: WFJSP 1-8 | C27: =AVERAGEIFS(Data_Inst!$F$2:$F$2883,Data_Inst!$A$2:$A$2883,$B$2,Data_Inst!$B$2:$B$2883,$A27)*100 | D27: =AVERAGEIFS(Data_Inst!$F$2:$F$2883,Data_Inst!$A$2:$A$2883,$B$3,Data_Inst!$B$2:$B$2883,$A27)*100 | E27: =ROUND(C27-D27,9) | P27: DP | Q27: =AVERAGEIFS($E$12:$E$273,$B$12:$B$273,P27)
A28: wfjsp2_7 | B28: WFJSP 1-8 | C28: =AVERAGEIFS(Data_Inst!$F$2:$F$2883,Data_Inst!$A$2:$A$2883,$B$2,Data_Inst!$B$2:$B$2883,$A28)*100 | D28: =AVERAGEIFS(Data_Inst!$F$2:$F$2883,Data_Inst!$A$2:$A$2883,$B$3,Data_Inst!$B$2:$B$2883,$A28)*100 | E28: =ROUND(C28-D28,9)
A29: wfjsp2_8 | B29: WFJSP 1-8 | C29: =AVERAGEIFS(Data_Inst!$F$2:$F$2883,Data_Inst!$A$2:$A$2883,$B$2,Data_Inst!$B$2:$B$2883,$A29)*100 | D29: =AVERAGEIFS(Data_Inst!$F$2:$F$2883,Data_Inst!$A$2:$A$2883,$B$3,Data_Inst!$B$2:$B$2883,$A29)*100 | E29: =ROUND(C29-D29,9)
A30: wfjsp2_9 | B30: WFJSP 1-8 | C30: =AVERAGEIFS(Data_Inst!$F$2:$F$2883,Data_Inst!$A$2:$A$2883,$B$2,Data_Inst!$B$2:$B$2883,$A30)*100 | D30: =AVERAGEIFS(Data_Inst!$F$2:$F$2883,Data_Inst!$A$2:$A$2883,$B$3,Data_Inst!$B$2:$B$2883,$A30)*100 | E30: =ROUND(C30-D30,9)
